5:return {{["x"] = 3, ["y"] = 0, ["z"] = 11, ["name"] = "wool:white"}, {["x"] = 4, ["y"] = 0, ["z"] = 12, ["name"] = "wool:white"}, {["x"] = 5, ["y"] = 0, ["z"] = 10, ["name"] = "wool:white"}, {["x"] = 5, ["y"] = 0, ["z"] = 11, ["name"] = "wool:white"}, {["x"] = 5, ["y"] = 0, ["z"] = 12, ["name"] = "wool:white"}, {["x"] = 5, ["y"] = 0, ["z"] = 13, ["name"] = "wool:white"}, {["x"] = 5, ["y"] = 1, ["z"] = 13, ["name"] = "wool:white"}, {["x"] = 5, ["y"] = 2, ["z"] = 12, ["name"] = "wool:white"}, {["x"] = 5, ["y"] = 3, ["z"] = 11, ["name"] = "wool:white"}, {["x"] = 6, ["y"] = 0, ["z"] = 12, ["name"] = "wool:white"}, {["x"] = 6, ["y"] = 2, ["z"] = 6, ["name"] = "wool:white"}, {["x"] = 6, ["y"] = 3, ["z"] = 5, ["name"] = "wool:white"}, {["x"] = 6, ["y"] = 3, ["z"] = 11, ["name"] = "wool:white"}, {["x"] = 6, ["y"] = 4, ["z"] = 4, ["name"] = "wool:white"}, {["x"] = 6, ["y"] = 4, ["z"] = 5, ["name"] = "wool:white"}, {["x"] = 6, ["y"] = 4, ["z"] = 6, ["name"] = "wool:white"}, {["x"] = 6, ["y"] = 4, ["z"] = 7, ["name"] = "wool:white"}, {["x"] = 6, ["y"] = 4, ["z"] = 12, ["name"] = "wool:white"}, {["x"] = 7, ["y"] = 0, ["z"] = 11, ["name"] = "wool:white"}, {["x"] = 7, ["y"] = 3, ["z"] = 14, ["name"] = "wool:white"}, {["x"] = 7, ["y"] = 4, ["z"] = 13, ["name"] = "wool:white"}, {["x"] = 7, ["y"] = 4, ["z"] = 14, ["name"] = "wool:white"}, {["x"] = 7, ["y"] = 5, ["z"] = 7, ["name"] = "wool:white"}, {["x"] = 7, ["y"] = 5, ["z"] = 9, ["name"] = "wool:white"}, {["x"] = 7, ["y"] = 5, ["z"] = 11, ["name"] = "wool:white"}, {["x"] = 7, ["y"] = 5, ["z"] = 13, ["name"] = "wool:white"}, {["x"] = 7, ["y"] = 6, ["z"] = 6, ["name"] = "wool:white"}, {["x"] = 7, ["y"] = 6, ["z"] = 14, ["name"] = "wool:white"}, {["x"] = 7, ["y"] = 6, ["z"] = 15, ["name"] = "wool:white"}, {["x"] = 7, ["y"] = 7, ["z"] = 7, ["name"] = "wool:white"}, {["x"] = 7, ["y"] = 8, ["z"] = 8, ["name"] = "wool:white"}, {["x"] = 7, ["y"] = 9, ["z"] = 1, ["name"] = "wool:white"}, {["x"] = 7, ["y"] = 9, ["z"] = 2, ["name"] = "wool:white"}, {["x"] = 7, ["y"] = 9, ["z"] = 3, ["name"] = "wool:white"}, {["x"] = 7, ["y"] = 9, ["z"] = 4, ["name"] = "wool:white"}, {["x"] = 7, ["y"] = 9, ["z"] = 5, ["name"] = "wool:white"}, {["x"] = 7, ["y"] = 9, ["z"] = 9, ["name"] = "wool:white"}, {["x"] = 7, ["y"] = 10, ["z"] = 2, ["name"] = "wool:white"}, {["x"] = 7, ["y"] = 10, ["z"] = 4, ["name"] = "wool:white"}, {["x"] = 7, ["y"] = 10, ["z"] = 6, ["name"] = "wool:white"}, {["x"] = 7, ["y"] = 10, ["z"] = 8, ["name"] = "wool:white"}, {["x"] = 7, ["y"] = 11, ["z"] = 3, ["name"] = "wool:white"}, {["x"] = 7, ["y"] = 11, ["z"] = 4, ["name"] = "wool:white"}, {["x"] = 7, ["y"] = 11, ["z"] = 5, ["name"] = "wool:white"}, {["x"] = 8, ["y"] = 0, ["z"] = 11, ["name"] = "wool:white"}, {["x"] = 8, ["y"] = 3, ["z"] = 14, ["name"] = "wool:white"}, {["x"] = 8, ["y"] = 4, ["z"] = 13, ["name"] = "wool:white"}, {["x"] = 8, ["y"] = 4, ["z"] = 14, ["name"] = "wool:white"}, {["x"] = 8, ["y"] = 5, ["z"] = 7, ["name"] = "wool:white"}, {["x"] = 8, ["y"] = 5, ["z"] = 9, ["name"] = "wool:white"}, {["x"] = 8, ["y"] = 5, ["z"] = 11, ["name"] = "wool:white"}, {["x"] = 8, ["y"] = 5, ["z"] = 13, ["name"] = "wool:white"}, {["x"] = 8, ["y"] = 6, ["z"] = 6, ["name"] = "wool:white"}, {["x"] = 8, ["y"] = 6, ["z"] = 14, ["name"] = "wool:white"}, {["x"] = 8, ["y"] = 6, ["z"] = 15, ["name"] = "wool:white"}, {["x"] = 8, ["y"] = 7, ["z"] = 7, ["name"] = "wool:white"}, {["x"] = 8, ["y"] = 8, ["z"] = 8, ["name"] = "wool:white"}, {["x"] = 8, ["y"] = 9, ["z"] = 1, ["name"] = "wool:white"}, {["x"] = 8, ["y"] = 9, ["z"] = 2, ["name"] = "wool:white"}, {["x"] = 8, ["y"] = 9, ["z"] = 3, ["name"] = "wool:white"}, {["x"] = 8, ["y"] = 9, ["z"] = 4, ["name"] = "wool:white"}, {["x"] = 8, ["y"] = 9, ["z"] = 5, ["name"] = "wool:white"}, {["x"] = 8, ["y"] = 9, ["z"] = 9, ["name"] = "wool:white"}, {["x"] = 8, ["y"] = 10, ["z"] = 2, ["name"] = "wool:white"}, {["x"] = 8, ["y"] = 10, ["z"] = 4, ["name"] = "wool:white"}, {["x"] = 8, ["y"] = 10, ["z"] = 6, ["name"] = "wool:white"}, {["x"] = 8, ["y"] = 10, ["z"] = 8, ["name"] = "wool:white"}, {["x"] = 8, ["y"] = 11, ["z"] = 3, ["name"] = "wool:white"}, {["x"] = 8, ["y"] = 11, ["z"] = 4, ["name"] = "wool:white"}, {["x"] = 8, ["y"] = 11, ["z"] = 5, ["name"] = "wool:white"}, {["x"] = 9, ["y"] = 0, ["z"] = 12, ["name"] = "wool:white"}, {["x"] = 9, ["y"] = 1, ["z"] = 7, ["name"] = "wool:white"}, {["x"] = 9, ["y"] = 2, ["z"] = 6, ["name"] = "wool:white"}, {["x"] = 9, ["y"] = 3, ["z"] = 5, ["name"] = "wool:white"}, {["x"] = 9, ["y"] = 3, ["z"] = 11, ["name"] = "wool:white"}, {["x"] = 9, ["y"] = 4, ["z"] = 4, ["name"] = "wool:white"}, {["x"] = 9, ["y"] = 4, ["z"] = 5, ["name"] = "wool:white"}, {["x"] = 9, ["y"] = 4, ["z"] = 6, ["name"] = "wool:white"}, {["x"] = 9, ["y"] = 4, ["z"] = 7, ["name"] = "wool:white"}, {["x"] = 9, ["y"] = 4, ["z"] = 12, ["name"] = "wool:white"}, {["x"] = 10, ["y"] = 0, ["z"] = 10, ["name"] = "wool:white"}, {["x"] = 10, ["y"] = 0, ["z"] = 11, ["name"] = "wool:white"}, {["x"] = 10, ["y"] = 0, ["z"] = 12, ["name"] = "wool:white"}, {["x"] = 10, ["y"] = 0, ["z"] = 13, ["name"] = "wool:white"}, {["x"] = 10, ["y"] = 1, ["z"] = 13, ["name"] = "wool:white"}, {["x"] = 10, ["y"] = 2, ["z"] = 12, ["name"] = "wool:white"}, {["x"] = 10, ["y"] = 3, ["z"] = 11, ["name"] = "wool:white"}, {["x"] = 11, ["y"] = 0, ["z"] = 12, ["name"] = "wool:white"}, {["x"] = 12, ["y"] = 0, ["z"] = 11, ["name"] = "wool:white"}}