5:return {{["x"] = 1, ["y"] = 0, ["z"] = 13, ["name"] = "wool:white"}, {["x"] = 1, ["y"] = 0, ["z"] = 14, ["name"] = "wool:white"}, {["x"] = 1, ["y"] = 1, ["z"] = 13, ["name"] = "wool:white"}, {["x"] = 1, ["y"] = 1, ["z"] = 14, ["name"] = "wool:white"}, {["x"] = 1, ["y"] = 2, ["z"] = 14, ["name"] = "wool:white"}, {["x"] = 1, ["y"] = 3, ["z"] = 14, ["name"] = "wool:white"}, {["x"] = 1, ["y"] = 4, ["z"] = 13, ["name"] = "wool:white"}, {["x"] = 1, ["y"] = 4, ["z"] = 14, ["name"] = "wool:white"}, {["x"] = 1, ["y"] = 5, ["z"] = 12, ["name"] = "wool:white"}, {["x"] = 1, ["y"] = 5, ["z"] = 13, ["name"] = "wool:white"}, {["x"] = 1, ["y"] = 6, ["z"] = 12, ["name"] = "wool:white"}, {["x"] = 1, ["y"] = 6, ["z"] = 13, ["name"] = "wool:white"}, {["x"] = 1, ["y"] = 7, ["z"] = 13, ["name"] = "wool:white"}, {["x"] = 1, ["y"] = 7, ["z"] = 14, ["name"] = "wool:white"}, {["x"] = 1, ["y"] = 8, ["z"] = 13, ["name"] = "wool:white"}, {["x"] = 1, ["y"] = 8, ["z"] = 14, ["name"] = "wool:white"}, {["x"] = 1, ["y"] = 9, ["z"] = 14, ["name"] = "wool:white"}, {["x"] = 1, ["y"] = 9, ["z"] = 15, ["name"] = "wool:white"}, {["x"] = 1, ["y"] = 10, ["z"] = 13, ["name"] = "wool:white"}, {["x"] = 1, ["y"] = 10, ["z"] = 14, ["name"] = "wool:white"}, {["x"] = 1, ["y"] = 11, ["z"] = 12, ["name"] = "wool:white"}, {["x"] = 1, ["y"] = 11, ["z"] = 13, ["name"] = "wool:white"}, {["x"] = 1, ["y"] = 12, ["z"] = 11, ["name"] = "wool:white"}, {["x"] = 1, ["y"] = 12, ["z"] = 12, ["name"] = "wool:white"}, {["x"] = 1, ["y"] = 12, ["z"] = 15, ["name"] = "wool:white"}, {["x"] = 1, ["y"] = 12, ["z"] = 17, ["name"] = "wool:white"}, {["x"] = 1, ["y"] = 13, ["z"] = 12, ["name"] = "wool:white"}, {["x"] = 1, ["y"] = 13, ["z"] = 13, ["name"] = "wool:white"}, {["x"] = 1, ["y"] = 13, ["z"] = 15, ["name"] = "wool:white"}, {["x"] = 1, ["y"] = 13, ["z"] = 17, ["name"] = "wool:white"}, {["x"] = 1, ["y"] = 13, ["z"] = 19, ["name"] = "wool:white"}, {["x"] = 1, ["y"] = 14, ["z"] = 12, ["name"] = "wool:white"}, {["x"] = 1, ["y"] = 14, ["z"] = 13, ["name"] = "wool:white"}, {["x"] = 1, ["y"] = 14, ["z"] = 15, ["name"] = "wool:white"}, {["x"] = 1, ["y"] = 14, ["z"] = 17, ["name"] = "wool:white"}, {["x"] = 1, ["y"] = 14, ["z"] = 19, ["name"] = "wool:white"}, {["x"] = 1, ["y"] = 14, ["z"] = 21, ["name"] = "wool:white"}, {["x"] = 1, ["y"] = 15, ["z"] = 11, ["name"] = "wool:white"}, {["x"] = 1, ["y"] = 15, ["z"] = 12, ["name"] = "wool:white"}, {["x"] = 1, ["y"] = 15, ["z"] = 15, ["name"] = "wool:white"}, {["x"] = 1, ["y"] = 15, ["z"] = 17, ["name"] = "wool:white"}, {["x"] = 1, ["y"] = 15, ["z"] = 19, ["name"] = "wool:white"}, {["x"] = 1, ["y"] = 15, ["z"] = 21, ["name"] = "wool:white"}, {["x"] = 1, ["y"] = 15, ["z"] = 23, ["name"] = "wool:white"}, {["x"] = 1, ["y"] = 16, ["z"] = 12, ["name"] = "wool:white"}, {["x"] = 1, ["y"] = 16, ["z"] = 15, ["name"] = "wool:white"}, {["x"] = 1, ["y"] = 16, ["z"] = 17, ["name"] = "wool:white"}, {["x"] = 1, ["y"] = 16, ["z"] = 19, ["name"] = "wool:white"}, {["x"] = 1, ["y"] = 16, ["z"] = 21, ["name"] = "wool:white"}, {["x"] = 1, ["y"] = 16, ["z"] = 23, ["name"] = "wool:white"}, {["x"] = 1, ["y"] = 17, ["z"] = 12, ["name"] = "wool:white"}, {["x"] = 1, ["y"] = 17, ["z"] = 13, ["name"] = "wool:white"}, {["x"] = 1, ["y"] = 17, ["z"] = 15, ["name"] = "wool:white"}, {["x"] = 1, ["y"] = 17, ["z"] = 17, ["name"] = "wool:white"}, {["x"] = 1, ["y"] = 17, ["z"] = 19, ["name"] = "wool:white"}, {["x"] = 1, ["y"] = 17, ["z"] = 21, ["name"] = "wool:white"}, {["x"] = 1, ["y"] = 17, ["z"] = 23, ["name"] = "wool:white"}, {["x"] = 1, ["y"] = 18, ["z"] = 12, ["name"] = "wool:white"}, {["x"] = 1, ["y"] = 18, ["z"] = 13, ["name"] = "wool:white"}, {["x"] = 1, ["y"] = 18, ["z"] = 15, ["name"] = "wool:white"}, {["x"] = 1, ["y"] = 18, ["z"] = 17, ["name"] = "wool:white"}, {["x"] = 1, ["y"] = 18, ["z"] = 19, ["name"] = "wool:white"}, {["x"] = 1, ["y"] = 18, ["z"] = 21, ["name"] = "wool:white"}, {["x"] = 1, ["y"] = 18, ["z"] = 23, ["name"] = "wool:white"}, {["x"] = 1, ["y"] = 19, ["z"] = 15, ["name"] = "wool:white"}, {["x"] = 1, ["y"] = 19, ["z"] = 17, ["name"] = "wool:white"}, {["x"] = 1, ["y"] = 19, ["z"] = 19, ["name"] = "wool:white"}, {["x"] = 1, ["y"] = 19, ["z"] = 21, ["name"] = "wool:white"}, {["x"] = 1, ["y"] = 19, ["z"] = 23, ["name"] = "wool:white"}, {["x"] = 1, ["y"] = 20, ["z"] = 17, ["name"] = "wool:white"}, {["x"] = 1, ["y"] = 20, ["z"] = 19, ["name"] = "wool:white"}, {["x"] = 1, ["y"] = 20, ["z"] = 21, ["name"] = "wool:white"}, {["x"] = 1, ["y"] = 20, ["z"] = 23, ["name"] = "wool:white"}, {["x"] = 1, ["y"] = 21, ["z"] = 19, ["name"] = "wool:white"}, {["x"] = 1, ["y"] = 21, ["z"] = 21, ["name"] = "wool:white"}, {["x"] = 1, ["y"] = 21, ["z"] = 23, ["name"] = "wool:white"}, {["x"] = 1, ["y"] = 22, ["z"] = 21, ["name"] = "wool:white"}, {["x"] = 1, ["y"] = 22, ["z"] = 23, ["name"] = "wool:white"}, {["x"] = 2, ["y"] = 0, ["z"] = 26, ["name"] = "wool:white"}, {["x"] = 2, ["y"] = 0, ["z"] = 27, ["name"] = "wool:white"}, {["x"] = 2, ["y"] = 1, ["z"] = 26, ["name"] = "wool:white"}, {["x"] = 2, ["y"] = 1, ["z"] = 27, ["name"] = "wool:white"}, {["x"] = 2, ["y"] = 2, ["z"] = 27, ["name"] = "wool:white"}, {["x"] = 2, ["y"] = 3, ["z"] = 14, ["name"] = "wool:white"}, {["x"] = 2, ["y"] = 3, ["z"] = 27, ["name"] = "wool:white"}, {["x"] = 2, ["y"] = 4, ["z"] = 13, ["name"] = "wool:white"}, {["x"] = 2, ["y"] = 4, ["z"] = 14, ["name"] = "wool:white"}, {["x"] = 2, ["y"] = 4, ["z"] = 27, ["name"] = "wool:white"}, {["x"] = 2, ["y"] = 4, ["z"] = 28, ["name"] = "wool:white"}, {["x"] = 2, ["y"] = 5, ["z"] = 12, ["name"] = "wool:white"}, {["x"] = 2, ["y"] = 5, ["z"] = 13, ["name"] = "wool:white"}, {["x"] = 2, ["y"] = 5, ["z"] = 27, ["name"] = "wool:white"}, {["x"] = 2, ["y"] = 5, ["z"] = 28, ["name"] = "wool:white"}, {["x"] = 2, ["y"] = 6, ["z"] = 12, ["name"] = "wool:white"}, {["x"] = 2, ["y"] = 6, ["z"] = 13, ["name"] = "wool:white"}, {["x"] = 2, ["y"] = 6, ["z"] = 27, ["name"] = "wool:white"}, {["x"] = 2, ["y"] = 6, ["z"] = 28, ["name"] = "wool:white"}, {["x"] = 2, ["y"] = 7, ["z"] = 13, ["name"] = "wool:white"}, {["x"] = 2, ["y"] = 7, ["z"] = 14, ["name"] = "wool:white"}, {["x"] = 2, ["y"] = 7, ["z"] = 27, ["name"] = "wool:white"}, {["x"] = 2, ["y"] = 7, ["z"] = 28, ["name"] = "wool:white"}, {["x"] = 2, ["y"] = 8, ["z"] = 13, ["name"] = "wool:white"}, {["x"] = 2, ["y"] = 8, ["z"] = 14, ["name"] = "wool:white"}, {["x"] = 2, ["y"] = 8, ["z"] = 27, ["name"] = "wool:white"}, {["x"] = 2, ["y"] = 8, ["z"] = 28, ["name"] = "wool:white"}, {["x"] = 2, ["y"] = 9, ["z"] = 14, ["name"] = "wool:white"}, {["x"] = 2, ["y"] = 9, ["z"] = 15, ["name"] = "wool:white"}, {["x"] = 2, ["y"] = 9, ["z"] = 28, ["name"] = "wool:white"}, {["x"] = 2, ["y"] = 9, ["z"] = 29, ["name"] = "wool:white"}, {["x"] = 2, ["y"] = 10, ["z"] = 13, ["name"] = "wool:white"}, {["x"] = 2, ["y"] = 10, ["z"] = 14, ["name"] = "wool:white"}, {["x"] = 2, ["y"] = 10, ["z"] = 27, ["name"] = "wool:white"}, {["x"] = 2, ["y"] = 10, ["z"] = 28, ["name"] = "wool:white"}, {["x"] = 2, ["y"] = 10, ["z"] = 30, ["name"] = "wool:white"}, {["x"] = 2, ["y"] = 11, ["z"] = 12, ["name"] = "wool:white"}, {["x"] = 2, ["y"] = 11, ["z"] = 13, ["name"] = "wool:white"}, {["x"] = 2, ["y"] = 11, ["z"] = 27, ["name"] = "wool:white"}, {["x"] = 2, ["y"] = 11, ["z"] = 28, ["name"] = "wool:white"}, {["x"] = 2, ["y"] = 12, ["z"] = 11, ["name"] = "wool:white"}, {["x"] = 2, ["y"] = 12, ["z"] = 12, ["name"] = "wool:white"}, {["x"] = 2, ["y"] = 12, ["z"] = 15, ["name"] = "wool:white"}, {["x"] = 2, ["y"] = 12, ["z"] = 17, ["name"] = "wool:white"}, {["x"] = 2, ["y"] = 12, ["z"] = 27, ["name"] = "wool:white"}, {["x"] = 2, ["y"] = 12, ["z"] = 28, ["name"] = "wool:white"}, {["x"] = 2, ["y"] = 13, ["z"] = 12, ["name"] = "wool:white"}, {["x"] = 2, ["y"] = 13, ["z"] = 13, ["name"] = "wool:white"}, {["x"] = 2, ["y"] = 13, ["z"] = 19, ["name"] = "wool:white"}, {["x"] = 2, ["y"] = 13, ["z"] = 26, ["name"] = "wool:white"}, {["x"] = 2, ["y"] = 13, ["z"] = 27, ["name"] = "wool:white"}, {["x"] = 2, ["y"] = 14, ["z"] = 12, ["name"] = "wool:white"}, {["x"] = 2, ["y"] = 14, ["z"] = 13, ["name"] = "wool:white"}, {["x"] = 2, ["y"] = 14, ["z"] = 21, ["name"] = "wool:white"}, {["x"] = 2, ["y"] = 14, ["z"] = 26, ["name"] = "wool:white"}, {["x"] = 2, ["y"] = 14, ["z"] = 27, ["name"] = "wool:white"}, {["x"] = 2, ["y"] = 15, ["z"] = 11, ["name"] = "wool:white"}, {["x"] = 2, ["y"] = 15, ["z"] = 12, ["name"] = "wool:white"}, {["x"] = 2, ["y"] = 15, ["z"] = 23, ["name"] = "wool:white"}, {["x"] = 2, ["y"] = 18, ["z"] = 13, ["name"] = "wool:white"}, {["x"] = 2, ["y"] = 19, ["z"] = 15, ["name"] = "wool:white"}, {["x"] = 2, ["y"] = 20, ["z"] = 17, ["name"] = "wool:white"}, {["x"] = 2, ["y"] = 21, ["z"] = 19, ["name"] = "wool:white"}, {["x"] = 2, ["y"] = 22, ["z"] = 21, ["name"] = "wool:white"}, {["x"] = 2, ["y"] = 22, ["z"] = 23, ["name"] = "wool:white"}, {["x"] = 3, ["y"] = 0, ["z"] = 13, ["name"] = "wool:white"}, {["x"] = 3, ["y"] = 0, ["z"] = 14, ["name"] = "wool:white"}, {["x"] = 3, ["y"] = 1, ["z"] = 13, ["name"] = "wool:white"}, {["x"] = 3, ["y"] = 1, ["z"] = 14, ["name"] = "wool:white"}, {["x"] = 3, ["y"] = 2, ["z"] = 14, ["name"] = "wool:white"}, {["x"] = 3, ["y"] = 3, ["z"] = 14, ["name"] = "wool:white"}, {["x"] = 3, ["y"] = 3, ["z"] = 27, ["name"] = "wool:white"}, {["x"] = 3, ["y"] = 4, ["z"] = 13, ["name"] = "wool:white"}, {["x"] = 3, ["y"] = 4, ["z"] = 14, ["name"] = "wool:white"}, {["x"] = 3, ["y"] = 4, ["z"] = 27, ["name"] = "wool:white"}, {["x"] = 3, ["y"] = 4, ["z"] = 28, ["name"] = "wool:white"}, {["x"] = 3, ["y"] = 5, ["z"] = 27, ["name"] = "wool:white"}, {["x"] = 3, ["y"] = 5, ["z"] = 28, ["name"] = "wool:white"}, {["x"] = 3, ["y"] = 6, ["z"] = 27, ["name"] = "wool:white"}, {["x"] = 3, ["y"] = 6, ["z"] = 28, ["name"] = "wool:white"}, {["x"] = 3, ["y"] = 7, ["z"] = 27, ["name"] = "wool:white"}, {["x"] = 3, ["y"] = 7, ["z"] = 28, ["name"] = "wool:white"}, {["x"] = 3, ["y"] = 8, ["z"] = 27, ["name"] = "wool:white"}, {["x"] = 3, ["y"] = 8, ["z"] = 28, ["name"] = "wool:white"}, {["x"] = 3, ["y"] = 9, ["z"] = 28, ["name"] = "wool:white"}, {["x"] = 3, ["y"] = 9, ["z"] = 29, ["name"] = "wool:white"}, {["x"] = 3, ["y"] = 10, ["z"] = 27, ["name"] = "wool:white"}, {["x"] = 3, ["y"] = 10, ["z"] = 28, ["name"] = "wool:white"}, {["x"] = 3, ["y"] = 10, ["z"] = 30, ["name"] = "wool:white"}, {["x"] = 3, ["y"] = 11, ["z"] = 27, ["name"] = "wool:white"}, {["x"] = 3, ["y"] = 11, ["z"] = 28, ["name"] = "wool:white"}, {["x"] = 3, ["y"] = 12, ["z"] = 15, ["name"] = "wool:white"}, {["x"] = 3, ["y"] = 12, ["z"] = 17, ["name"] = "wool:white"}, {["x"] = 3, ["y"] = 12, ["z"] = 27, ["name"] = "wool:white"}, {["x"] = 3, ["y"] = 12, ["z"] = 28, ["name"] = "wool:white"}, {["x"] = 3, ["y"] = 13, ["z"] = 19, ["name"] = "wool:white"}, {["x"] = 3, ["y"] = 13, ["z"] = 26, ["name"] = "wool:white"}, {["x"] = 3, ["y"] = 13, ["z"] = 27, ["name"] = "wool:white"}, {["x"] = 3, ["y"] = 14, ["z"] = 21, ["name"] = "wool:white"}, {["x"] = 3, ["y"] = 14, ["z"] = 26, ["name"] = "wool:white"}, {["x"] = 3, ["y"] = 14, ["z"] = 27, ["name"] = "wool:white"}, {["x"] = 3, ["y"] = 15, ["z"] = 23, ["name"] = "wool:white"}, {["x"] = 3, ["y"] = 15, ["z"] = 26, ["name"] = "wool:white"}, {["x"] = 3, ["y"] = 15, ["z"] = 27, ["name"] = "wool:white"}, {["x"] = 3, ["y"] = 16, ["z"] = 13, ["name"] = "wool:white"}, {["x"] = 3, ["y"] = 16, ["z"] = 27, ["name"] = "wool:white"}, {["x"] = 3, ["y"] = 16, ["z"] = 28, ["name"] = "wool:white"}, {["x"] = 3, ["y"] = 17, ["z"] = 13, ["name"] = "wool:white"}, {["x"] = 3, ["y"] = 18, ["z"] = 13, ["name"] = "wool:white"}, {["x"] = 3, ["y"] = 19, ["z"] = 15, ["name"] = "wool:white"}, {["x"] = 3, ["y"] = 20, ["z"] = 17, ["name"] = "wool:white"}, {["x"] = 3, ["y"] = 21, ["z"] = 19, ["name"] = "wool:white"}, {["x"] = 3, ["y"] = 22, ["z"] = 21, ["name"] = "wool:white"}, {["x"] = 3, ["y"] = 22, ["z"] = 23, ["name"] = "wool:white"}, {["x"] = 4, ["y"] = 0, ["z"] = 26, ["name"] = "wool:white"}, {["x"] = 4, ["y"] = 0, ["z"] = 27, ["name"] = "wool:white"}, {["x"] = 4, ["y"] = 1, ["z"] = 26, ["name"] = "wool:white"}, {["x"] = 4, ["y"] = 1, ["z"] = 27, ["name"] = "wool:white"}, {["x"] = 4, ["y"] = 2, ["z"] = 27, ["name"] = "wool:white"}, {["x"] = 4, ["y"] = 3, ["z"] = 27, ["name"] = "wool:white"}, {["x"] = 4, ["y"] = 12, ["z"] = 15, ["name"] = "wool:white"}, {["x"] = 4, ["y"] = 12, ["z"] = 17, ["name"] = "wool:white"}, {["x"] = 4, ["y"] = 13, ["z"] = 19, ["name"] = "wool:white"}, {["x"] = 4, ["y"] = 14, ["z"] = 13, ["name"] = "wool:white"}, {["x"] = 4, ["y"] = 14, ["z"] = 21, ["name"] = "wool:white"}, {["x"] = 4, ["y"] = 15, ["z"] = 13, ["name"] = "wool:white"}, {["x"] = 4, ["y"] = 15, ["z"] = 23, ["name"] = "wool:white"}, {["x"] = 4, ["y"] = 15, ["z"] = 26, ["name"] = "wool:white"}, {["x"] = 4, ["y"] = 15, ["z"] = 27, ["name"] = "wool:white"}, {["x"] = 4, ["y"] = 16, ["z"] = 27, ["name"] = "wool:white"}, {["x"] = 4, ["y"] = 16, ["z"] = 28, ["name"] = "wool:white"}, {["x"] = 4, ["y"] = 17, ["z"] = 28, ["name"] = "wool:white"}, {["x"] = 4, ["y"] = 17, ["z"] = 29, ["name"] = "wool:white"}, {["x"] = 4, ["y"] = 18, ["z"] = 13, ["name"] = "wool:white"}, {["x"] = 4, ["y"] = 18, ["z"] = 28, ["name"] = "wool:white"}, {["x"] = 4, ["y"] = 18, ["z"] = 29, ["name"] = "wool:white"}, {["x"] = 4, ["y"] = 19, ["z"] = 15, ["name"] = "wool:white"}, {["x"] = 4, ["y"] = 19, ["z"] = 28, ["name"] = "wool:white"}, {["x"] = 4, ["y"] = 20, ["z"] = 17, ["name"] = "wool:white"}, {["x"] = 4, ["y"] = 20, ["z"] = 27, ["name"] = "wool:white"}, {["x"] = 4, ["y"] = 20, ["z"] = 28, ["name"] = "wool:white"}, {["x"] = 4, ["y"] = 21, ["z"] = 19, ["name"] = "wool:white"}, {["x"] = 4, ["y"] = 22, ["z"] = 21, ["name"] = "wool:white"}, {["x"] = 4, ["y"] = 22, ["z"] = 23, ["name"] = "wool:white"}, {["x"] = 5, ["y"] = 12, ["z"] = 15, ["name"] = "wool:white"}, {["x"] = 5, ["y"] = 12, ["z"] = 17, ["name"] = "wool:white"}, {["x"] = 5, ["y"] = 13, ["z"] = 19, ["name"] = "wool:white"}, {["x"] = 5, ["y"] = 14, ["z"] = 13, ["name"] = "wool:white"}, {["x"] = 5, ["y"] = 14, ["z"] = 21, ["name"] = "wool:white"}, {["x"] = 5, ["y"] = 15, ["z"] = 23, ["name"] = "wool:white"}, {["x"] = 5, ["y"] = 17, ["z"] = 2, ["name"] = "wool:white"}, {["x"] = 5, ["y"] = 17, ["z"] = 3, ["name"] = "wool:white"}, {["x"] = 5, ["y"] = 17, ["z"] = 4, ["name"] = "wool:white"}, {["x"] = 5, ["y"] = 17, ["z"] = 28, ["name"] = "wool:white"}, {["x"] = 5, ["y"] = 17, ["z"] = 29, ["name"] = "wool:white"}, {["x"] = 5, ["y"] = 18, ["z"] = 3, ["name"] = "wool:white"}, {["x"] = 5, ["y"] = 18, ["z"] = 4, ["name"] = "wool:white"}, {["x"] = 5, ["y"] = 18, ["z"] = 13, ["name"] = "wool:white"}, {["x"] = 5, ["y"] = 18, ["z"] = 28, ["name"] = "wool:white"}, {["x"] = 5, ["y"] = 18, ["z"] = 29, ["name"] = "wool:white"}, {["x"] = 5, ["y"] = 18, ["z"] = 30, ["name"] = "wool:white"}, {["x"] = 5, ["y"] = 19, ["z"] = 1, ["name"] = "wool:white"}, {["x"] = 5, ["y"] = 19, ["z"] = 2, ["name"] = "wool:white"}, {["x"] = 5, ["y"] = 19, ["z"] = 4, ["name"] = "wool:white"}, {["x"] = 5, ["y"] = 19, ["z"] = 15, ["name"] = "wool:white"}, {["x"] = 5, ["y"] = 19, ["z"] = 28, ["name"] = "wool:white"}, {["x"] = 5, ["y"] = 20, ["z"] = 3, ["name"] = "wool:white"}, {["x"] = 5, ["y"] = 20, ["z"] = 4, ["name"] = "wool:white"}, {["x"] = 5, ["y"] = 20, ["z"] = 5, ["name"] = "wool:white"}, {["x"] = 5, ["y"] = 20, ["z"] = 17, ["name"] = "wool:white"}, {["x"] = 5, ["y"] = 20, ["z"] = 27, ["name"] = "wool:white"}, {["x"] = 5, ["y"] = 20, ["z"] = 28, ["name"] = "wool:white"}, {["x"] = 5, ["y"] = 21, ["z"] = 3, ["name"] = "wool:white"}, {["x"] = 5, ["y"] = 21, ["z"] = 4, ["name"] = "wool:white"}, {["x"] = 5, ["y"] = 21, ["z"] = 5, ["name"] = "wool:white"}, {["x"] = 5, ["y"] = 21, ["z"] = 19, ["name"] = "wool:white"}, {["x"] = 5, ["y"] = 22, ["z"] = 21, ["name"] = "wool:white"}, {["x"] = 5, ["y"] = 22, ["z"] = 23, ["name"] = "wool:white"}, {["x"] = 5, ["y"] = 23, ["z"] = 2, ["name"] = "wool:white"}, {["x"] = 6, ["y"] = 12, ["z"] = 16, ["name"] = "wool:white"}, {["x"] = 6, ["y"] = 12, ["z"] = 18, ["name"] = "wool:white"}, {["x"] = 6, ["y"] = 13, ["z"] = 14, ["name"] = "wool:white"}, {["x"] = 6, ["y"] = 13, ["z"] = 20, ["name"] = "wool:white"}, {["x"] = 6, ["y"] = 14, ["z"] = 22, ["name"] = "wool:white"}, {["x"] = 6, ["y"] = 16, ["z"] = 11, ["name"] = "wool:white"}, {["x"] = 6, ["y"] = 16, ["z"] = 13, ["name"] = "wool:white"}, {["x"] = 6, ["y"] = 17, ["z"] = 0, ["name"] = "wool:white"}, {["x"] = 6, ["y"] = 17, ["z"] = 1, ["name"] = "wool:white"}, {["x"] = 6, ["y"] = 17, ["z"] = 2, ["name"] = "wool:white"}, {["x"] = 6, ["y"] = 17, ["z"] = 3, ["name"] = "wool:white"}, {["x"] = 6, ["y"] = 17, ["z"] = 4, ["name"] = "wool:white"}, {["x"] = 6, ["y"] = 17, ["z"] = 9, ["name"] = "wool:white"}, {["x"] = 6, ["y"] = 17, ["z"] = 11, ["name"] = "wool:white"}, {["x"] = 6, ["y"] = 17, ["z"] = 13, ["name"] = "wool:white"}, {["x"] = 6, ["y"] = 17, ["z"] = 15, ["name"] = "wool:white"}, {["x"] = 6, ["y"] = 18, ["z"] = 7, ["name"] = "wool:white"}, {["x"] = 6, ["y"] = 18, ["z"] = 9, ["name"] = "wool:white"}, {["x"] = 6, ["y"] = 18, ["z"] = 11, ["name"] = "wool:white"}, {["x"] = 6, ["y"] = 18, ["z"] = 13, ["name"] = "wool:white"}, {["x"] = 6, ["y"] = 18, ["z"] = 15, ["name"] = "wool:white"}, {["x"] = 6, ["y"] = 18, ["z"] = 17, ["name"] = "wool:white"}, {["x"] = 6, ["y"] = 19, ["z"] = 0, ["name"] = "wool:white"}, {["x"] = 6, ["y"] = 19, ["z"] = 7, ["name"] = "wool:white"}, {["x"] = 6, ["y"] = 19, ["z"] = 9, ["name"] = "wool:white"}, {["x"] = 6, ["y"] = 19, ["z"] = 15, ["name"] = "wool:white"}, {["x"] = 6, ["y"] = 19, ["z"] = 17, ["name"] = "wool:white"}, {["x"] = 6, ["y"] = 19, ["z"] = 19, ["name"] = "wool:white"}, {["x"] = 6, ["y"] = 20, ["z"] = 1, ["name"] = "wool:white"}, {["x"] = 6, ["y"] = 20, ["z"] = 7, ["name"] = "wool:white"}, {["x"] = 6, ["y"] = 20, ["z"] = 17, ["name"] = "wool:white"}, {["x"] = 6, ["y"] = 20, ["z"] = 19, ["name"] = "wool:white"}, {["x"] = 6, ["y"] = 20, ["z"] = 21, ["name"] = "wool:white"}, {["x"] = 6, ["y"] = 20, ["z"] = 23, ["name"] = "wool:white"}, {["x"] = 6, ["y"] = 20, ["z"] = 25, ["name"] = "wool:white"}, {["x"] = 6, ["y"] = 20, ["z"] = 27, ["name"] = "wool:white"}, {["x"] = 6, ["y"] = 20, ["z"] = 29, ["name"] = "wool:white"}, {["x"] = 6, ["y"] = 21, ["z"] = 2, ["name"] = "wool:white"}, {["x"] = 6, ["y"] = 21, ["z"] = 3, ["name"] = "wool:white"}, {["x"] = 6, ["y"] = 21, ["z"] = 4, ["name"] = "wool:white"}, {["x"] = 6, ["y"] = 21, ["z"] = 5, ["name"] = "wool:white"}, {["x"] = 6, ["y"] = 21, ["z"] = 19, ["name"] = "wool:white"}, {["x"] = 6, ["y"] = 21, ["z"] = 21, ["name"] = "wool:white"}, {["x"] = 6, ["y"] = 21, ["z"] = 23, ["name"] = "wool:white"}, {["x"] = 6, ["y"] = 21, ["z"] = 25, ["name"] = "wool:white"}, {["x"] = 6, ["y"] = 21, ["z"] = 27, ["name"] = "wool:white"}, {["x"] = 6, ["y"] = 21, ["z"] = 29, ["name"] = "wool:white"}, {["x"] = 6, ["y"] = 22, ["z"] = 2, ["name"] = "wool:white"}, {["x"] = 6, ["y"] = 22, ["z"] = 21, ["name"] = "wool:white"}, {["x"] = 6, ["y"] = 22, ["z"] = 23, ["name"] = "wool:white"}, {["x"] = 6, ["y"] = 22, ["z"] = 25, ["name"] = "wool:white"}, {["x"] = 6, ["y"] = 22, ["z"] = 27, ["name"] = "wool:white"}, {["x"] = 6, ["y"] = 22, ["z"] = 29, ["name"] = "wool:white"}, {["x"] = 7, ["y"] = 12, ["z"] = 16, ["name"] = "wool:white"}, {["x"] = 7, ["y"] = 12, ["z"] = 18, ["name"] = "wool:white"}, {["x"] = 7, ["y"] = 12, ["z"] = 31, ["name"] = "wool:white"}, {["x"] = 7, ["y"] = 13, ["z"] = 14, ["name"] = "wool:white"}, {["x"] = 7, ["y"] = 13, ["z"] = 20, ["name"] = "wool:white"}, {["x"] = 7, ["y"] = 13, ["z"] = 31, ["name"] = "wool:white"}, {["x"] = 7, ["y"] = 14, ["z"] = 22, ["name"] = "wool:white"}, {["x"] = 7, ["y"] = 14, ["z"] = 31, ["name"] = "wool:white"}, {["x"] = 7, ["y"] = 15, ["z"] = 31, ["name"] = "wool:white"}, {["x"] = 7, ["y"] = 16, ["z"] = 11, ["name"] = "wool:white"}, {["x"] = 7, ["y"] = 16, ["z"] = 13, ["name"] = "wool:white"}, {["x"] = 7, ["y"] = 16, ["z"] = 31, ["name"] = "wool:white"}, {["x"] = 7, ["y"] = 17, ["z"] = 0, ["name"] = "wool:white"}, {["x"] = 7, ["y"] = 17, ["z"] = 1, ["name"] = "wool:white"}, {["x"] = 7, ["y"] = 17, ["z"] = 2, ["name"] = "wool:white"}, {["x"] = 7, ["y"] = 17, ["z"] = 3, ["name"] = "wool:white"}, {["x"] = 7, ["y"] = 17, ["z"] = 4, ["name"] = "wool:white"}, {["x"] = 7, ["y"] = 17, ["z"] = 9, ["name"] = "wool:white"}, {["x"] = 7, ["y"] = 17, ["z"] = 15, ["name"] = "wool:white"}, {["x"] = 7, ["y"] = 17, ["z"] = 31, ["name"] = "wool:white"}, {["x"] = 7, ["y"] = 18, ["z"] = 7, ["name"] = "wool:white"}, {["x"] = 7, ["y"] = 18, ["z"] = 11, ["name"] = "wool:white"}, {["x"] = 7, ["y"] = 18, ["z"] = 13, ["name"] = "wool:white"}, {["x"] = 7, ["y"] = 18, ["z"] = 17, ["name"] = "wool:white"}, {["x"] = 7, ["y"] = 18, ["z"] = 31, ["name"] = "wool:white"}, {["x"] = 7, ["y"] = 19, ["z"] = 9, ["name"] = "wool:white"}, {["x"] = 7, ["y"] = 19, ["z"] = 11, ["name"] = "wool:white"}, {["x"] = 7, ["y"] = 19, ["z"] = 13, ["name"] = "wool:white"}, {["x"] = 7, ["y"] = 19, ["z"] = 15, ["name"] = "wool:white"}, {["x"] = 7, ["y"] = 19, ["z"] = 19, ["name"] = "wool:white"}, {["x"] = 7, ["y"] = 19, ["z"] = 31, ["name"] = "wool:white"}, {["x"] = 7, ["y"] = 20, ["z"] = 7, ["name"] = "wool:white"}, {["x"] = 7, ["y"] = 20, ["z"] = 11, ["name"] = "wool:white"}, {["x"] = 7, ["y"] = 20, ["z"] = 13, ["name"] = "wool:white"}, {["x"] = 7, ["y"] = 20, ["z"] = 15, ["name"] = "wool:white"}, {["x"] = 7, ["y"] = 20, ["z"] = 17, ["name"] = "wool:white"}, {["x"] = 7, ["y"] = 20, ["z"] = 21, ["name"] = "wool:white"}, {["x"] = 7, ["y"] = 20, ["z"] = 23, ["name"] = "wool:white"}, {["x"] = 7, ["y"] = 20, ["z"] = 25, ["name"] = "wool:white"}, {["x"] = 7, ["y"] = 20, ["z"] = 27, ["name"] = "wool:white"}, {["x"] = 7, ["y"] = 20, ["z"] = 29, ["name"] = "wool:white"}, {["x"] = 7, ["y"] = 20, ["z"] = 31, ["name"] = "wool:white"}, {["x"] = 7, ["y"] = 21, ["z"] = 2, ["name"] = "wool:white"}, {["x"] = 7, ["y"] = 21, ["z"] = 3, ["name"] = "wool:white"}, {["x"] = 7, ["y"] = 21, ["z"] = 4, ["name"] = "wool:white"}, {["x"] = 7, ["y"] = 21, ["z"] = 5, ["name"] = "wool:white"}, {["x"] = 7, ["y"] = 21, ["z"] = 13, ["name"] = "wool:white"}, {["x"] = 7, ["y"] = 21, ["z"] = 15, ["name"] = "wool:white"}, {["x"] = 7, ["y"] = 21, ["z"] = 17, ["name"] = "wool:white"}, {["x"] = 7, ["y"] = 21, ["z"] = 19, ["name"] = "wool:white"}, {["x"] = 7, ["y"] = 21, ["z"] = 30, ["name"] = "wool:white"}, {["x"] = 7, ["y"] = 22, ["z"] = 15, ["name"] = "wool:white"}, {["x"] = 7, ["y"] = 22, ["z"] = 17, ["name"] = "wool:white"}, {["x"] = 7, ["y"] = 22, ["z"] = 19, ["name"] = "wool:white"}, {["x"] = 7, ["y"] = 22, ["z"] = 21, ["name"] = "wool:white"}, {["x"] = 7, ["y"] = 22, ["z"] = 23, ["name"] = "wool:white"}, {["x"] = 7, ["y"] = 22, ["z"] = 25, ["name"] = "wool:white"}, {["x"] = 7, ["y"] = 22, ["z"] = 27, ["name"] = "wool:white"}, {["x"] = 7, ["y"] = 22, ["z"] = 29, ["name"] = "wool:white"}, {["x"] = 8, ["y"] = 12, ["z"] = 16, ["name"] = "wool:white"}, {["x"] = 8, ["y"] = 12, ["z"] = 18, ["name"] = "wool:white"}, {["x"] = 8, ["y"] = 13, ["z"] = 14, ["name"] = "wool:white"}, {["x"] = 8, ["y"] = 13, ["z"] = 20, ["name"] = "wool:white"}, {["x"] = 8, ["y"] = 14, ["z"] = 22, ["name"] = "wool:white"}, {["x"] = 8, ["y"] = 16, ["z"] = 11, ["name"] = "wool:white"}, {["x"] = 8, ["y"] = 16, ["z"] = 13, ["name"] = "wool:white"}, {["x"] = 8, ["y"] = 17, ["z"] = 0, ["name"] = "wool:white"}, {["x"] = 8, ["y"] = 17, ["z"] = 1, ["name"] = "wool:white"}, {["x"] = 8, ["y"] = 17, ["z"] = 2, ["name"] = "wool:white"}, {["x"] = 8, ["y"] = 17, ["z"] = 3, ["name"] = "wool:white"}, {["x"] = 8, ["y"] = 17, ["z"] = 4, ["name"] = "wool:white"}, {["x"] = 8, ["y"] = 17, ["z"] = 9, ["name"] = "wool:white"}, {["x"] = 8, ["y"] = 17, ["z"] = 11, ["name"] = "wool:white"}, {["x"] = 8, ["y"] = 17, ["z"] = 13, ["name"] = "wool:white"}, {["x"] = 8, ["y"] = 17, ["z"] = 15, ["name"] = "wool:white"}, {["x"] = 8, ["y"] = 18, ["z"] = 7, ["name"] = "wool:white"}, {["x"] = 8, ["y"] = 18, ["z"] = 9, ["name"] = "wool:white"}, {["x"] = 8, ["y"] = 18, ["z"] = 11, ["name"] = "wool:white"}, {["x"] = 8, ["y"] = 18, ["z"] = 13, ["name"] = "wool:white"}, {["x"] = 8, ["y"] = 18, ["z"] = 15, ["name"] = "wool:white"}, {["x"] = 8, ["y"] = 18, ["z"] = 17, ["name"] = "wool:white"}, {["x"] = 8, ["y"] = 19, ["z"] = 0, ["name"] = "wool:white"}, {["x"] = 8, ["y"] = 19, ["z"] = 7, ["name"] = "wool:white"}, {["x"] = 8, ["y"] = 19, ["z"] = 9, ["name"] = "wool:white"}, {["x"] = 8, ["y"] = 19, ["z"] = 15, ["name"] = "wool:white"}, {["x"] = 8, ["y"] = 19, ["z"] = 17, ["name"] = "wool:white"}, {["x"] = 8, ["y"] = 19, ["z"] = 19, ["name"] = "wool:white"}, {["x"] = 8, ["y"] = 20, ["z"] = 1, ["name"] = "wool:white"}, {["x"] = 8, ["y"] = 20, ["z"] = 7, ["name"] = "wool:white"}, {["x"] = 8, ["y"] = 20, ["z"] = 17, ["name"] = "wool:white"}, {["x"] = 8, ["y"] = 20, ["z"] = 19, ["name"] = "wool:white"}, {["x"] = 8, ["y"] = 20, ["z"] = 21, ["name"] = "wool:white"}, {["x"] = 8, ["y"] = 20, ["z"] = 23, ["name"] = "wool:white"}, {["x"] = 8, ["y"] = 20, ["z"] = 25, ["name"] = "wool:white"}, {["x"] = 8, ["y"] = 20, ["z"] = 27, ["name"] = "wool:white"}, {["x"] = 8, ["y"] = 20, ["z"] = 29, ["name"] = "wool:white"}, {["x"] = 8, ["y"] = 21, ["z"] = 2, ["name"] = "wool:white"}, {["x"] = 8, ["y"] = 21, ["z"] = 3, ["name"] = "wool:white"}, {["x"] = 8, ["y"] = 21, ["z"] = 4, ["name"] = "wool:white"}, {["x"] = 8, ["y"] = 21, ["z"] = 5, ["name"] = "wool:white"}, {["x"] = 8, ["y"] = 21, ["z"] = 19, ["name"] = "wool:white"}, {["x"] = 8, ["y"] = 21, ["z"] = 21, ["name"] = "wool:white"}, {["x"] = 8, ["y"] = 21, ["z"] = 23, ["name"] = "wool:white"}, {["x"] = 8, ["y"] = 21, ["z"] = 25, ["name"] = "wool:white"}, {["x"] = 8, ["y"] = 21, ["z"] = 27, ["name"] = "wool:white"}, {["x"] = 8, ["y"] = 21, ["z"] = 29, ["name"] = "wool:white"}, {["x"] = 8, ["y"] = 22, ["z"] = 2, ["name"] = "wool:white"}, {["x"] = 8, ["y"] = 22, ["z"] = 21, ["name"] = "wool:white"}, {["x"] = 8, ["y"] = 22, ["z"] = 23, ["name"] = "wool:white"}, {["x"] = 8, ["y"] = 22, ["z"] = 25, ["name"] = "wool:white"}, {["x"] = 8, ["y"] = 22, ["z"] = 27, ["name"] = "wool:white"}, {["x"] = 8, ["y"] = 22, ["z"] = 29, ["name"] = "wool:white"}, {["x"] = 9, ["y"] = 12, ["z"] = 15, ["name"] = "wool:white"}, {["x"] = 9, ["y"] = 12, ["z"] = 17, ["name"] = "wool:white"}, {["x"] = 9, ["y"] = 13, ["z"] = 13, ["name"] = "wool:white"}, {["x"] = 9, ["y"] = 13, ["z"] = 19, ["name"] = "wool:white"}, {["x"] = 9, ["y"] = 14, ["z"] = 21, ["name"] = "wool:white"}, {["x"] = 9, ["y"] = 15, ["z"] = 23, ["name"] = "wool:white"}, {["x"] = 9, ["y"] = 17, ["z"] = 2, ["name"] = "wool:white"}, {["x"] = 9, ["y"] = 17, ["z"] = 3, ["name"] = "wool:white"}, {["x"] = 9, ["y"] = 17, ["z"] = 4, ["name"] = "wool:white"}, {["x"] = 9, ["y"] = 17, ["z"] = 28, ["name"] = "wool:white"}, {["x"] = 9, ["y"] = 17, ["z"] = 29, ["name"] = "wool:white"}, {["x"] = 9, ["y"] = 18, ["z"] = 3, ["name"] = "wool:white"}, {["x"] = 9, ["y"] = 18, ["z"] = 4, ["name"] = "wool:white"}, {["x"] = 9, ["y"] = 18, ["z"] = 13, ["name"] = "wool:white"}, {["x"] = 9, ["y"] = 18, ["z"] = 28, ["name"] = "wool:white"}, {["x"] = 9, ["y"] = 18, ["z"] = 29, ["name"] = "wool:white"}, {["x"] = 9, ["y"] = 18, ["z"] = 30, ["name"] = "wool:white"}, {["x"] = 9, ["y"] = 19, ["z"] = 1, ["name"] = "wool:white"}, {["x"] = 9, ["y"] = 19, ["z"] = 2, ["name"] = "wool:white"}, {["x"] = 9, ["y"] = 19, ["z"] = 4, ["name"] = "wool:white"}, {["x"] = 9, ["y"] = 19, ["z"] = 15, ["name"] = "wool:white"}, {["x"] = 9, ["y"] = 19, ["z"] = 28, ["name"] = "wool:white"}, {["x"] = 9, ["y"] = 20, ["z"] = 3, ["name"] = "wool:white"}, {["x"] = 9, ["y"] = 20, ["z"] = 4, ["name"] = "wool:white"}, {["x"] = 9, ["y"] = 20, ["z"] = 5, ["name"] = "wool:white"}, {["x"] = 9, ["y"] = 20, ["z"] = 17, ["name"] = "wool:white"}, {["x"] = 9, ["y"] = 20, ["z"] = 27, ["name"] = "wool:white"}, {["x"] = 9, ["y"] = 20, ["z"] = 28, ["name"] = "wool:white"}, {["x"] = 9, ["y"] = 21, ["z"] = 3, ["name"] = "wool:white"}, {["x"] = 9, ["y"] = 21, ["z"] = 4, ["name"] = "wool:white"}, {["x"] = 9, ["y"] = 21, ["z"] = 5, ["name"] = "wool:white"}, {["x"] = 9, ["y"] = 21, ["z"] = 19, ["name"] = "wool:white"}, {["x"] = 9, ["y"] = 22, ["z"] = 21, ["name"] = "wool:white"}, {["x"] = 9, ["y"] = 22, ["z"] = 23, ["name"] = "wool:white"}, {["x"] = 9, ["y"] = 23, ["z"] = 2, ["name"] = "wool:white"}, {["x"] = 10, ["y"] = 0, ["z"] = 26, ["name"] = "wool:white"}, {["x"] = 10, ["y"] = 0, ["z"] = 27, ["name"] = "wool:white"}, {["x"] = 10, ["y"] = 1, ["z"] = 26, ["name"] = "wool:white"}, {["x"] = 10, ["y"] = 1, ["z"] = 27, ["name"] = "wool:white"}, {["x"] = 10, ["y"] = 2, ["z"] = 27, ["name"] = "wool:white"}, {["x"] = 10, ["y"] = 3, ["z"] = 27, ["name"] = "wool:white"}, {["x"] = 10, ["y"] = 12, ["z"] = 15, ["name"] = "wool:white"}, {["x"] = 10, ["y"] = 12, ["z"] = 17, ["name"] = "wool:white"}, {["x"] = 10, ["y"] = 13, ["z"] = 13, ["name"] = "wool:white"}, {["x"] = 10, ["y"] = 13, ["z"] = 19, ["name"] = "wool:white"}, {["x"] = 10, ["y"] = 14, ["z"] = 13, ["name"] = "wool:white"}, {["x"] = 10, ["y"] = 14, ["z"] = 21, ["name"] = "wool:white"}, {["x"] = 10, ["y"] = 15, ["z"] = 23, ["name"] = "wool:white"}, {["x"] = 10, ["y"] = 15, ["z"] = 26, ["name"] = "wool:white"}, {["x"] = 10, ["y"] = 15, ["z"] = 27, ["name"] = "wool:white"}, {["x"] = 10, ["y"] = 16, ["z"] = 27, ["name"] = "wool:white"}, {["x"] = 10, ["y"] = 16, ["z"] = 28, ["name"] = "wool:white"}, {["x"] = 10, ["y"] = 17, ["z"] = 28, ["name"] = "wool:white"}, {["x"] = 10, ["y"] = 17, ["z"] = 29, ["name"] = "wool:white"}, {["x"] = 10, ["y"] = 18, ["z"] = 13, ["name"] = "wool:white"}, {["x"] = 10, ["y"] = 18, ["z"] = 28, ["name"] = "wool:white"}, {["x"] = 10, ["y"] = 18, ["z"] = 29, ["name"] = "wool:white"}, {["x"] = 10, ["y"] = 19, ["z"] = 15, ["name"] = "wool:white"}, {["x"] = 10, ["y"] = 19, ["z"] = 28, ["name"] = "wool:white"}, {["x"] = 10, ["y"] = 20, ["z"] = 17, ["name"] = "wool:white"}, {["x"] = 10, ["y"] = 20, ["z"] = 27, ["name"] = "wool:white"}, {["x"] = 10, ["y"] = 20, ["z"] = 28, ["name"] = "wool:white"}, {["x"] = 10, ["y"] = 21, ["z"] = 19, ["name"] = "wool:white"}, {["x"] = 10, ["y"] = 22, ["z"] = 21, ["name"] = "wool:white"}, {["x"] = 10, ["y"] = 22, ["z"] = 23, ["name"] = "wool:white"}, {["x"] = 11, ["y"] = 0, ["z"] = 13, ["name"] = "wool:white"}, {["x"] = 11, ["y"] = 0, ["z"] = 14, ["name"] = "wool:white"}, {["x"] = 11, ["y"] = 1, ["z"] = 13, ["name"] = "wool:white"}, {["x"] = 11, ["y"] = 1, ["z"] = 14, ["name"] = "wool:white"}, {["x"] = 11, ["y"] = 2, ["z"] = 14, ["name"] = "wool:white"}, {["x"] = 11, ["y"] = 3, ["z"] = 14, ["name"] = "wool:white"}, {["x"] = 11, ["y"] = 3, ["z"] = 27, ["name"] = "wool:white"}, {["x"] = 11, ["y"] = 4, ["z"] = 13, ["name"] = "wool:white"}, {["x"] = 11, ["y"] = 4, ["z"] = 14, ["name"] = "wool:white"}, {["x"] = 11, ["y"] = 4, ["z"] = 27, ["name"] = "wool:white"}, {["x"] = 11, ["y"] = 4, ["z"] = 28, ["name"] = "wool:white"}, {["x"] = 11, ["y"] = 5, ["z"] = 27, ["name"] = "wool:white"}, {["x"] = 11, ["y"] = 5, ["z"] = 28, ["name"] = "wool:white"}, {["x"] = 11, ["y"] = 6, ["z"] = 27, ["name"] = "wool:white"}, {["x"] = 11, ["y"] = 6, ["z"] = 28, ["name"] = "wool:white"}, {["x"] = 11, ["y"] = 7, ["z"] = 27, ["name"] = "wool:white"}, {["x"] = 11, ["y"] = 7, ["z"] = 28, ["name"] = "wool:white"}, {["x"] = 11, ["y"] = 8, ["z"] = 27, ["name"] = "wool:white"}, {["x"] = 11, ["y"] = 8, ["z"] = 28, ["name"] = "wool:white"}, {["x"] = 11, ["y"] = 9, ["z"] = 28, ["name"] = "wool:white"}, {["x"] = 11, ["y"] = 9, ["z"] = 29, ["name"] = "wool:white"}, {["x"] = 11, ["y"] = 10, ["z"] = 27, ["name"] = "wool:white"}, {["x"] = 11, ["y"] = 10, ["z"] = 28, ["name"] = "wool:white"}, {["x"] = 11, ["y"] = 10, ["z"] = 30, ["name"] = "wool:white"}, {["x"] = 11, ["y"] = 11, ["z"] = 27, ["name"] = "wool:white"}, {["x"] = 11, ["y"] = 11, ["z"] = 28, ["name"] = "wool:white"}, {["x"] = 11, ["y"] = 12, ["z"] = 15, ["name"] = "wool:white"}, {["x"] = 11, ["y"] = 12, ["z"] = 17, ["name"] = "wool:white"}, {["x"] = 11, ["y"] = 12, ["z"] = 27, ["name"] = "wool:white"}, {["x"] = 11, ["y"] = 12, ["z"] = 28, ["name"] = "wool:white"}, {["x"] = 11, ["y"] = 13, ["z"] = 19, ["name"] = "wool:white"}, {["x"] = 11, ["y"] = 13, ["z"] = 26, ["name"] = "wool:white"}, {["x"] = 11, ["y"] = 13, ["z"] = 27, ["name"] = "wool:white"}, {["x"] = 11, ["y"] = 14, ["z"] = 21, ["name"] = "wool:white"}, {["x"] = 11, ["y"] = 14, ["z"] = 26, ["name"] = "wool:white"}, {["x"] = 11, ["y"] = 14, ["z"] = 27, ["name"] = "wool:white"}, {["x"] = 11, ["y"] = 15, ["z"] = 13, ["name"] = "wool:white"}, {["x"] = 11, ["y"] = 15, ["z"] = 23, ["name"] = "wool:white"}, {["x"] = 11, ["y"] = 15, ["z"] = 26, ["name"] = "wool:white"}, {["x"] = 11, ["y"] = 15, ["z"] = 27, ["name"] = "wool:white"}, {["x"] = 11, ["y"] = 16, ["z"] = 13, ["name"] = "wool:white"}, {["x"] = 11, ["y"] = 16, ["z"] = 27, ["name"] = "wool:white"}, {["x"] = 11, ["y"] = 16, ["z"] = 28, ["name"] = "wool:white"}, {["x"] = 11, ["y"] = 17, ["z"] = 13, ["name"] = "wool:white"}, {["x"] = 11, ["y"] = 18, ["z"] = 13, ["name"] = "wool:white"}, {["x"] = 11, ["y"] = 19, ["z"] = 15, ["name"] = "wool:white"}, {["x"] = 11, ["y"] = 20, ["z"] = 17, ["name"] = "wool:white"}, {["x"] = 11, ["y"] = 21, ["z"] = 19, ["name"] = "wool:white"}, {["x"] = 11, ["y"] = 22, ["z"] = 21, ["name"] = "wool:white"}, {["x"] = 11, ["y"] = 22, ["z"] = 23, ["name"] = "wool:white"}, {["x"] = 12, ["y"] = 0, ["z"] = 26, ["name"] = "wool:white"}, {["x"] = 12, ["y"] = 0, ["z"] = 27, ["name"] = "wool:white"}, {["x"] = 12, ["y"] = 1, ["z"] = 26, ["name"] = "wool:white"}, {["x"] = 12, ["y"] = 1, ["z"] = 27, ["name"] = "wool:white"}, {["x"] = 12, ["y"] = 2, ["z"] = 27, ["name"] = "wool:white"}, {["x"] = 12, ["y"] = 3, ["z"] = 14, ["name"] = "wool:white"}, {["x"] = 12, ["y"] = 3, ["z"] = 27, ["name"] = "wool:white"}, {["x"] = 12, ["y"] = 4, ["z"] = 13, ["name"] = "wool:white"}, {["x"] = 12, ["y"] = 4, ["z"] = 14, ["name"] = "wool:white"}, {["x"] = 12, ["y"] = 4, ["z"] = 27, ["name"] = "wool:white"}, {["x"] = 12, ["y"] = 4, ["z"] = 28, ["name"] = "wool:white"}, {["x"] = 12, ["y"] = 5, ["z"] = 12, ["name"] = "wool:white"}, {["x"] = 12, ["y"] = 5, ["z"] = 13, ["name"] = "wool:white"}, {["x"] = 12, ["y"] = 5, ["z"] = 27, ["name"] = "wool:white"}, {["x"] = 12, ["y"] = 5, ["z"] = 28, ["name"] = "wool:white"}, {["x"] = 12, ["y"] = 6, ["z"] = 12, ["name"] = "wool:white"}, {["x"] = 12, ["y"] = 6, ["z"] = 13, ["name"] = "wool:white"}, {["x"] = 12, ["y"] = 6, ["z"] = 27, ["name"] = "wool:white"}, {["x"] = 12, ["y"] = 6, ["z"] = 28, ["name"] = "wool:white"}, {["x"] = 12, ["y"] = 7, ["z"] = 13, ["name"] = "wool:white"}, {["x"] = 12, ["y"] = 7, ["z"] = 14, ["name"] = "wool:white"}, {["x"] = 12, ["y"] = 7, ["z"] = 27, ["name"] = "wool:white"}, {["x"] = 12, ["y"] = 7, ["z"] = 28, ["name"] = "wool:white"}, {["x"] = 12, ["y"] = 8, ["z"] = 13, ["name"] = "wool:white"}, {["x"] = 12, ["y"] = 8, ["z"] = 14, ["name"] = "wool:white"}, {["x"] = 12, ["y"] = 8, ["z"] = 27, ["name"] = "wool:white"}, {["x"] = 12, ["y"] = 8, ["z"] = 28, ["name"] = "wool:white"}, {["x"] = 12, ["y"] = 9, ["z"] = 14, ["name"] = "wool:white"}, {["x"] = 12, ["y"] = 9, ["z"] = 15, ["name"] = "wool:white"}, {["x"] = 12, ["y"] = 9, ["z"] = 28, ["name"] = "wool:white"}, {["x"] = 12, ["y"] = 9, ["z"] = 29, ["name"] = "wool:white"}, {["x"] = 12, ["y"] = 10, ["z"] = 13, ["name"] = "wool:white"}, {["x"] = 12, ["y"] = 10, ["z"] = 14, ["name"] = "wool:white"}, {["x"] = 12, ["y"] = 10, ["z"] = 27, ["name"] = "wool:white"}, {["x"] = 12, ["y"] = 10, ["z"] = 28, ["name"] = "wool:white"}, {["x"] = 12, ["y"] = 10, ["z"] = 30, ["name"] = "wool:white"}, {["x"] = 12, ["y"] = 11, ["z"] = 12, ["name"] = "wool:white"}, {["x"] = 12, ["y"] = 11, ["z"] = 13, ["name"] = "wool:white"}, {["x"] = 12, ["y"] = 11, ["z"] = 27, ["name"] = "wool:white"}, {["x"] = 12, ["y"] = 11, ["z"] = 28, ["name"] = "wool:white"}, {["x"] = 12, ["y"] = 12, ["z"] = 11, ["name"] = "wool:white"}, {["x"] = 12, ["y"] = 12, ["z"] = 12, ["name"] = "wool:white"}, {["x"] = 12, ["y"] = 12, ["z"] = 15, ["name"] = "wool:white"}, {["x"] = 12, ["y"] = 12, ["z"] = 17, ["name"] = "wool:white"}, {["x"] = 12, ["y"] = 12, ["z"] = 27, ["name"] = "wool:white"}, {["x"] = 12, ["y"] = 12, ["z"] = 28, ["name"] = "wool:white"}, {["x"] = 12, ["y"] = 13, ["z"] = 12, ["name"] = "wool:white"}, {["x"] = 12, ["y"] = 13, ["z"] = 13, ["name"] = "wool:white"}, {["x"] = 12, ["y"] = 13, ["z"] = 19, ["name"] = "wool:white"}, {["x"] = 12, ["y"] = 13, ["z"] = 26, ["name"] = "wool:white"}, {["x"] = 12, ["y"] = 13, ["z"] = 27, ["name"] = "wool:white"}, {["x"] = 12, ["y"] = 14, ["z"] = 12, ["name"] = "wool:white"}, {["x"] = 12, ["y"] = 14, ["z"] = 13, ["name"] = "wool:white"}, {["x"] = 12, ["y"] = 14, ["z"] = 21, ["name"] = "wool:white"}, {["x"] = 12, ["y"] = 14, ["z"] = 26, ["name"] = "wool:white"}, {["x"] = 12, ["y"] = 14, ["z"] = 27, ["name"] = "wool:white"}, {["x"] = 12, ["y"] = 15, ["z"] = 11, ["name"] = "wool:white"}, {["x"] = 12, ["y"] = 15, ["z"] = 12, ["name"] = "wool:white"}, {["x"] = 12, ["y"] = 15, ["z"] = 23, ["name"] = "wool:white"}, {["x"] = 12, ["y"] = 18, ["z"] = 13, ["name"] = "wool:white"}, {["x"] = 12, ["y"] = 19, ["z"] = 15, ["name"] = "wool:white"}, {["x"] = 12, ["y"] = 20, ["z"] = 17, ["name"] = "wool:white"}, {["x"] = 12, ["y"] = 21, ["z"] = 19, ["name"] = "wool:white"}, {["x"] = 12, ["y"] = 22, ["z"] = 21, ["name"] = "wool:white"}, {["x"] = 12, ["y"] = 22, ["z"] = 23, ["name"] = "wool:white"}, {["x"] = 13, ["y"] = 0, ["z"] = 13, ["name"] = "wool:white"}, {["x"] = 13, ["y"] = 0, ["z"] = 14, ["name"] = "wool:white"}, {["x"] = 13, ["y"] = 1, ["z"] = 13, ["name"] = "wool:white"}, {["x"] = 13, ["y"] = 1, ["z"] = 14, ["name"] = "wool:white"}, {["x"] = 13, ["y"] = 2, ["z"] = 14, ["name"] = "wool:white"}, {["x"] = 13, ["y"] = 3, ["z"] = 14, ["name"] = "wool:white"}, {["x"] = 13, ["y"] = 4, ["z"] = 13, ["name"] = "wool:white"}, {["x"] = 13, ["y"] = 4, ["z"] = 14, ["name"] = "wool:white"}, {["x"] = 13, ["y"] = 5, ["z"] = 12, ["name"] = "wool:white"}, {["x"] = 13, ["y"] = 5, ["z"] = 13, ["name"] = "wool:white"}, {["x"] = 13, ["y"] = 6, ["z"] = 12, ["name"] = "wool:white"}, {["x"] = 13, ["y"] = 6, ["z"] = 13, ["name"] = "wool:white"}, {["x"] = 13, ["y"] = 7, ["z"] = 13, ["name"] = "wool:white"}, {["x"] = 13, ["y"] = 7, ["z"] = 14, ["name"] = "wool:white"}, {["x"] = 13, ["y"] = 8, ["z"] = 13, ["name"] = "wool:white"}, {["x"] = 13, ["y"] = 8, ["z"] = 14, ["name"] = "wool:white"}, {["x"] = 13, ["y"] = 9, ["z"] = 14, ["name"] = "wool:white"}, {["x"] = 13, ["y"] = 9, ["z"] = 15, ["name"] = "wool:white"}, {["x"] = 13, ["y"] = 10, ["z"] = 13, ["name"] = "wool:white"}, {["x"] = 13, ["y"] = 10, ["z"] = 14, ["name"] = "wool:white"}, {["x"] = 13, ["y"] = 11, ["z"] = 12, ["name"] = "wool:white"}, {["x"] = 13, ["y"] = 11, ["z"] = 13, ["name"] = "wool:white"}, {["x"] = 13, ["y"] = 12, ["z"] = 11, ["name"] = "wool:white"}, {["x"] = 13, ["y"] = 12, ["z"] = 12, ["name"] = "wool:white"}, {["x"] = 13, ["y"] = 12, ["z"] = 15, ["name"] = "wool:white"}, {["x"] = 13, ["y"] = 12, ["z"] = 17, ["name"] = "wool:white"}, {["x"] = 13, ["y"] = 13, ["z"] = 12, ["name"] = "wool:white"}, {["x"] = 13, ["y"] = 13, ["z"] = 13, ["name"] = "wool:white"}, {["x"] = 13, ["y"] = 13, ["z"] = 15, ["name"] = "wool:white"}, {["x"] = 13, ["y"] = 13, ["z"] = 17, ["name"] = "wool:white"}, {["x"] = 13, ["y"] = 13, ["z"] = 19, ["name"] = "wool:white"}, {["x"] = 13, ["y"] = 14, ["z"] = 12, ["name"] = "wool:white"}, {["x"] = 13, ["y"] = 14, ["z"] = 13, ["name"] = "wool:white"}, {["x"] = 13, ["y"] = 14, ["z"] = 15, ["name"] = "wool:white"}, {["x"] = 13, ["y"] = 14, ["z"] = 17, ["name"] = "wool:white"}, {["x"] = 13, ["y"] = 14, ["z"] = 19, ["name"] = "wool:white"}, {["x"] = 13, ["y"] = 14, ["z"] = 21, ["name"] = "wool:white"}, {["x"] = 13, ["y"] = 15, ["z"] = 11, ["name"] = "wool:white"}, {["x"] = 13, ["y"] = 15, ["z"] = 12, ["name"] = "wool:white"}, {["x"] = 13, ["y"] = 15, ["z"] = 15, ["name"] = "wool:white"}, {["x"] = 13, ["y"] = 15, ["z"] = 17, ["name"] = "wool:white"}, {["x"] = 13, ["y"] = 15, ["z"] = 19, ["name"] = "wool:white"}, {["x"] = 13, ["y"] = 15, ["z"] = 21, ["name"] = "wool:white"}, {["x"] = 13, ["y"] = 15, ["z"] = 23, ["name"] = "wool:white"}, {["x"] = 13, ["y"] = 16, ["z"] = 12, ["name"] = "wool:white"}, {["x"] = 13, ["y"] = 16, ["z"] = 15, ["name"] = "wool:white"}, {["x"] = 13, ["y"] = 16, ["z"] = 17, ["name"] = "wool:white"}, {["x"] = 13, ["y"] = 16, ["z"] = 19, ["name"] = "wool:white"}, {["x"] = 13, ["y"] = 16, ["z"] = 21, ["name"] = "wool:white"}, {["x"] = 13, ["y"] = 16, ["z"] = 23, ["name"] = "wool:white"}, {["x"] = 13, ["y"] = 17, ["z"] = 12, ["name"] = "wool:white"}, {["x"] = 13, ["y"] = 17, ["z"] = 13, ["name"] = "wool:white"}, {["x"] = 13, ["y"] = 17, ["z"] = 15, ["name"] = "wool:white"}, {["x"] = 13, ["y"] = 17, ["z"] = 17, ["name"] = "wool:white"}, {["x"] = 13, ["y"] = 17, ["z"] = 19, ["name"] = "wool:white"}, {["x"] = 13, ["y"] = 17, ["z"] = 21, ["name"] = "wool:white"}, {["x"] = 13, ["y"] = 17, ["z"] = 23, ["name"] = "wool:white"}, {["x"] = 13, ["y"] = 18, ["z"] = 12, ["name"] = "wool:white"}, {["x"] = 13, ["y"] = 18, ["z"] = 13, ["name"] = "wool:white"}, {["x"] = 13, ["y"] = 18, ["z"] = 15, ["name"] = "wool:white"}, {["x"] = 13, ["y"] = 18, ["z"] = 17, ["name"] = "wool:white"}, {["x"] = 13, ["y"] = 18, ["z"] = 19, ["name"] = "wool:white"}, {["x"] = 13, ["y"] = 18, ["z"] = 21, ["name"] = "wool:white"}, {["x"] = 13, ["y"] = 18, ["z"] = 23, ["name"] = "wool:white"}, {["x"] = 13, ["y"] = 19, ["z"] = 15, ["name"] = "wool:white"}, {["x"] = 13, ["y"] = 19, ["z"] = 17, ["name"] = "wool:white"}, {["x"] = 13, ["y"] = 19, ["z"] = 19, ["name"] = "wool:white"}, {["x"] = 13, ["y"] = 19, ["z"] = 21, ["name"] = "wool:white"}, {["x"] = 13, ["y"] = 19, ["z"] = 23, ["name"] = "wool:white"}, {["x"] = 13, ["y"] = 20, ["z"] = 17, ["name"] = "wool:white"}, {["x"] = 13, ["y"] = 20, ["z"] = 19, ["name"] = "wool:white"}, {["x"] = 13, ["y"] = 20, ["z"] = 21, ["name"] = "wool:white"}, {["x"] = 13, ["y"] = 20, ["z"] = 23, ["name"] = "wool:white"}, {["x"] = 13, ["y"] = 21, ["z"] = 19, ["name"] = "wool:white"}, {["x"] = 13, ["y"] = 21, ["z"] = 21, ["name"] = "wool:white"}, {["x"] = 13, ["y"] = 21, ["z"] = 23, ["name"] = "wool:white"}, {["x"] = 13, ["y"] = 22, ["z"] = 21, ["name"] = "wool:white"}, {["x"] = 13, ["y"] = 22, ["z"] = 23, ["name"] = "wool:white"}}