5:return {{["x"] = 0, ["y"] = 0, ["z"] = 18, ["name"] = "wool:white"}, {["x"] = 0, ["y"] = 0, ["z"] = 19, ["name"] = "wool:white"}, {["x"] = 0, ["y"] = 1, ["z"] = 18, ["name"] = "wool:white"}, {["x"] = 0, ["y"] = 1, ["z"] = 19, ["name"] = "wool:white"}, {["x"] = 0, ["y"] = 2, ["z"] = 19, ["name"] = "wool:white"}, {["x"] = 0, ["y"] = 2, ["z"] = 20, ["name"] = "wool:white"}, {["x"] = 0, ["y"] = 3, ["z"] = 19, ["name"] = "wool:white"}, {["x"] = 0, ["y"] = 3, ["z"] = 20, ["name"] = "wool:white"}, {["x"] = 0, ["y"] = 4, ["z"] = 19, ["name"] = "wool:white"}, {["x"] = 0, ["y"] = 4, ["z"] = 20, ["name"] = "wool:white"}, {["x"] = 0, ["y"] = 5, ["z"] = 20, ["name"] = "wool:white"}, {["x"] = 0, ["y"] = 5, ["z"] = 21, ["name"] = "wool:white"}, {["x"] = 0, ["y"] = 6, ["z"] = 19, ["name"] = "wool:white"}, {["x"] = 0, ["y"] = 6, ["z"] = 20, ["name"] = "wool:white"}, {["x"] = 0, ["y"] = 7, ["z"] = 19, ["name"] = "wool:white"}, {["x"] = 0, ["y"] = 7, ["z"] = 20, ["name"] = "wool:white"}, {["x"] = 0, ["y"] = 8, ["z"] = 19, ["name"] = "wool:white"}, {["x"] = 0, ["y"] = 8, ["z"] = 20, ["name"] = "wool:white"}, {["x"] = 0, ["y"] = 9, ["z"] = 20, ["name"] = "wool:white"}, {["x"] = 0, ["y"] = 10, ["z"] = 20, ["name"] = "wool:white"}, {["x"] = 0, ["y"] = 14, ["z"] = 18, ["name"] = "wool:white"}, {["x"] = 0, ["y"] = 15, ["z"] = 19, ["name"] = "wool:white"}, {["x"] = 0, ["y"] = 16, ["z"] = 39, ["name"] = "wool:white"}, {["x"] = 0, ["y"] = 17, ["z"] = 39, ["name"] = "wool:white"}, {["x"] = 0, ["y"] = 18, ["z"] = 39, ["name"] = "wool:white"}, {["x"] = 0, ["y"] = 19, ["z"] = 39, ["name"] = "wool:white"}, {["x"] = 0, ["y"] = 20, ["z"] = 39, ["name"] = "wool:white"}, {["x"] = 1, ["y"] = 0, ["z"] = 18, ["name"] = "wool:white"}, {["x"] = 1, ["y"] = 0, ["z"] = 19, ["name"] = "wool:white"}, {["x"] = 1, ["y"] = 1, ["z"] = 18, ["name"] = "wool:white"}, {["x"] = 1, ["y"] = 1, ["z"] = 19, ["name"] = "wool:white"}, {["x"] = 1, ["y"] = 2, ["z"] = 19, ["name"] = "wool:white"}, {["x"] = 1, ["y"] = 2, ["z"] = 20, ["name"] = "wool:white"}, {["x"] = 1, ["y"] = 3, ["z"] = 19, ["name"] = "wool:white"}, {["x"] = 1, ["y"] = 3, ["z"] = 20, ["name"] = "wool:white"}, {["x"] = 1, ["y"] = 4, ["z"] = 19, ["name"] = "wool:white"}, {["x"] = 1, ["y"] = 4, ["z"] = 20, ["name"] = "wool:white"}, {["x"] = 1, ["y"] = 5, ["z"] = 20, ["name"] = "wool:white"}, {["x"] = 1, ["y"] = 5, ["z"] = 21, ["name"] = "wool:white"}, {["x"] = 1, ["y"] = 6, ["z"] = 19, ["name"] = "wool:white"}, {["x"] = 1, ["y"] = 6, ["z"] = 20, ["name"] = "wool:white"}, {["x"] = 1, ["y"] = 7, ["z"] = 19, ["name"] = "wool:white"}, {["x"] = 1, ["y"] = 7, ["z"] = 20, ["name"] = "wool:white"}, {["x"] = 1, ["y"] = 8, ["z"] = 19, ["name"] = "wool:white"}, {["x"] = 1, ["y"] = 8, ["z"] = 20, ["name"] = "wool:white"}, {["x"] = 1, ["y"] = 9, ["z"] = 18, ["name"] = "wool:white"}, {["x"] = 1, ["y"] = 9, ["z"] = 19, ["name"] = "wool:white"}, {["x"] = 1, ["y"] = 9, ["z"] = 20, ["name"] = "wool:white"}, {["x"] = 1, ["y"] = 10, ["z"] = 17, ["name"] = "wool:white"}, {["x"] = 1, ["y"] = 10, ["z"] = 18, ["name"] = "wool:white"}, {["x"] = 1, ["y"] = 10, ["z"] = 20, ["name"] = "wool:white"}, {["x"] = 1, ["y"] = 11, ["z"] = 17, ["name"] = "wool:white"}, {["x"] = 1, ["y"] = 12, ["z"] = 16, ["name"] = "wool:white"}, {["x"] = 1, ["y"] = 12, ["z"] = 17, ["name"] = "wool:white"}, {["x"] = 1, ["y"] = 12, ["z"] = 21, ["name"] = "wool:white"}, {["x"] = 1, ["y"] = 12, ["z"] = 23, ["name"] = "wool:white"}, {["x"] = 1, ["y"] = 13, ["z"] = 16, ["name"] = "wool:white"}, {["x"] = 1, ["y"] = 13, ["z"] = 17, ["name"] = "wool:white"}, {["x"] = 1, ["y"] = 13, ["z"] = 21, ["name"] = "wool:white"}, {["x"] = 1, ["y"] = 13, ["z"] = 23, ["name"] = "wool:white"}, {["x"] = 1, ["y"] = 14, ["z"] = 17, ["name"] = "wool:white"}, {["x"] = 1, ["y"] = 14, ["z"] = 21, ["name"] = "wool:white"}, {["x"] = 1, ["y"] = 14, ["z"] = 23, ["name"] = "wool:white"}, {["x"] = 1, ["y"] = 15, ["z"] = 17, ["name"] = "wool:white"}, {["x"] = 1, ["y"] = 15, ["z"] = 18, ["name"] = "wool:white"}, {["x"] = 1, ["y"] = 16, ["z"] = 18, ["name"] = "wool:white"}, {["x"] = 1, ["y"] = 16, ["z"] = 19, ["name"] = "wool:white"}, {["x"] = 1, ["y"] = 17, ["z"] = 19, ["name"] = "wool:white"}, {["x"] = 1, ["y"] = 17, ["z"] = 20, ["name"] = "wool:white"}, {["x"] = 1, ["y"] = 17, ["z"] = 40, ["name"] = "wool:white"}, {["x"] = 1, ["y"] = 18, ["z"] = 21, ["name"] = "wool:white"}, {["x"] = 1, ["y"] = 18, ["z"] = 40, ["name"] = "wool:white"}, {["x"] = 1, ["y"] = 19, ["z"] = 40, ["name"] = "wool:white"}, {["x"] = 2, ["y"] = 0, ["z"] = 39, ["name"] = "wool:white"}, {["x"] = 2, ["y"] = 0, ["z"] = 40, ["name"] = "wool:white"}, {["x"] = 2, ["y"] = 1, ["z"] = 39, ["name"] = "wool:white"}, {["x"] = 2, ["y"] = 1, ["z"] = 40, ["name"] = "wool:white"}, {["x"] = 2, ["y"] = 1, ["z"] = 41, ["name"] = "wool:white"}, {["x"] = 2, ["y"] = 2, ["z"] = 41, ["name"] = "wool:white"}, {["x"] = 2, ["y"] = 2, ["z"] = 42, ["name"] = "wool:white"}, {["x"] = 2, ["y"] = 3, ["z"] = 42, ["name"] = "wool:white"}, {["x"] = 2, ["y"] = 3, ["z"] = 43, ["name"] = "wool:white"}, {["x"] = 2, ["y"] = 4, ["z"] = 42, ["name"] = "wool:white"}, {["x"] = 2, ["y"] = 4, ["z"] = 43, ["name"] = "wool:white"}, {["x"] = 2, ["y"] = 4, ["z"] = 44, ["name"] = "wool:white"}, {["x"] = 2, ["y"] = 5, ["z"] = 42, ["name"] = "wool:white"}, {["x"] = 2, ["y"] = 5, ["z"] = 43, ["name"] = "wool:white"}, {["x"] = 2, ["y"] = 5, ["z"] = 45, ["name"] = "wool:white"}, {["x"] = 2, ["y"] = 6, ["z"] = 41, ["name"] = "wool:white"}, {["x"] = 2, ["y"] = 6, ["z"] = 42, ["name"] = "wool:white"}, {["x"] = 2, ["y"] = 7, ["z"] = 41, ["name"] = "wool:white"}, {["x"] = 2, ["y"] = 7, ["z"] = 42, ["name"] = "wool:white"}, {["x"] = 2, ["y"] = 8, ["z"] = 41, ["name"] = "wool:white"}, {["x"] = 2, ["y"] = 8, ["z"] = 42, ["name"] = "wool:white"}, {["x"] = 2, ["y"] = 9, ["z"] = 18, ["name"] = "wool:white"}, {["x"] = 2, ["y"] = 9, ["z"] = 19, ["name"] = "wool:white"}, {["x"] = 2, ["y"] = 9, ["z"] = 40, ["name"] = "wool:white"}, {["x"] = 2, ["y"] = 9, ["z"] = 41, ["name"] = "wool:white"}, {["x"] = 2, ["y"] = 10, ["z"] = 17, ["name"] = "wool:white"}, {["x"] = 2, ["y"] = 10, ["z"] = 18, ["name"] = "wool:white"}, {["x"] = 2, ["y"] = 10, ["z"] = 21, ["name"] = "wool:white"}, {["x"] = 2, ["y"] = 10, ["z"] = 40, ["name"] = "wool:white"}, {["x"] = 2, ["y"] = 10, ["z"] = 41, ["name"] = "wool:white"}, {["x"] = 2, ["y"] = 11, ["z"] = 17, ["name"] = "wool:white"}, {["x"] = 2, ["y"] = 11, ["z"] = 21, ["name"] = "wool:white"}, {["x"] = 2, ["y"] = 11, ["z"] = 23, ["name"] = "wool:white"}, {["x"] = 2, ["y"] = 11, ["z"] = 40, ["name"] = "wool:white"}, {["x"] = 2, ["y"] = 11, ["z"] = 41, ["name"] = "wool:white"}, {["x"] = 2, ["y"] = 12, ["z"] = 16, ["name"] = "wool:white"}, {["x"] = 2, ["y"] = 12, ["z"] = 17, ["name"] = "wool:white"}, {["x"] = 2, ["y"] = 12, ["z"] = 19, ["name"] = "wool:white"}, {["x"] = 2, ["y"] = 12, ["z"] = 41, ["name"] = "wool:white"}, {["x"] = 2, ["y"] = 12, ["z"] = 42, ["name"] = "wool:white"}, {["x"] = 2, ["y"] = 13, ["z"] = 16, ["name"] = "wool:white"}, {["x"] = 2, ["y"] = 13, ["z"] = 17, ["name"] = "wool:white"}, {["x"] = 2, ["y"] = 13, ["z"] = 19, ["name"] = "wool:white"}, {["x"] = 2, ["y"] = 13, ["z"] = 25, ["name"] = "wool:white"}, {["x"] = 2, ["y"] = 13, ["z"] = 41, ["name"] = "wool:white"}, {["x"] = 2, ["y"] = 13, ["z"] = 42, ["name"] = "wool:white"}, {["x"] = 2, ["y"] = 14, ["z"] = 16, ["name"] = "wool:white"}, {["x"] = 2, ["y"] = 14, ["z"] = 19, ["name"] = "wool:white"}, {["x"] = 2, ["y"] = 14, ["z"] = 25, ["name"] = "wool:white"}, {["x"] = 2, ["y"] = 14, ["z"] = 27, ["name"] = "wool:white"}, {["x"] = 2, ["y"] = 15, ["z"] = 16, ["name"] = "wool:white"}, {["x"] = 2, ["y"] = 15, ["z"] = 21, ["name"] = "wool:white"}, {["x"] = 2, ["y"] = 15, ["z"] = 23, ["name"] = "wool:white"}, {["x"] = 2, ["y"] = 15, ["z"] = 25, ["name"] = "wool:white"}, {["x"] = 2, ["y"] = 15, ["z"] = 27, ["name"] = "wool:white"}, {["x"] = 2, ["y"] = 15, ["z"] = 29, ["name"] = "wool:white"}, {["x"] = 2, ["y"] = 16, ["z"] = 17, ["name"] = "wool:white"}, {["x"] = 2, ["y"] = 16, ["z"] = 21, ["name"] = "wool:white"}, {["x"] = 2, ["y"] = 16, ["z"] = 23, ["name"] = "wool:white"}, {["x"] = 2, ["y"] = 16, ["z"] = 25, ["name"] = "wool:white"}, {["x"] = 2, ["y"] = 16, ["z"] = 27, ["name"] = "wool:white"}, {["x"] = 2, ["y"] = 16, ["z"] = 29, ["name"] = "wool:white"}, {["x"] = 2, ["y"] = 17, ["z"] = 18, ["name"] = "wool:white"}, {["x"] = 2, ["y"] = 17, ["z"] = 19, ["name"] = "wool:white"}, {["x"] = 2, ["y"] = 17, ["z"] = 41, ["name"] = "wool:white"}, {["x"] = 2, ["y"] = 18, ["z"] = 20, ["name"] = "wool:white"}, {["x"] = 2, ["y"] = 18, ["z"] = 22, ["name"] = "wool:white"}, {["x"] = 2, ["y"] = 18, ["z"] = 41, ["name"] = "wool:white"}, {["x"] = 2, ["y"] = 19, ["z"] = 21, ["name"] = "wool:white"}, {["x"] = 2, ["y"] = 19, ["z"] = 41, ["name"] = "wool:white"}, {["x"] = 3, ["y"] = 0, ["z"] = 39, ["name"] = "wool:white"}, {["x"] = 3, ["y"] = 0, ["z"] = 40, ["name"] = "wool:white"}, {["x"] = 3, ["y"] = 1, ["z"] = 39, ["name"] = "wool:white"}, {["x"] = 3, ["y"] = 1, ["z"] = 40, ["name"] = "wool:white"}, {["x"] = 3, ["y"] = 1, ["z"] = 41, ["name"] = "wool:white"}, {["x"] = 3, ["y"] = 2, ["z"] = 41, ["name"] = "wool:white"}, {["x"] = 3, ["y"] = 2, ["z"] = 42, ["name"] = "wool:white"}, {["x"] = 3, ["y"] = 3, ["z"] = 42, ["name"] = "wool:white"}, {["x"] = 3, ["y"] = 3, ["z"] = 43, ["name"] = "wool:white"}, {["x"] = 3, ["y"] = 4, ["z"] = 42, ["name"] = "wool:white"}, {["x"] = 3, ["y"] = 4, ["z"] = 43, ["name"] = "wool:white"}, {["x"] = 3, ["y"] = 4, ["z"] = 44, ["name"] = "wool:white"}, {["x"] = 3, ["y"] = 5, ["z"] = 42, ["name"] = "wool:white"}, {["x"] = 3, ["y"] = 5, ["z"] = 43, ["name"] = "wool:white"}, {["x"] = 3, ["y"] = 5, ["z"] = 45, ["name"] = "wool:white"}, {["x"] = 3, ["y"] = 6, ["z"] = 41, ["name"] = "wool:white"}, {["x"] = 3, ["y"] = 6, ["z"] = 42, ["name"] = "wool:white"}, {["x"] = 3, ["y"] = 7, ["z"] = 41, ["name"] = "wool:white"}, {["x"] = 3, ["y"] = 7, ["z"] = 42, ["name"] = "wool:white"}, {["x"] = 3, ["y"] = 8, ["z"] = 41, ["name"] = "wool:white"}, {["x"] = 3, ["y"] = 8, ["z"] = 42, ["name"] = "wool:white"}, {["x"] = 3, ["y"] = 9, ["z"] = 21, ["name"] = "wool:white"}, {["x"] = 3, ["y"] = 9, ["z"] = 40, ["name"] = "wool:white"}, {["x"] = 3, ["y"] = 9, ["z"] = 41, ["name"] = "wool:white"}, {["x"] = 3, ["y"] = 10, ["z"] = 19, ["name"] = "wool:white"}, {["x"] = 3, ["y"] = 10, ["z"] = 23, ["name"] = "wool:white"}, {["x"] = 3, ["y"] = 10, ["z"] = 40, ["name"] = "wool:white"}, {["x"] = 3, ["y"] = 10, ["z"] = 41, ["name"] = "wool:white"}, {["x"] = 3, ["y"] = 11, ["z"] = 19, ["name"] = "wool:white"}, {["x"] = 3, ["y"] = 11, ["z"] = 25, ["name"] = "wool:white"}, {["x"] = 3, ["y"] = 11, ["z"] = 40, ["name"] = "wool:white"}, {["x"] = 3, ["y"] = 11, ["z"] = 41, ["name"] = "wool:white"}, {["x"] = 3, ["y"] = 12, ["z"] = 25, ["name"] = "wool:white"}, {["x"] = 3, ["y"] = 12, ["z"] = 27, ["name"] = "wool:white"}, {["x"] = 3, ["y"] = 12, ["z"] = 41, ["name"] = "wool:white"}, {["x"] = 3, ["y"] = 12, ["z"] = 42, ["name"] = "wool:white"}, {["x"] = 3, ["y"] = 13, ["z"] = 27, ["name"] = "wool:white"}, {["x"] = 3, ["y"] = 13, ["z"] = 41, ["name"] = "wool:white"}, {["x"] = 3, ["y"] = 13, ["z"] = 42, ["name"] = "wool:white"}, {["x"] = 3, ["y"] = 14, ["z"] = 29, ["name"] = "wool:white"}, {["x"] = 3, ["y"] = 14, ["z"] = 43, ["name"] = "wool:white"}, {["x"] = 3, ["y"] = 14, ["z"] = 44, ["name"] = "wool:white"}, {["x"] = 3, ["y"] = 15, ["z"] = 19, ["name"] = "wool:white"}, {["x"] = 3, ["y"] = 15, ["z"] = 31, ["name"] = "wool:white"}, {["x"] = 3, ["y"] = 15, ["z"] = 33, ["name"] = "wool:white"}, {["x"] = 3, ["y"] = 15, ["z"] = 42, ["name"] = "wool:white"}, {["x"] = 3, ["y"] = 15, ["z"] = 43, ["name"] = "wool:white"}, {["x"] = 3, ["y"] = 15, ["z"] = 44, ["name"] = "wool:white"}, {["x"] = 3, ["y"] = 16, ["z"] = 19, ["name"] = "wool:white"}, {["x"] = 3, ["y"] = 16, ["z"] = 31, ["name"] = "wool:white"}, {["x"] = 3, ["y"] = 16, ["z"] = 33, ["name"] = "wool:white"}, {["x"] = 3, ["y"] = 16, ["z"] = 42, ["name"] = "wool:white"}, {["x"] = 3, ["y"] = 17, ["z"] = 21, ["name"] = "wool:white"}, {["x"] = 3, ["y"] = 17, ["z"] = 23, ["name"] = "wool:white"}, {["x"] = 3, ["y"] = 17, ["z"] = 25, ["name"] = "wool:white"}, {["x"] = 3, ["y"] = 17, ["z"] = 27, ["name"] = "wool:white"}, {["x"] = 3, ["y"] = 17, ["z"] = 29, ["name"] = "wool:white"}, {["x"] = 3, ["y"] = 17, ["z"] = 42, ["name"] = "wool:white"}, {["x"] = 3, ["y"] = 18, ["z"] = 18, ["name"] = "wool:white"}, {["x"] = 3, ["y"] = 18, ["z"] = 19, ["name"] = "wool:white"}, {["x"] = 3, ["y"] = 18, ["z"] = 42, ["name"] = "wool:white"}, {["x"] = 3, ["y"] = 19, ["z"] = 20, ["name"] = "wool:white"}, {["x"] = 3, ["y"] = 19, ["z"] = 21, ["name"] = "wool:white"}, {["x"] = 3, ["y"] = 19, ["z"] = 22, ["name"] = "wool:white"}, {["x"] = 3, ["y"] = 19, ["z"] = 39, ["name"] = "wool:white"}, {["x"] = 3, ["y"] = 19, ["z"] = 42, ["name"] = "wool:white"}, {["x"] = 3, ["y"] = 20, ["z"] = 41, ["name"] = "wool:white"}, {["x"] = 4, ["y"] = 9, ["z"] = 19, ["name"] = "wool:white"}, {["x"] = 4, ["y"] = 9, ["z"] = 21, ["name"] = "wool:white"}, {["x"] = 4, ["y"] = 10, ["z"] = 23, ["name"] = "wool:white"}, {["x"] = 4, ["y"] = 10, ["z"] = 25, ["name"] = "wool:white"}, {["x"] = 4, ["y"] = 11, ["z"] = 27, ["name"] = "wool:white"}, {["x"] = 4, ["y"] = 13, ["z"] = 29, ["name"] = "wool:white"}, {["x"] = 4, ["y"] = 13, ["z"] = 31, ["name"] = "wool:white"}, {["x"] = 4, ["y"] = 13, ["z"] = 43, ["name"] = "wool:white"}, {["x"] = 4, ["y"] = 13, ["z"] = 44, ["name"] = "wool:white"}, {["x"] = 4, ["y"] = 13, ["z"] = 45, ["name"] = "wool:white"}, {["x"] = 4, ["y"] = 14, ["z"] = 31, ["name"] = "wool:white"}, {["x"] = 4, ["y"] = 14, ["z"] = 33, ["name"] = "wool:white"}, {["x"] = 4, ["y"] = 17, ["z"] = 19, ["name"] = "wool:white"}, {["x"] = 4, ["y"] = 17, ["z"] = 21, ["name"] = "wool:white"}, {["x"] = 4, ["y"] = 17, ["z"] = 23, ["name"] = "wool:white"}, {["x"] = 4, ["y"] = 17, ["z"] = 31, ["name"] = "wool:white"}, {["x"] = 4, ["y"] = 17, ["z"] = 33, ["name"] = "wool:white"}, {["x"] = 4, ["y"] = 18, ["z"] = 25, ["name"] = "wool:white"}, {["x"] = 4, ["y"] = 18, ["z"] = 27, ["name"] = "wool:white"}, {["x"] = 4, ["y"] = 18, ["z"] = 29, ["name"] = "wool:white"}, {["x"] = 4, ["y"] = 18, ["z"] = 31, ["name"] = "wool:white"}, {["x"] = 4, ["y"] = 18, ["z"] = 33, ["name"] = "wool:white"}, {["x"] = 4, ["y"] = 19, ["z"] = 18, ["name"] = "wool:white"}, {["x"] = 4, ["y"] = 19, ["z"] = 19, ["name"] = "wool:white"}, {["x"] = 4, ["y"] = 19, ["z"] = 20, ["name"] = "wool:white"}, {["x"] = 4, ["y"] = 19, ["z"] = 35, ["name"] = "wool:white"}, {["x"] = 4, ["y"] = 19, ["z"] = 37, ["name"] = "wool:white"}, {["x"] = 4, ["y"] = 19, ["z"] = 39, ["name"] = "wool:white"}, {["x"] = 4, ["y"] = 19, ["z"] = 41, ["name"] = "wool:white"}, {["x"] = 4, ["y"] = 19, ["z"] = 43, ["name"] = "wool:white"}, {["x"] = 4, ["y"] = 20, ["z"] = 21, ["name"] = "wool:white"}, {["x"] = 4, ["y"] = 20, ["z"] = 22, ["name"] = "wool:white"}, {["x"] = 4, ["y"] = 20, ["z"] = 42, ["name"] = "wool:white"}, {["x"] = 5, ["y"] = 9, ["z"] = 19, ["name"] = "wool:white"}, {["x"] = 5, ["y"] = 9, ["z"] = 21, ["name"] = "wool:white"}, {["x"] = 5, ["y"] = 10, ["z"] = 23, ["name"] = "wool:white"}, {["x"] = 5, ["y"] = 10, ["z"] = 25, ["name"] = "wool:white"}, {["x"] = 5, ["y"] = 11, ["z"] = 27, ["name"] = "wool:white"}, {["x"] = 5, ["y"] = 12, ["z"] = 29, ["name"] = "wool:white"}, {["x"] = 5, ["y"] = 12, ["z"] = 30, ["name"] = "wool:white"}, {["x"] = 5, ["y"] = 12, ["z"] = 31, ["name"] = "wool:white"}, {["x"] = 5, ["y"] = 13, ["z"] = 32, ["name"] = "wool:white"}, {["x"] = 5, ["y"] = 13, ["z"] = 33, ["name"] = "wool:white"}, {["x"] = 5, ["y"] = 13, ["z"] = 43, ["name"] = "wool:white"}, {["x"] = 5, ["y"] = 13, ["z"] = 44, ["name"] = "wool:white"}, {["x"] = 5, ["y"] = 13, ["z"] = 45, ["name"] = "wool:white"}, {["x"] = 5, ["meta"] = {["fields"] = {}, ["inventory"] = {}}, ["y"] = 16, ["param1"] = 25, ["z"] = 6, ["name"] = "wool:white"}, {["x"] = 5, ["meta"] = {["fields"] = {}, ["inventory"] = {}}, ["y"] = 17, ["param1"] = 25, ["z"] = 6, ["name"] = "wool:white"}, {["x"] = 5, ["meta"] = {["fields"] = {}, ["inventory"] = {}}, ["y"] = 17, ["param1"] = 25, ["z"] = 7, ["name"] = "wool:white"}, {["x"] = 5, ["meta"] = {["fields"] = {}, ["inventory"] = {}}, ["y"] = 17, ["param1"] = 25, ["z"] = 8, ["name"] = "wool:white"}, {["x"] = 5, ["y"] = 17, ["z"] = 19, ["name"] = "wool:white"}, {["x"] = 5, ["y"] = 17, ["z"] = 21, ["name"] = "wool:white"}, {["x"] = 5, ["y"] = 17, ["z"] = 23, ["name"] = "wool:white"}, {["x"] = 5, ["meta"] = {["fields"] = {}, ["inventory"] = {}}, ["y"] = 18, ["param1"] = 25, ["z"] = 6, ["name"] = "wool:white"}, {["x"] = 5, ["meta"] = {["fields"] = {}, ["inventory"] = {}}, ["y"] = 18, ["param1"] = 25, ["z"] = 7, ["name"] = "wool:white"}, {["x"] = 5, ["meta"] = {["fields"] = {}, ["inventory"] = {}}, ["y"] = 18, ["param1"] = 25, ["z"] = 8, ["name"] = "wool:white"}, {["x"] = 5, ["meta"] = {["fields"] = {}, ["inventory"] = {}}, ["y"] = 18, ["param1"] = 25, ["z"] = 9, ["name"] = "wool:white"}, {["x"] = 5, ["y"] = 18, ["z"] = 25, ["name"] = "wool:white"}, {["x"] = 5, ["y"] = 18, ["z"] = 27, ["name"] = "wool:white"}, {["x"] = 5, ["meta"] = {["fields"] = {}, ["inventory"] = {}}, ["y"] = 19, ["param1"] = 25, ["z"] = 5, ["name"] = "wool:white"}, {["x"] = 5, ["meta"] = {["fields"] = {}, ["inventory"] = {}}, ["y"] = 19, ["param1"] = 25, ["z"] = 6, ["name"] = "wool:white"}, {["x"] = 5, ["meta"] = {["fields"] = {}, ["inventory"] = {}}, ["y"] = 19, ["param1"] = 25, ["z"] = 7, ["name"] = "wool:white"}, {["x"] = 5, ["meta"] = {["fields"] = {}, ["inventory"] = {}}, ["y"] = 19, ["param1"] = 25, ["z"] = 9, ["name"] = "wool:white"}, {["x"] = 5, ["meta"] = {["fields"] = {}, ["inventory"] = {}}, ["y"] = 19, ["param1"] = 25, ["z"] = 10, ["name"] = "wool:white"}, {["x"] = 5, ["y"] = 19, ["z"] = 29, ["name"] = "wool:white"}, {["x"] = 5, ["y"] = 19, ["z"] = 31, ["name"] = "wool:white"}, {["x"] = 5, ["y"] = 19, ["z"] = 33, ["name"] = "wool:white"}, {["x"] = 5, ["y"] = 19, ["z"] = 35, ["name"] = "wool:white"}, {["x"] = 5, ["y"] = 19, ["z"] = 37, ["name"] = "wool:white"}, {["x"] = 5, ["y"] = 19, ["z"] = 39, ["name"] = "wool:white"}, {["x"] = 5, ["y"] = 19, ["z"] = 41, ["name"] = "wool:white"}, {["x"] = 5, ["y"] = 19, ["z"] = 43, ["name"] = "wool:white"}, {["x"] = 5, ["meta"] = {["fields"] = {}, ["inventory"] = {}}, ["y"] = 20, ["param1"] = 25, ["z"] = 6, ["name"] = "wool:white"}, {["x"] = 5, ["meta"] = {["fields"] = {}, ["inventory"] = {}}, ["y"] = 20, ["param1"] = 25, ["z"] = 7, ["name"] = "wool:white"}, {["x"] = 5, ["meta"] = {["fields"] = {}, ["inventory"] = {}}, ["y"] = 20, ["param1"] = 25, ["z"] = 8, ["name"] = "wool:white"}, {["x"] = 5, ["meta"] = {["fields"] = {}, ["inventory"] = {}}, ["y"] = 20, ["param1"] = 25, ["z"] = 10, ["name"] = "wool:white"}, {["x"] = 5, ["y"] = 20, ["z"] = 19, ["name"] = "wool:white"}, {["x"] = 5, ["y"] = 20, ["z"] = 20, ["name"] = "wool:white"}, {["x"] = 5, ["y"] = 20, ["z"] = 21, ["name"] = "wool:white"}, {["x"] = 5, ["y"] = 20, ["z"] = 22, ["name"] = "wool:white"}, {["x"] = 5, ["y"] = 20, ["z"] = 42, ["name"] = "wool:white"}, {["x"] = 5, ["meta"] = {["fields"] = {}, ["inventory"] = {}}, ["y"] = 21, ["param1"] = 25, ["z"] = 7, ["name"] = "wool:white"}, {["x"] = 5, ["meta"] = {["fields"] = {}, ["inventory"] = {}}, ["y"] = 21, ["param1"] = 25, ["z"] = 9, ["name"] = "wool:white"}, {["x"] = 5, ["meta"] = {["fields"] = {}, ["inventory"] = {}}, ["y"] = 21, ["param1"] = 25, ["z"] = 10, ["name"] = "wool:white"}, {["x"] = 5, ["meta"] = {["fields"] = {}, ["inventory"] = {}}, ["y"] = 22, ["param1"] = 25, ["z"] = 8, ["name"] = "wool:white"}, {["x"] = 5, ["meta"] = {["fields"] = {}, ["inventory"] = {}}, ["y"] = 22, ["param1"] = 25, ["z"] = 9, ["name"] = "wool:white"}, {["x"] = 5, ["meta"] = {["fields"] = {}, ["inventory"] = {}}, ["y"] = 22, ["param1"] = 25, ["z"] = 10, ["name"] = "wool:white"}, {["x"] = 6, ["y"] = 9, ["z"] = 18, ["name"] = "wool:white"}, {["x"] = 6, ["y"] = 9, ["z"] = 20, ["name"] = "wool:white"}, {["x"] = 6, ["y"] = 9, ["z"] = 22, ["name"] = "wool:white"}, {["x"] = 6, ["y"] = 10, ["z"] = 24, ["name"] = "wool:white"}, {["x"] = 6, ["y"] = 10, ["z"] = 26, ["name"] = "wool:white"}, {["x"] = 6, ["y"] = 11, ["z"] = 28, ["name"] = "wool:white"}, {["x"] = 6, ["y"] = 12, ["z"] = 43, ["name"] = "wool:white"}, {["x"] = 6, ["y"] = 12, ["z"] = 44, ["name"] = "wool:white"}, {["x"] = 6, ["y"] = 15, ["z"] = 19, ["name"] = "wool:white"}, {["x"] = 6, ["y"] = 15, ["z"] = 21, ["name"] = "wool:white"}, {["x"] = 6, ["y"] = 15, ["z"] = 23, ["name"] = "wool:white"}, {["x"] = 6, ["meta"] = {["fields"] = {}, ["inventory"] = {}}, ["y"] = 16, ["param1"] = 25, ["z"] = 4, ["name"] = "wool:white"}, {["x"] = 6, ["meta"] = {["fields"] = {}, ["inventory"] = {}}, ["y"] = 16, ["param1"] = 25, ["z"] = 5, ["name"] = "wool:white"}, {["x"] = 6, ["y"] = 16, ["z"] = 17, ["name"] = "wool:white"}, {["x"] = 6, ["y"] = 16, ["z"] = 19, ["name"] = "wool:white"}, {["x"] = 6, ["y"] = 16, ["z"] = 21, ["name"] = "wool:white"}, {["x"] = 6, ["y"] = 16, ["z"] = 23, ["name"] = "wool:white"}, {["x"] = 6, ["y"] = 16, ["z"] = 25, ["name"] = "wool:white"}, {["x"] = 6, ["y"] = 16, ["z"] = 27, ["name"] = "wool:white"}, {["x"] = 6, ["meta"] = {["fields"] = {}, ["inventory"] = {}}, ["y"] = 17, ["param1"] = 25, ["z"] = 5, ["name"] = "wool:white"}, {["x"] = 6, ["meta"] = {["fields"] = {}, ["inventory"] = {}}, ["y"] = 17, ["param1"] = 25, ["z"] = 15, ["name"] = "wool:white"}, {["x"] = 6, ["y"] = 17, ["z"] = 17, ["name"] = "wool:white"}, {["x"] = 6, ["y"] = 17, ["z"] = 19, ["name"] = "wool:white"}, {["x"] = 6, ["y"] = 17, ["z"] = 21, ["name"] = "wool:white"}, {["x"] = 6, ["y"] = 17, ["z"] = 23, ["name"] = "wool:white"}, {["x"] = 6, ["y"] = 17, ["z"] = 25, ["name"] = "wool:white"}, {["x"] = 6, ["y"] = 17, ["z"] = 27, ["name"] = "wool:white"}, {["x"] = 6, ["y"] = 17, ["z"] = 29, ["name"] = "wool:white"}, {["x"] = 6, ["y"] = 17, ["z"] = 31, ["name"] = "wool:white"}, {["x"] = 6, ["y"] = 17, ["z"] = 33, ["name"] = "wool:white"}, {["x"] = 6, ["y"] = 17, ["z"] = 35, ["name"] = "wool:white"}, {["x"] = 6, ["y"] = 17, ["z"] = 37, ["name"] = "wool:white"}, {["x"] = 6, ["y"] = 17, ["z"] = 39, ["name"] = "wool:white"}, {["x"] = 6, ["y"] = 17, ["z"] = 41, ["name"] = "wool:white"}, {["x"] = 6, ["y"] = 17, ["z"] = 43, ["name"] = "wool:white"}, {["x"] = 6, ["meta"] = {["fields"] = {}, ["inventory"] = {}}, ["y"] = 18, ["param1"] = 25, ["z"] = 4, ["name"] = "wool:white"}, {["x"] = 6, ["meta"] = {["fields"] = {}, ["inventory"] = {}}, ["y"] = 18, ["param1"] = 25, ["z"] = 13, ["name"] = "wool:white"}, {["x"] = 6, ["meta"] = {["fields"] = {}, ["inventory"] = {}}, ["y"] = 18, ["param1"] = 25, ["z"] = 15, ["name"] = "wool:white"}, {["x"] = 6, ["y"] = 18, ["z"] = 17, ["name"] = "wool:white"}, {["x"] = 6, ["y"] = 18, ["z"] = 25, ["name"] = "wool:white"}, {["x"] = 6, ["y"] = 18, ["z"] = 27, ["name"] = "wool:white"}, {["x"] = 6, ["y"] = 18, ["z"] = 29, ["name"] = "wool:white"}, {["x"] = 6, ["y"] = 18, ["z"] = 31, ["name"] = "wool:white"}, {["x"] = 6, ["y"] = 18, ["z"] = 33, ["name"] = "wool:white"}, {["x"] = 6, ["y"] = 18, ["z"] = 35, ["name"] = "wool:white"}, {["x"] = 6, ["y"] = 18, ["z"] = 37, ["name"] = "wool:white"}, {["x"] = 6, ["y"] = 18, ["z"] = 39, ["name"] = "wool:white"}, {["x"] = 6, ["y"] = 18, ["z"] = 41, ["name"] = "wool:white"}, {["x"] = 6, ["y"] = 18, ["z"] = 43, ["name"] = "wool:white"}, {["x"] = 6, ["meta"] = {["fields"] = {}, ["inventory"] = {}}, ["y"] = 19, ["param1"] = 25, ["z"] = 11, ["name"] = "wool:white"}, {["x"] = 6, ["meta"] = {["fields"] = {}, ["inventory"] = {}}, ["y"] = 19, ["param1"] = 25, ["z"] = 13, ["name"] = "wool:white"}, {["x"] = 6, ["meta"] = {["fields"] = {}, ["inventory"] = {}}, ["y"] = 19, ["param1"] = 25, ["z"] = 15, ["name"] = "wool:white"}, {["x"] = 6, ["y"] = 19, ["z"] = 29, ["name"] = "wool:white"}, {["x"] = 6, ["y"] = 19, ["z"] = 31, ["name"] = "wool:white"}, {["x"] = 6, ["y"] = 19, ["z"] = 33, ["name"] = "wool:white"}, {["x"] = 6, ["y"] = 19, ["z"] = 35, ["name"] = "wool:white"}, {["x"] = 6, ["y"] = 19, ["z"] = 37, ["name"] = "wool:white"}, {["x"] = 6, ["y"] = 19, ["z"] = 39, ["name"] = "wool:white"}, {["x"] = 6, ["y"] = 19, ["z"] = 41, ["name"] = "wool:white"}, {["x"] = 6, ["y"] = 19, ["z"] = 43, ["name"] = "wool:white"}, {["x"] = 6, ["meta"] = {["fields"] = {}, ["inventory"] = {}}, ["y"] = 20, ["param1"] = 25, ["z"] = 6, ["name"] = "wool:white"}, {["x"] = 6, ["meta"] = {["fields"] = {}, ["inventory"] = {}}, ["y"] = 20, ["param1"] = 25, ["z"] = 11, ["name"] = "wool:white"}, {["x"] = 6, ["meta"] = {["fields"] = {}, ["inventory"] = {}}, ["y"] = 20, ["param1"] = 25, ["z"] = 13, ["name"] = "wool:white"}, {["x"] = 6, ["y"] = 20, ["z"] = 20, ["name"] = "wool:white"}, {["x"] = 6, ["y"] = 20, ["z"] = 21, ["name"] = "wool:white"}, {["x"] = 6, ["meta"] = {["fields"] = {}, ["inventory"] = {}}, ["y"] = 21, ["param1"] = 25, ["z"] = 7, ["name"] = "wool:white"}, {["x"] = 6, ["meta"] = {["fields"] = {}, ["inventory"] = {}}, ["y"] = 21, ["param1"] = 25, ["z"] = 11, ["name"] = "wool:white"}, {["x"] = 6, ["meta"] = {["fields"] = {}, ["inventory"] = {}}, ["y"] = 22, ["param1"] = 25, ["z"] = 8, ["name"] = "wool:white"}, {["x"] = 6, ["meta"] = {["fields"] = {}, ["inventory"] = {}}, ["y"] = 22, ["param1"] = 25, ["z"] = 9, ["name"] = "wool:white"}, {["x"] = 7, ["y"] = 9, ["z"] = 17, ["name"] = "wool:white"}, {["x"] = 7, ["y"] = 9, ["z"] = 18, ["name"] = "wool:white"}, {["x"] = 7, ["y"] = 9, ["z"] = 20, ["name"] = "wool:white"}, {["x"] = 7, ["y"] = 9, ["z"] = 22, ["name"] = "wool:white"}, {["x"] = 7, ["y"] = 9, ["z"] = 47, ["name"] = "wool:white"}, {["x"] = 7, ["y"] = 10, ["z"] = 24, ["name"] = "wool:white"}, {["x"] = 7, ["y"] = 10, ["z"] = 26, ["name"] = "wool:white"}, {["x"] = 7, ["y"] = 10, ["z"] = 47, ["name"] = "wool:white"}, {["x"] = 7, ["y"] = 11, ["z"] = 28, ["name"] = "wool:white"}, {["x"] = 7, ["y"] = 11, ["z"] = 47, ["name"] = "wool:white"}, {["x"] = 7, ["y"] = 12, ["z"] = 43, ["name"] = "wool:white"}, {["x"] = 7, ["y"] = 12, ["z"] = 44, ["name"] = "wool:white"}, {["x"] = 7, ["y"] = 12, ["z"] = 47, ["name"] = "wool:white"}, {["x"] = 7, ["y"] = 13, ["z"] = 47, ["name"] = "wool:white"}, {["x"] = 7, ["y"] = 14, ["z"] = 47, ["name"] = "wool:white"}, {["x"] = 7, ["y"] = 15, ["z"] = 19, ["name"] = "wool:white"}, {["x"] = 7, ["y"] = 15, ["z"] = 21, ["name"] = "wool:white"}, {["x"] = 7, ["y"] = 15, ["z"] = 23, ["name"] = "wool:white"}, {["x"] = 7, ["y"] = 15, ["z"] = 47, ["name"] = "wool:white"}, {["x"] = 7, ["meta"] = {["fields"] = {}, ["inventory"] = {}}, ["y"] = 16, ["param1"] = 25, ["z"] = 3, ["name"] = "wool:white"}, {["x"] = 7, ["y"] = 16, ["z"] = 17, ["name"] = "wool:white"}, {["x"] = 7, ["y"] = 16, ["z"] = 25, ["name"] = "wool:white"}, {["x"] = 7, ["y"] = 16, ["z"] = 27, ["name"] = "wool:white"}, {["x"] = 7, ["y"] = 16, ["z"] = 47, ["name"] = "wool:white"}, {["x"] = 7, ["meta"] = {["fields"] = {}, ["inventory"] = {}}, ["y"] = 17, ["param1"] = 25, ["z"] = 3, ["name"] = "wool:white"}, {["x"] = 7, ["meta"] = {["fields"] = {}, ["inventory"] = {}}, ["y"] = 17, ["param1"] = 25, ["z"] = 15, ["name"] = "wool:white"}, {["x"] = 7, ["y"] = 17, ["z"] = 19, ["name"] = "wool:white"}, {["x"] = 7, ["y"] = 17, ["z"] = 21, ["name"] = "wool:white"}, {["x"] = 7, ["y"] = 17, ["z"] = 23, ["name"] = "wool:white"}, {["x"] = 7, ["y"] = 17, ["z"] = 29, ["name"] = "wool:white"}, {["x"] = 7, ["y"] = 17, ["z"] = 31, ["name"] = "wool:white"}, {["x"] = 7, ["y"] = 17, ["z"] = 33, ["name"] = "wool:white"}, {["x"] = 7, ["y"] = 17, ["z"] = 35, ["name"] = "wool:white"}, {["x"] = 7, ["y"] = 17, ["z"] = 37, ["name"] = "wool:white"}, {["x"] = 7, ["y"] = 17, ["z"] = 39, ["name"] = "wool:white"}, {["x"] = 7, ["y"] = 17, ["z"] = 41, ["name"] = "wool:white"}, {["x"] = 7, ["y"] = 17, ["z"] = 43, ["name"] = "wool:white"}, {["x"] = 7, ["y"] = 17, ["z"] = 46, ["name"] = "wool:white"}, {["x"] = 7, ["meta"] = {["fields"] = {}, ["inventory"] = {}}, ["y"] = 18, ["param1"] = 25, ["z"] = 3, ["name"] = "wool:white"}, {["x"] = 7, ["meta"] = {["fields"] = {}, ["inventory"] = {}}, ["y"] = 18, ["param1"] = 25, ["z"] = 13, ["name"] = "wool:white"}, {["x"] = 7, ["y"] = 18, ["z"] = 17, ["name"] = "wool:white"}, {["x"] = 7, ["y"] = 18, ["z"] = 19, ["name"] = "wool:white"}, {["x"] = 7, ["y"] = 18, ["z"] = 21, ["name"] = "wool:white"}, {["x"] = 7, ["y"] = 18, ["z"] = 23, ["name"] = "wool:white"}, {["x"] = 7, ["y"] = 18, ["z"] = 25, ["name"] = "wool:white"}, {["x"] = 7, ["y"] = 18, ["z"] = 27, ["name"] = "wool:white"}, {["x"] = 7, ["y"] = 18, ["z"] = 44, ["name"] = "wool:white"}, {["x"] = 7, ["y"] = 18, ["z"] = 45, ["name"] = "wool:white"}, {["x"] = 7, ["meta"] = {["fields"] = {}, ["inventory"] = {}}, ["y"] = 19, ["param1"] = 25, ["z"] = 5, ["name"] = "wool:white"}, {["x"] = 7, ["meta"] = {["fields"] = {}, ["inventory"] = {}}, ["y"] = 19, ["param1"] = 25, ["z"] = 11, ["name"] = "wool:white"}, {["x"] = 7, ["meta"] = {["fields"] = {}, ["inventory"] = {}}, ["y"] = 19, ["param1"] = 25, ["z"] = 15, ["name"] = "wool:white"}, {["x"] = 7, ["y"] = 19, ["z"] = 17, ["name"] = "wool:white"}, {["x"] = 7, ["y"] = 19, ["z"] = 19, ["name"] = "wool:white"}, {["x"] = 7, ["y"] = 19, ["z"] = 21, ["name"] = "wool:white"}, {["x"] = 7, ["y"] = 19, ["z"] = 23, ["name"] = "wool:white"}, {["x"] = 7, ["y"] = 19, ["z"] = 25, ["name"] = "wool:white"}, {["x"] = 7, ["y"] = 19, ["z"] = 27, ["name"] = "wool:white"}, {["x"] = 7, ["y"] = 19, ["z"] = 29, ["name"] = "wool:white"}, {["x"] = 7, ["y"] = 19, ["z"] = 31, ["name"] = "wool:white"}, {["x"] = 7, ["y"] = 19, ["z"] = 33, ["name"] = "wool:white"}, {["x"] = 7, ["y"] = 19, ["z"] = 35, ["name"] = "wool:white"}, {["x"] = 7, ["y"] = 19, ["z"] = 37, ["name"] = "wool:white"}, {["x"] = 7, ["y"] = 19, ["z"] = 39, ["name"] = "wool:white"}, {["x"] = 7, ["y"] = 19, ["z"] = 41, ["name"] = "wool:white"}, {["x"] = 7, ["y"] = 19, ["z"] = 43, ["name"] = "wool:white"}, {["x"] = 7, ["meta"] = {["fields"] = {}, ["inventory"] = {}}, ["y"] = 20, ["param1"] = 25, ["z"] = 6, ["name"] = "wool:white"}, {["x"] = 7, ["meta"] = {["fields"] = {}, ["inventory"] = {}}, ["y"] = 20, ["param1"] = 25, ["z"] = 13, ["name"] = "wool:white"}, {["x"] = 7, ["meta"] = {["fields"] = {}, ["inventory"] = {}}, ["y"] = 21, ["param1"] = 25, ["z"] = 7, ["name"] = "wool:white"}, {["x"] = 7, ["meta"] = {["fields"] = {}, ["inventory"] = {}}, ["y"] = 21, ["param1"] = 25, ["z"] = 8, ["name"] = "wool:white"}, {["x"] = 7, ["meta"] = {["fields"] = {}, ["inventory"] = {}}, ["y"] = 21, ["param1"] = 25, ["z"] = 11, ["name"] = "wool:white"}, {["x"] = 7, ["meta"] = {["fields"] = {}, ["inventory"] = {}}, ["y"] = 22, ["param1"] = 25, ["z"] = 8, ["name"] = "wool:white"}, {["x"] = 7, ["meta"] = {["fields"] = {}, ["inventory"] = {}}, ["y"] = 22, ["param1"] = 25, ["z"] = 9, ["name"] = "wool:white"}, {["x"] = 7, ["meta"] = {["fields"] = {}, ["inventory"] = {}}, ["y"] = 22, ["param1"] = 25, ["z"] = 10, ["name"] = "wool:white"}, {["x"] = 7, ["meta"] = {["fields"] = {}, ["inventory"] = {}}, ["y"] = 22, ["param1"] = 25, ["z"] = 11, ["name"] = "wool:white"}, {["x"] = 8, ["y"] = 9, ["z"] = 18, ["name"] = "wool:white"}, {["x"] = 8, ["y"] = 9, ["z"] = 20, ["name"] = "wool:white"}, {["x"] = 8, ["y"] = 9, ["z"] = 22, ["name"] = "wool:white"}, {["x"] = 8, ["y"] = 10, ["z"] = 24, ["name"] = "wool:white"}, {["x"] = 8, ["y"] = 10, ["z"] = 26, ["name"] = "wool:white"}, {["x"] = 8, ["y"] = 11, ["z"] = 28, ["name"] = "wool:white"}, {["x"] = 8, ["y"] = 12, ["z"] = 43, ["name"] = "wool:white"}, {["x"] = 8, ["y"] = 12, ["z"] = 44, ["name"] = "wool:white"}, {["x"] = 8, ["y"] = 15, ["z"] = 19, ["name"] = "wool:white"}, {["x"] = 8, ["y"] = 15, ["z"] = 21, ["name"] = "wool:white"}, {["x"] = 8, ["y"] = 15, ["z"] = 23, ["name"] = "wool:white"}, {["x"] = 8, ["meta"] = {["fields"] = {}, ["inventory"] = {}}, ["y"] = 16, ["param1"] = 25, ["z"] = 4, ["name"] = "wool:white"}, {["x"] = 8, ["meta"] = {["fields"] = {}, ["inventory"] = {}}, ["y"] = 16, ["param1"] = 25, ["z"] = 5, ["name"] = "wool:white"}, {["x"] = 8, ["y"] = 16, ["z"] = 17, ["name"] = "wool:white"}, {["x"] = 8, ["y"] = 16, ["z"] = 19, ["name"] = "wool:white"}, {["x"] = 8, ["y"] = 16, ["z"] = 21, ["name"] = "wool:white"}, {["x"] = 8, ["y"] = 16, ["z"] = 23, ["name"] = "wool:white"}, {["x"] = 8, ["y"] = 16, ["z"] = 25, ["name"] = "wool:white"}, {["x"] = 8, ["y"] = 16, ["z"] = 27, ["name"] = "wool:white"}, {["x"] = 8, ["meta"] = {["fields"] = {}, ["inventory"] = {}}, ["y"] = 17, ["param1"] = 25, ["z"] = 5, ["name"] = "wool:white"}, {["x"] = 8, ["meta"] = {["fields"] = {}, ["inventory"] = {}}, ["y"] = 17, ["param1"] = 25, ["z"] = 15, ["name"] = "wool:white"}, {["x"] = 8, ["y"] = 17, ["z"] = 17, ["name"] = "wool:white"}, {["x"] = 8, ["y"] = 17, ["z"] = 19, ["name"] = "wool:white"}, {["x"] = 8, ["y"] = 17, ["z"] = 21, ["name"] = "wool:white"}, {["x"] = 8, ["y"] = 17, ["z"] = 23, ["name"] = "wool:white"}, {["x"] = 8, ["y"] = 17, ["z"] = 25, ["name"] = "wool:white"}, {["x"] = 8, ["y"] = 17, ["z"] = 27, ["name"] = "wool:white"}, {["x"] = 8, ["y"] = 17, ["z"] = 29, ["name"] = "wool:white"}, {["x"] = 8, ["y"] = 17, ["z"] = 31, ["name"] = "wool:white"}, {["x"] = 8, ["y"] = 17, ["z"] = 33, ["name"] = "wool:white"}, {["x"] = 8, ["y"] = 17, ["z"] = 35, ["name"] = "wool:white"}, {["x"] = 8, ["y"] = 17, ["z"] = 37, ["name"] = "wool:white"}, {["x"] = 8, ["y"] = 17, ["z"] = 39, ["name"] = "wool:white"}, {["x"] = 8, ["y"] = 17, ["z"] = 41, ["name"] = "wool:white"}, {["x"] = 8, ["y"] = 17, ["z"] = 43, ["name"] = "wool:white"}, {["x"] = 8, ["meta"] = {["fields"] = {}, ["inventory"] = {}}, ["y"] = 18, ["param1"] = 25, ["z"] = 4, ["name"] = "wool:white"}, {["x"] = 8, ["meta"] = {["fields"] = {}, ["inventory"] = {}}, ["y"] = 18, ["param1"] = 25, ["z"] = 13, ["name"] = "wool:white"}, {["x"] = 8, ["meta"] = {["fields"] = {}, ["inventory"] = {}}, ["y"] = 18, ["param1"] = 25, ["z"] = 15, ["name"] = "wool:white"}, {["x"] = 8, ["y"] = 18, ["z"] = 17, ["name"] = "wool:white"}, {["x"] = 8, ["y"] = 18, ["z"] = 25, ["name"] = "wool:white"}, {["x"] = 8, ["y"] = 18, ["z"] = 27, ["name"] = "wool:white"}, {["x"] = 8, ["y"] = 18, ["z"] = 29, ["name"] = "wool:white"}, {["x"] = 8, ["y"] = 18, ["z"] = 31, ["name"] = "wool:white"}, {["x"] = 8, ["y"] = 18, ["z"] = 33, ["name"] = "wool:white"}, {["x"] = 8, ["y"] = 18, ["z"] = 35, ["name"] = "wool:white"}, {["x"] = 8, ["y"] = 18, ["z"] = 37, ["name"] = "wool:white"}, {["x"] = 8, ["y"] = 18, ["z"] = 39, ["name"] = "wool:white"}, {["x"] = 8, ["y"] = 18, ["z"] = 41, ["name"] = "wool:white"}, {["x"] = 8, ["y"] = 18, ["z"] = 43, ["name"] = "wool:white"}, {["x"] = 8, ["meta"] = {["fields"] = {}, ["inventory"] = {}}, ["y"] = 19, ["param1"] = 25, ["z"] = 11, ["name"] = "wool:white"}, {["x"] = 8, ["meta"] = {["fields"] = {}, ["inventory"] = {}}, ["y"] = 19, ["param1"] = 25, ["z"] = 13, ["name"] = "wool:white"}, {["x"] = 8, ["meta"] = {["fields"] = {}, ["inventory"] = {}}, ["y"] = 19, ["param1"] = 25, ["z"] = 15, ["name"] = "wool:white"}, {["x"] = 8, ["y"] = 19, ["z"] = 29, ["name"] = "wool:white"}, {["x"] = 8, ["y"] = 19, ["z"] = 31, ["name"] = "wool:white"}, {["x"] = 8, ["y"] = 19, ["z"] = 33, ["name"] = "wool:white"}, {["x"] = 8, ["y"] = 19, ["z"] = 35, ["name"] = "wool:white"}, {["x"] = 8, ["y"] = 19, ["z"] = 37, ["name"] = "wool:white"}, {["x"] = 8, ["y"] = 19, ["z"] = 39, ["name"] = "wool:white"}, {["x"] = 8, ["y"] = 19, ["z"] = 41, ["name"] = "wool:white"}, {["x"] = 8, ["y"] = 19, ["z"] = 43, ["name"] = "wool:white"}, {["x"] = 8, ["meta"] = {["fields"] = {}, ["inventory"] = {}}, ["y"] = 20, ["param1"] = 25, ["z"] = 6, ["name"] = "wool:white"}, {["x"] = 8, ["meta"] = {["fields"] = {}, ["inventory"] = {}}, ["y"] = 20, ["param1"] = 25, ["z"] = 11, ["name"] = "wool:white"}, {["x"] = 8, ["meta"] = {["fields"] = {}, ["inventory"] = {}}, ["y"] = 20, ["param1"] = 25, ["z"] = 13, ["name"] = "wool:white"}, {["x"] = 8, ["y"] = 20, ["z"] = 20, ["name"] = "wool:white"}, {["x"] = 8, ["y"] = 20, ["z"] = 21, ["name"] = "wool:white"}, {["x"] = 8, ["meta"] = {["fields"] = {}, ["inventory"] = {}}, ["y"] = 21, ["param1"] = 25, ["z"] = 7, ["name"] = "wool:white"}, {["x"] = 8, ["meta"] = {["fields"] = {}, ["inventory"] = {}}, ["y"] = 21, ["param1"] = 25, ["z"] = 11, ["name"] = "wool:white"}, {["x"] = 8, ["meta"] = {["fields"] = {}, ["inventory"] = {}}, ["y"] = 22, ["param1"] = 25, ["z"] = 8, ["name"] = "wool:white"}, {["x"] = 8, ["meta"] = {["fields"] = {}, ["inventory"] = {}}, ["y"] = 22, ["param1"] = 25, ["z"] = 9, ["name"] = "wool:white"}, {["x"] = 9, ["y"] = 9, ["z"] = 19, ["name"] = "wool:white"}, {["x"] = 9, ["y"] = 9, ["z"] = 21, ["name"] = "wool:white"}, {["x"] = 9, ["y"] = 10, ["z"] = 23, ["name"] = "wool:white"}, {["x"] = 9, ["y"] = 10, ["z"] = 25, ["name"] = "wool:white"}, {["x"] = 9, ["y"] = 11, ["z"] = 27, ["name"] = "wool:white"}, {["x"] = 9, ["y"] = 12, ["z"] = 29, ["name"] = "wool:white"}, {["x"] = 9, ["y"] = 12, ["z"] = 30, ["name"] = "wool:white"}, {["x"] = 9, ["y"] = 12, ["z"] = 31, ["name"] = "wool:white"}, {["x"] = 9, ["y"] = 13, ["z"] = 32, ["name"] = "wool:white"}, {["x"] = 9, ["y"] = 13, ["z"] = 33, ["name"] = "wool:white"}, {["x"] = 9, ["y"] = 13, ["z"] = 43, ["name"] = "wool:white"}, {["x"] = 9, ["y"] = 13, ["z"] = 44, ["name"] = "wool:white"}, {["x"] = 9, ["y"] = 13, ["z"] = 45, ["name"] = "wool:white"}, {["x"] = 9, ["meta"] = {["fields"] = {}, ["inventory"] = {}}, ["y"] = 16, ["param1"] = 25, ["z"] = 6, ["name"] = "wool:white"}, {["x"] = 9, ["meta"] = {["fields"] = {}, ["inventory"] = {}}, ["y"] = 17, ["param1"] = 25, ["z"] = 6, ["name"] = "wool:white"}, {["x"] = 9, ["meta"] = {["fields"] = {}, ["inventory"] = {}}, ["y"] = 17, ["param1"] = 25, ["z"] = 7, ["name"] = "wool:white"}, {["x"] = 9, ["meta"] = {["fields"] = {}, ["inventory"] = {}}, ["y"] = 17, ["param1"] = 25, ["z"] = 8, ["name"] = "wool:white"}, {["x"] = 9, ["y"] = 17, ["z"] = 19, ["name"] = "wool:white"}, {["x"] = 9, ["y"] = 17, ["z"] = 21, ["name"] = "wool:white"}, {["x"] = 9, ["y"] = 17, ["z"] = 23, ["name"] = "wool:white"}, {["x"] = 9, ["meta"] = {["fields"] = {}, ["inventory"] = {}}, ["y"] = 18, ["param1"] = 25, ["z"] = 6, ["name"] = "wool:white"}, {["x"] = 9, ["meta"] = {["fields"] = {}, ["inventory"] = {}}, ["y"] = 18, ["param1"] = 25, ["z"] = 7, ["name"] = "wool:white"}, {["x"] = 9, ["meta"] = {["fields"] = {}, ["inventory"] = {}}, ["y"] = 18, ["param1"] = 25, ["z"] = 8, ["name"] = "wool:white"}, {["x"] = 9, ["meta"] = {["fields"] = {}, ["inventory"] = {}}, ["y"] = 18, ["param1"] = 25, ["z"] = 9, ["name"] = "wool:white"}, {["x"] = 9, ["y"] = 18, ["z"] = 25, ["name"] = "wool:white"}, {["x"] = 9, ["y"] = 18, ["z"] = 27, ["name"] = "wool:white"}, {["x"] = 9, ["meta"] = {["fields"] = {}, ["inventory"] = {}}, ["y"] = 19, ["param1"] = 25, ["z"] = 5, ["name"] = "wool:white"}, {["x"] = 9, ["meta"] = {["fields"] = {}, ["inventory"] = {}}, ["y"] = 19, ["param1"] = 25, ["z"] = 6, ["name"] = "wool:white"}, {["x"] = 9, ["meta"] = {["fields"] = {}, ["inventory"] = {}}, ["y"] = 19, ["param1"] = 25, ["z"] = 7, ["name"] = "wool:white"}, {["x"] = 9, ["meta"] = {["fields"] = {}, ["inventory"] = {}}, ["y"] = 19, ["param1"] = 25, ["z"] = 9, ["name"] = "wool:white"}, {["x"] = 9, ["meta"] = {["fields"] = {}, ["inventory"] = {}}, ["y"] = 19, ["param1"] = 25, ["z"] = 10, ["name"] = "wool:white"}, {["x"] = 9, ["y"] = 19, ["z"] = 29, ["name"] = "wool:white"}, {["x"] = 9, ["y"] = 19, ["z"] = 31, ["name"] = "wool:white"}, {["x"] = 9, ["y"] = 19, ["z"] = 33, ["name"] = "wool:white"}, {["x"] = 9, ["y"] = 19, ["z"] = 35, ["name"] = "wool:white"}, {["x"] = 9, ["y"] = 19, ["z"] = 37, ["name"] = "wool:white"}, {["x"] = 9, ["y"] = 19, ["z"] = 39, ["name"] = "wool:white"}, {["x"] = 9, ["y"] = 19, ["z"] = 41, ["name"] = "wool:white"}, {["x"] = 9, ["y"] = 19, ["z"] = 43, ["name"] = "wool:white"}, {["x"] = 9, ["meta"] = {["fields"] = {}, ["inventory"] = {}}, ["y"] = 20, ["param1"] = 25, ["z"] = 6, ["name"] = "wool:white"}, {["x"] = 9, ["meta"] = {["fields"] = {}, ["inventory"] = {}}, ["y"] = 20, ["param1"] = 25, ["z"] = 7, ["name"] = "wool:white"}, {["x"] = 9, ["meta"] = {["fields"] = {}, ["inventory"] = {}}, ["y"] = 20, ["param1"] = 25, ["z"] = 8, ["name"] = "wool:white"}, {["x"] = 9, ["meta"] = {["fields"] = {}, ["inventory"] = {}}, ["y"] = 20, ["param1"] = 25, ["z"] = 10, ["name"] = "wool:white"}, {["x"] = 9, ["y"] = 20, ["z"] = 19, ["name"] = "wool:white"}, {["x"] = 9, ["y"] = 20, ["z"] = 20, ["name"] = "wool:white"}, {["x"] = 9, ["y"] = 20, ["z"] = 21, ["name"] = "wool:white"}, {["x"] = 9, ["y"] = 20, ["z"] = 22, ["name"] = "wool:white"}, {["x"] = 9, ["y"] = 20, ["z"] = 42, ["name"] = "wool:white"}, {["x"] = 9, ["meta"] = {["fields"] = {}, ["inventory"] = {}}, ["y"] = 21, ["param1"] = 25, ["z"] = 7, ["name"] = "wool:white"}, {["x"] = 9, ["meta"] = {["fields"] = {}, ["inventory"] = {}}, ["y"] = 21, ["param1"] = 25, ["z"] = 9, ["name"] = "wool:white"}, {["x"] = 9, ["meta"] = {["fields"] = {}, ["inventory"] = {}}, ["y"] = 21, ["param1"] = 25, ["z"] = 10, ["name"] = "wool:white"}, {["x"] = 9, ["meta"] = {["fields"] = {}, ["inventory"] = {}}, ["y"] = 22, ["param1"] = 25, ["z"] = 8, ["name"] = "wool:white"}, {["x"] = 9, ["meta"] = {["fields"] = {}, ["inventory"] = {}}, ["y"] = 22, ["param1"] = 25, ["z"] = 9, ["name"] = "wool:white"}, {["x"] = 9, ["meta"] = {["fields"] = {}, ["inventory"] = {}}, ["y"] = 22, ["param1"] = 25, ["z"] = 10, ["name"] = "wool:white"}, {["x"] = 10, ["y"] = 9, ["z"] = 19, ["name"] = "wool:white"}, {["x"] = 10, ["y"] = 9, ["z"] = 21, ["name"] = "wool:white"}, {["x"] = 10, ["y"] = 10, ["z"] = 23, ["name"] = "wool:white"}, {["x"] = 10, ["y"] = 10, ["z"] = 25, ["name"] = "wool:white"}, {["x"] = 10, ["y"] = 11, ["z"] = 27, ["name"] = "wool:white"}, {["x"] = 10, ["y"] = 13, ["z"] = 29, ["name"] = "wool:white"}, {["x"] = 10, ["y"] = 13, ["z"] = 31, ["name"] = "wool:white"}, {["x"] = 10, ["y"] = 13, ["z"] = 43, ["name"] = "wool:white"}, {["x"] = 10, ["y"] = 13, ["z"] = 44, ["name"] = "wool:white"}, {["x"] = 10, ["y"] = 13, ["z"] = 45, ["name"] = "wool:white"}, {["x"] = 10, ["y"] = 14, ["z"] = 31, ["name"] = "wool:white"}, {["x"] = 10, ["y"] = 14, ["z"] = 33, ["name"] = "wool:white"}, {["x"] = 10, ["y"] = 17, ["z"] = 19, ["name"] = "wool:white"}, {["x"] = 10, ["y"] = 17, ["z"] = 21, ["name"] = "wool:white"}, {["x"] = 10, ["y"] = 17, ["z"] = 23, ["name"] = "wool:white"}, {["x"] = 10, ["y"] = 17, ["z"] = 31, ["name"] = "wool:white"}, {["x"] = 10, ["y"] = 17, ["z"] = 33, ["name"] = "wool:white"}, {["x"] = 10, ["y"] = 18, ["z"] = 25, ["name"] = "wool:white"}, {["x"] = 10, ["y"] = 18, ["z"] = 27, ["name"] = "wool:white"}, {["x"] = 10, ["y"] = 18, ["z"] = 29, ["name"] = "wool:white"}, {["x"] = 10, ["y"] = 18, ["z"] = 31, ["name"] = "wool:white"}, {["x"] = 10, ["y"] = 18, ["z"] = 33, ["name"] = "wool:white"}, {["x"] = 10, ["y"] = 19, ["z"] = 18, ["name"] = "wool:white"}, {["x"] = 10, ["y"] = 19, ["z"] = 19, ["name"] = "wool:white"}, {["x"] = 10, ["y"] = 19, ["z"] = 20, ["name"] = "wool:white"}, {["x"] = 10, ["y"] = 19, ["z"] = 35, ["name"] = "wool:white"}, {["x"] = 10, ["y"] = 19, ["z"] = 37, ["name"] = "wool:white"}, {["x"] = 10, ["y"] = 19, ["z"] = 39, ["name"] = "wool:white"}, {["x"] = 10, ["y"] = 19, ["z"] = 41, ["name"] = "wool:white"}, {["x"] = 10, ["y"] = 19, ["z"] = 43, ["name"] = "wool:white"}, {["x"] = 10, ["y"] = 20, ["z"] = 21, ["name"] = "wool:white"}, {["x"] = 10, ["y"] = 20, ["z"] = 22, ["name"] = "wool:white"}, {["x"] = 10, ["y"] = 20, ["z"] = 42, ["name"] = "wool:white"}, {["x"] = 11, ["y"] = 0, ["z"] = 39, ["name"] = "wool:white"}, {["x"] = 11, ["y"] = 0, ["z"] = 40, ["name"] = "wool:white"}, {["x"] = 11, ["y"] = 1, ["z"] = 39, ["name"] = "wool:white"}, {["x"] = 11, ["y"] = 1, ["z"] = 40, ["name"] = "wool:white"}, {["x"] = 11, ["y"] = 1, ["z"] = 41, ["name"] = "wool:white"}, {["x"] = 11, ["y"] = 2, ["z"] = 41, ["name"] = "wool:white"}, {["x"] = 11, ["y"] = 2, ["z"] = 42, ["name"] = "wool:white"}, {["x"] = 11, ["y"] = 3, ["z"] = 42, ["name"] = "wool:white"}, {["x"] = 11, ["y"] = 3, ["z"] = 43, ["name"] = "wool:white"}, {["x"] = 11, ["y"] = 4, ["z"] = 42, ["name"] = "wool:white"}, {["x"] = 11, ["y"] = 4, ["z"] = 43, ["name"] = "wool:white"}, {["x"] = 11, ["y"] = 4, ["z"] = 44, ["name"] = "wool:white"}, {["x"] = 11, ["y"] = 5, ["z"] = 42, ["name"] = "wool:white"}, {["x"] = 11, ["y"] = 5, ["z"] = 43, ["name"] = "wool:white"}, {["x"] = 11, ["y"] = 5, ["z"] = 45, ["name"] = "wool:white"}, {["x"] = 11, ["y"] = 6, ["z"] = 41, ["name"] = "wool:white"}, {["x"] = 11, ["y"] = 6, ["z"] = 42, ["name"] = "wool:white"}, {["x"] = 11, ["y"] = 7, ["z"] = 41, ["name"] = "wool:white"}, {["x"] = 11, ["y"] = 7, ["z"] = 42, ["name"] = "wool:white"}, {["x"] = 11, ["y"] = 8, ["z"] = 41, ["name"] = "wool:white"}, {["x"] = 11, ["y"] = 8, ["z"] = 42, ["name"] = "wool:white"}, {["x"] = 11, ["y"] = 9, ["z"] = 21, ["name"] = "wool:white"}, {["x"] = 11, ["y"] = 9, ["z"] = 40, ["name"] = "wool:white"}, {["x"] = 11, ["y"] = 9, ["z"] = 41, ["name"] = "wool:white"}, {["x"] = 11, ["y"] = 10, ["z"] = 19, ["name"] = "wool:white"}, {["x"] = 11, ["y"] = 10, ["z"] = 23, ["name"] = "wool:white"}, {["x"] = 11, ["y"] = 10, ["z"] = 40, ["name"] = "wool:white"}, {["x"] = 11, ["y"] = 10, ["z"] = 41, ["name"] = "wool:white"}, {["x"] = 11, ["y"] = 11, ["z"] = 19, ["name"] = "wool:white"}, {["x"] = 11, ["y"] = 11, ["z"] = 25, ["name"] = "wool:white"}, {["x"] = 11, ["y"] = 11, ["z"] = 40, ["name"] = "wool:white"}, {["x"] = 11, ["y"] = 11, ["z"] = 41, ["name"] = "wool:white"}, {["x"] = 11, ["y"] = 12, ["z"] = 25, ["name"] = "wool:white"}, {["x"] = 11, ["y"] = 12, ["z"] = 27, ["name"] = "wool:white"}, {["x"] = 11, ["y"] = 12, ["z"] = 41, ["name"] = "wool:white"}, {["x"] = 11, ["y"] = 12, ["z"] = 42, ["name"] = "wool:white"}, {["x"] = 11, ["y"] = 13, ["z"] = 27, ["name"] = "wool:white"}, {["x"] = 11, ["y"] = 13, ["z"] = 41, ["name"] = "wool:white"}, {["x"] = 11, ["y"] = 13, ["z"] = 42, ["name"] = "wool:white"}, {["x"] = 11, ["y"] = 14, ["z"] = 29, ["name"] = "wool:white"}, {["x"] = 11, ["y"] = 14, ["z"] = 43, ["name"] = "wool:white"}, {["x"] = 11, ["y"] = 14, ["z"] = 44, ["name"] = "wool:white"}, {["x"] = 11, ["y"] = 15, ["z"] = 19, ["name"] = "wool:white"}, {["x"] = 11, ["y"] = 15, ["z"] = 31, ["name"] = "wool:white"}, {["x"] = 11, ["y"] = 15, ["z"] = 33, ["name"] = "wool:white"}, {["x"] = 11, ["y"] = 15, ["z"] = 42, ["name"] = "wool:white"}, {["x"] = 11, ["y"] = 15, ["z"] = 43, ["name"] = "wool:white"}, {["x"] = 11, ["y"] = 15, ["z"] = 44, ["name"] = "wool:white"}, {["x"] = 11, ["y"] = 16, ["z"] = 19, ["name"] = "wool:white"}, {["x"] = 11, ["y"] = 16, ["z"] = 31, ["name"] = "wool:white"}, {["x"] = 11, ["y"] = 16, ["z"] = 33, ["name"] = "wool:white"}, {["x"] = 11, ["y"] = 16, ["z"] = 42, ["name"] = "wool:white"}, {["x"] = 11, ["y"] = 17, ["z"] = 17, ["name"] = "wool:white"}, {["x"] = 11, ["y"] = 17, ["z"] = 21, ["name"] = "wool:white"}, {["x"] = 11, ["y"] = 17, ["z"] = 23, ["name"] = "wool:white"}, {["x"] = 11, ["y"] = 17, ["z"] = 25, ["name"] = "wool:white"}, {["x"] = 11, ["y"] = 17, ["z"] = 27, ["name"] = "wool:white"}, {["x"] = 11, ["y"] = 17, ["z"] = 29, ["name"] = "wool:white"}, {["x"] = 11, ["y"] = 17, ["z"] = 42, ["name"] = "wool:white"}, {["x"] = 11, ["y"] = 18, ["z"] = 18, ["name"] = "wool:white"}, {["x"] = 11, ["y"] = 18, ["z"] = 19, ["name"] = "wool:white"}, {["x"] = 11, ["y"] = 18, ["z"] = 42, ["name"] = "wool:white"}, {["x"] = 11, ["y"] = 19, ["z"] = 20, ["name"] = "wool:white"}, {["x"] = 11, ["y"] = 19, ["z"] = 21, ["name"] = "wool:white"}, {["x"] = 11, ["y"] = 19, ["z"] = 22, ["name"] = "wool:white"}, {["x"] = 11, ["y"] = 19, ["z"] = 39, ["name"] = "wool:white"}, {["x"] = 11, ["y"] = 19, ["z"] = 42, ["name"] = "wool:white"}, {["x"] = 11, ["y"] = 20, ["z"] = 41, ["name"] = "wool:white"}, {["x"] = 12, ["y"] = 0, ["z"] = 39, ["name"] = "wool:white"}, {["x"] = 12, ["y"] = 0, ["z"] = 40, ["name"] = "wool:white"}, {["x"] = 12, ["y"] = 1, ["z"] = 39, ["name"] = "wool:white"}, {["x"] = 12, ["y"] = 1, ["z"] = 40, ["name"] = "wool:white"}, {["x"] = 12, ["y"] = 1, ["z"] = 41, ["name"] = "wool:white"}, {["x"] = 12, ["y"] = 2, ["z"] = 41, ["name"] = "wool:white"}, {["x"] = 12, ["y"] = 2, ["z"] = 42, ["name"] = "wool:white"}, {["x"] = 12, ["y"] = 3, ["z"] = 42, ["name"] = "wool:white"}, {["x"] = 12, ["y"] = 3, ["z"] = 43, ["name"] = "wool:white"}, {["x"] = 12, ["y"] = 4, ["z"] = 42, ["name"] = "wool:white"}, {["x"] = 12, ["y"] = 4, ["z"] = 43, ["name"] = "wool:white"}, {["x"] = 12, ["y"] = 4, ["z"] = 44, ["name"] = "wool:white"}, {["x"] = 12, ["y"] = 5, ["z"] = 42, ["name"] = "wool:white"}, {["x"] = 12, ["y"] = 5, ["z"] = 43, ["name"] = "wool:white"}, {["x"] = 12, ["y"] = 5, ["z"] = 45, ["name"] = "wool:white"}, {["x"] = 12, ["y"] = 6, ["z"] = 41, ["name"] = "wool:white"}, {["x"] = 12, ["y"] = 6, ["z"] = 42, ["name"] = "wool:white"}, {["x"] = 12, ["y"] = 7, ["z"] = 41, ["name"] = "wool:white"}, {["x"] = 12, ["y"] = 7, ["z"] = 42, ["name"] = "wool:white"}, {["x"] = 12, ["y"] = 8, ["z"] = 41, ["name"] = "wool:white"}, {["x"] = 12, ["y"] = 8, ["z"] = 42, ["name"] = "wool:white"}, {["x"] = 12, ["y"] = 9, ["z"] = 18, ["name"] = "wool:white"}, {["x"] = 12, ["y"] = 9, ["z"] = 19, ["name"] = "wool:white"}, {["x"] = 12, ["y"] = 9, ["z"] = 40, ["name"] = "wool:white"}, {["x"] = 12, ["y"] = 9, ["z"] = 41, ["name"] = "wool:white"}, {["x"] = 12, ["y"] = 10, ["z"] = 17, ["name"] = "wool:white"}, {["x"] = 12, ["y"] = 10, ["z"] = 18, ["name"] = "wool:white"}, {["x"] = 12, ["y"] = 10, ["z"] = 21, ["name"] = "wool:white"}, {["x"] = 12, ["y"] = 10, ["z"] = 40, ["name"] = "wool:white"}, {["x"] = 12, ["y"] = 10, ["z"] = 41, ["name"] = "wool:white"}, {["x"] = 12, ["y"] = 11, ["z"] = 17, ["name"] = "wool:white"}, {["x"] = 12, ["y"] = 11, ["z"] = 21, ["name"] = "wool:white"}, {["x"] = 12, ["y"] = 11, ["z"] = 23, ["name"] = "wool:white"}, {["x"] = 12, ["y"] = 11, ["z"] = 40, ["name"] = "wool:white"}, {["x"] = 12, ["y"] = 11, ["z"] = 41, ["name"] = "wool:white"}, {["x"] = 12, ["y"] = 12, ["z"] = 16, ["name"] = "wool:white"}, {["x"] = 12, ["y"] = 12, ["z"] = 17, ["name"] = "wool:white"}, {["x"] = 12, ["y"] = 12, ["z"] = 19, ["name"] = "wool:white"}, {["x"] = 12, ["y"] = 12, ["z"] = 41, ["name"] = "wool:white"}, {["x"] = 12, ["y"] = 12, ["z"] = 42, ["name"] = "wool:white"}, {["x"] = 12, ["y"] = 13, ["z"] = 16, ["name"] = "wool:white"}, {["x"] = 12, ["y"] = 13, ["z"] = 17, ["name"] = "wool:white"}, {["x"] = 12, ["y"] = 13, ["z"] = 19, ["name"] = "wool:white"}, {["x"] = 12, ["y"] = 13, ["z"] = 25, ["name"] = "wool:white"}, {["x"] = 12, ["y"] = 13, ["z"] = 41, ["name"] = "wool:white"}, {["x"] = 12, ["y"] = 13, ["z"] = 42, ["name"] = "wool:white"}, {["x"] = 12, ["y"] = 14, ["z"] = 16, ["name"] = "wool:white"}, {["x"] = 12, ["y"] = 14, ["z"] = 19, ["name"] = "wool:white"}, {["x"] = 12, ["y"] = 14, ["z"] = 25, ["name"] = "wool:white"}, {["x"] = 12, ["y"] = 14, ["z"] = 27, ["name"] = "wool:white"}, {["x"] = 12, ["y"] = 15, ["z"] = 16, ["name"] = "wool:white"}, {["x"] = 12, ["y"] = 15, ["z"] = 21, ["name"] = "wool:white"}, {["x"] = 12, ["y"] = 15, ["z"] = 23, ["name"] = "wool:white"}, {["x"] = 12, ["y"] = 15, ["z"] = 25, ["name"] = "wool:white"}, {["x"] = 12, ["y"] = 15, ["z"] = 27, ["name"] = "wool:white"}, {["x"] = 12, ["y"] = 15, ["z"] = 29, ["name"] = "wool:white"}, {["x"] = 12, ["y"] = 16, ["z"] = 17, ["name"] = "wool:white"}, {["x"] = 12, ["y"] = 16, ["z"] = 21, ["name"] = "wool:white"}, {["x"] = 12, ["y"] = 16, ["z"] = 23, ["name"] = "wool:white"}, {["x"] = 12, ["y"] = 16, ["z"] = 25, ["name"] = "wool:white"}, {["x"] = 12, ["y"] = 16, ["z"] = 27, ["name"] = "wool:white"}, {["x"] = 12, ["y"] = 16, ["z"] = 29, ["name"] = "wool:white"}, {["x"] = 12, ["y"] = 17, ["z"] = 18, ["name"] = "wool:white"}, {["x"] = 12, ["y"] = 17, ["z"] = 19, ["name"] = "wool:white"}, {["x"] = 12, ["y"] = 17, ["z"] = 41, ["name"] = "wool:white"}, {["x"] = 12, ["y"] = 18, ["z"] = 20, ["name"] = "wool:white"}, {["x"] = 12, ["y"] = 18, ["z"] = 22, ["name"] = "wool:white"}, {["x"] = 12, ["y"] = 18, ["z"] = 41, ["name"] = "wool:white"}, {["x"] = 12, ["y"] = 19, ["z"] = 21, ["name"] = "wool:white"}, {["x"] = 12, ["y"] = 19, ["z"] = 41, ["name"] = "wool:white"}, {["x"] = 13, ["y"] = 0, ["z"] = 18, ["name"] = "wool:white"}, {["x"] = 13, ["y"] = 0, ["z"] = 19, ["name"] = "wool:white"}, {["x"] = 13, ["y"] = 1, ["z"] = 18, ["name"] = "wool:white"}, {["x"] = 13, ["y"] = 1, ["z"] = 19, ["name"] = "wool:white"}, {["x"] = 13, ["y"] = 2, ["z"] = 19, ["name"] = "wool:white"}, {["x"] = 13, ["y"] = 2, ["z"] = 20, ["name"] = "wool:white"}, {["x"] = 13, ["y"] = 3, ["z"] = 19, ["name"] = "wool:white"}, {["x"] = 13, ["y"] = 3, ["z"] = 20, ["name"] = "wool:white"}, {["x"] = 13, ["y"] = 4, ["z"] = 19, ["name"] = "wool:white"}, {["x"] = 13, ["y"] = 4, ["z"] = 20, ["name"] = "wool:white"}, {["x"] = 13, ["y"] = 5, ["z"] = 20, ["name"] = "wool:white"}, {["x"] = 13, ["y"] = 5, ["z"] = 21, ["name"] = "wool:white"}, {["x"] = 13, ["y"] = 6, ["z"] = 19, ["name"] = "wool:white"}, {["x"] = 13, ["y"] = 6, ["z"] = 20, ["name"] = "wool:white"}, {["x"] = 13, ["y"] = 7, ["z"] = 19, ["name"] = "wool:white"}, {["x"] = 13, ["y"] = 7, ["z"] = 20, ["name"] = "wool:white"}, {["x"] = 13, ["y"] = 8, ["z"] = 19, ["name"] = "wool:white"}, {["x"] = 13, ["y"] = 8, ["z"] = 20, ["name"] = "wool:white"}, {["x"] = 13, ["y"] = 9, ["z"] = 18, ["name"] = "wool:white"}, {["x"] = 13, ["y"] = 9, ["z"] = 19, ["name"] = "wool:white"}, {["x"] = 13, ["y"] = 9, ["z"] = 20, ["name"] = "wool:white"}, {["x"] = 13, ["y"] = 10, ["z"] = 17, ["name"] = "wool:white"}, {["x"] = 13, ["y"] = 10, ["z"] = 18, ["name"] = "wool:white"}, {["x"] = 13, ["y"] = 10, ["z"] = 20, ["name"] = "wool:white"}, {["x"] = 13, ["y"] = 11, ["z"] = 17, ["name"] = "wool:white"}, {["x"] = 13, ["y"] = 12, ["z"] = 16, ["name"] = "wool:white"}, {["x"] = 13, ["y"] = 12, ["z"] = 17, ["name"] = "wool:white"}, {["x"] = 13, ["y"] = 12, ["z"] = 21, ["name"] = "wool:white"}, {["x"] = 13, ["y"] = 12, ["z"] = 23, ["name"] = "wool:white"}, {["x"] = 13, ["y"] = 13, ["z"] = 16, ["name"] = "wool:white"}, {["x"] = 13, ["y"] = 13, ["z"] = 17, ["name"] = "wool:white"}, {["x"] = 13, ["y"] = 13, ["z"] = 21, ["name"] = "wool:white"}, {["x"] = 13, ["y"] = 13, ["z"] = 23, ["name"] = "wool:white"}, {["x"] = 13, ["y"] = 14, ["z"] = 17, ["name"] = "wool:white"}, {["x"] = 13, ["y"] = 14, ["z"] = 21, ["name"] = "wool:white"}, {["x"] = 13, ["y"] = 14, ["z"] = 23, ["name"] = "wool:white"}, {["x"] = 13, ["y"] = 15, ["z"] = 17, ["name"] = "wool:white"}, {["x"] = 13, ["y"] = 15, ["z"] = 18, ["name"] = "wool:white"}, {["x"] = 13, ["y"] = 16, ["z"] = 18, ["name"] = "wool:white"}, {["x"] = 13, ["y"] = 16, ["z"] = 19, ["name"] = "wool:white"}, {["x"] = 13, ["y"] = 17, ["z"] = 19, ["name"] = "wool:white"}, {["x"] = 13, ["y"] = 17, ["z"] = 20, ["name"] = "wool:white"}, {["x"] = 13, ["y"] = 17, ["z"] = 40, ["name"] = "wool:white"}, {["x"] = 13, ["y"] = 18, ["z"] = 21, ["name"] = "wool:white"}, {["x"] = 13, ["y"] = 18, ["z"] = 40, ["name"] = "wool:white"}, {["x"] = 13, ["y"] = 19, ["z"] = 40, ["name"] = "wool:white"}, {["x"] = 14, ["y"] = 0, ["z"] = 18, ["name"] = "wool:white"}, {["x"] = 14, ["y"] = 0, ["z"] = 19, ["name"] = "wool:white"}, {["x"] = 14, ["y"] = 1, ["z"] = 18, ["name"] = "wool:white"}, {["x"] = 14, ["y"] = 1, ["z"] = 19, ["name"] = "wool:white"}, {["x"] = 14, ["y"] = 2, ["z"] = 19, ["name"] = "wool:white"}, {["x"] = 14, ["y"] = 2, ["z"] = 20, ["name"] = "wool:white"}, {["x"] = 14, ["y"] = 3, ["z"] = 19, ["name"] = "wool:white"}, {["x"] = 14, ["y"] = 3, ["z"] = 20, ["name"] = "wool:white"}, {["x"] = 14, ["y"] = 4, ["z"] = 19, ["name"] = "wool:white"}, {["x"] = 14, ["y"] = 4, ["z"] = 20, ["name"] = "wool:white"}, {["x"] = 14, ["y"] = 5, ["z"] = 20, ["name"] = "wool:white"}, {["x"] = 14, ["y"] = 5, ["z"] = 21, ["name"] = "wool:white"}, {["x"] = 14, ["y"] = 6, ["z"] = 19, ["name"] = "wool:white"}, {["x"] = 14, ["y"] = 6, ["z"] = 20, ["name"] = "wool:white"}, {["x"] = 14, ["y"] = 7, ["z"] = 19, ["name"] = "wool:white"}, {["x"] = 14, ["y"] = 7, ["z"] = 20, ["name"] = "wool:white"}, {["x"] = 14, ["y"] = 8, ["z"] = 19, ["name"] = "wool:white"}, {["x"] = 14, ["y"] = 8, ["z"] = 20, ["name"] = "wool:white"}, {["x"] = 14, ["y"] = 9, ["z"] = 20, ["name"] = "wool:white"}, {["x"] = 14, ["y"] = 10, ["z"] = 20, ["name"] = "wool:white"}, {["x"] = 14, ["y"] = 14, ["z"] = 18, ["name"] = "wool:white"}, {["x"] = 14, ["y"] = 15, ["z"] = 19, ["name"] = "wool:white"}, {["x"] = 14, ["y"] = 16, ["z"] = 39, ["name"] = "wool:white"}, {["x"] = 14, ["y"] = 17, ["z"] = 39, ["name"] = "wool:white"}, {["x"] = 14, ["y"] = 18, ["z"] = 39, ["name"] = "wool:white"}, {["x"] = 14, ["y"] = 19, ["z"] = 39, ["name"] = "wool:white"}, {["x"] = 14, ["y"] = 20, ["z"] = 39, ["name"] = "wool:white"}}