5:return {{["x"] = 4, ["y"] = 0, ["param1"] = 140, ["z"] = 12, ["name"] = "wool:white"}, {["x"] = 4, ["y"] = 1, ["param1"] = 140, ["z"] = 11, ["name"] = "wool:white"}, {["x"] = 4, ["y"] = 1, ["param1"] = 140, ["z"] = 12, ["name"] = "wool:white"}, {["x"] = 4, ["y"] = 1, ["param1"] = 140, ["z"] = 13, ["name"] = "wool:white"}, {["x"] = 4, ["y"] = 2, ["param1"] = 140, ["z"] = 10, ["name"] = "wool:white"}, {["x"] = 4, ["y"] = 2, ["param1"] = 140, ["z"] = 11, ["name"] = "wool:white"}, {["x"] = 4, ["y"] = 2, ["param1"] = 140, ["z"] = 12, ["name"] = "wool:white"}, {["x"] = 4, ["y"] = 2, ["param1"] = 140, ["z"] = 13, ["name"] = "wool:white"}, {["x"] = 4, ["y"] = 2, ["param1"] = 140, ["z"] = 14, ["name"] = "wool:white"}, {["x"] = 4, ["y"] = 3, ["param1"] = 140, ["z"] = 10, ["name"] = "wool:white"}, {["x"] = 4, ["y"] = 3, ["param1"] = 140, ["z"] = 11, ["name"] = "wool:white"}, {["x"] = 4, ["y"] = 3, ["param1"] = 140, ["z"] = 12, ["name"] = "wool:white"}, {["x"] = 4, ["y"] = 3, ["param1"] = 140, ["z"] = 13, ["name"] = "wool:white"}, {["x"] = 4, ["y"] = 3, ["param1"] = 140, ["z"] = 14, ["name"] = "wool:white"}, {["x"] = 4, ["y"] = 4, ["param1"] = 140, ["z"] = 10, ["name"] = "wool:white"}, {["x"] = 4, ["y"] = 4, ["param1"] = 140, ["z"] = 11, ["name"] = "wool:white"}, {["x"] = 4, ["y"] = 4, ["param1"] = 140, ["z"] = 12, ["name"] = "wool:white"}, {["x"] = 4, ["y"] = 4, ["param1"] = 140, ["z"] = 13, ["name"] = "wool:white"}, {["x"] = 4, ["y"] = 5, ["param1"] = 140, ["z"] = 11, ["name"] = "wool:white"}, {["x"] = 4, ["y"] = 6, ["param1"] = 140, ["z"] = 11, ["name"] = "wool:white"}, {["x"] = 4, ["y"] = 6, ["param1"] = 140, ["z"] = 12, ["name"] = "wool:white"}, {["x"] = 4, ["y"] = 7, ["param1"] = 140, ["z"] = 12, ["name"] = "wool:white"}, {["x"] = 5, ["y"] = 0, ["param1"] = 140, ["z"] = 11, ["name"] = "wool:white"}, {["x"] = 5, ["y"] = 0, ["param1"] = 140, ["z"] = 12, ["name"] = "wool:white"}, {["x"] = 5, ["y"] = 0, ["param1"] = 140, ["z"] = 13, ["name"] = "wool:white"}, {["x"] = 5, ["y"] = 1, ["param1"] = 140, ["z"] = 14, ["name"] = "wool:white"}, {["x"] = 5, ["y"] = 2, ["param1"] = 140, ["z"] = 14, ["name"] = "wool:white"}, {["x"] = 5, ["y"] = 2, ["param1"] = 140, ["z"] = 15, ["name"] = "wool:white"}, {["x"] = 5, ["y"] = 3, ["param1"] = 140, ["z"] = 15, ["name"] = "wool:white"}, {["x"] = 5, ["y"] = 4, ["param1"] = 140, ["z"] = 11, ["name"] = "wool:white"}, {["x"] = 5, ["y"] = 4, ["param1"] = 140, ["z"] = 12, ["name"] = "wool:white"}, {["x"] = 5, ["y"] = 4, ["param1"] = 140, ["z"] = 13, ["name"] = "wool:white"}, {["x"] = 5, ["y"] = 4, ["param1"] = 140, ["z"] = 14, ["name"] = "wool:white"}, {["x"] = 5, ["y"] = 5, ["param1"] = 140, ["z"] = 8, ["name"] = "wool:white"}, {["x"] = 5, ["y"] = 5, ["param1"] = 140, ["z"] = 9, ["name"] = "wool:white"}, {["x"] = 5, ["y"] = 6, ["param1"] = 140, ["z"] = 8, ["name"] = "wool:white"}, {["x"] = 5, ["y"] = 6, ["param1"] = 140, ["z"] = 9, ["name"] = "wool:white"}, {["x"] = 5, ["y"] = 6, ["param1"] = 140, ["z"] = 11, ["name"] = "wool:white"}, {["x"] = 5, ["y"] = 6, ["param1"] = 140, ["z"] = 13, ["name"] = "wool:white"}, {["x"] = 5, ["y"] = 6, ["param1"] = 140, ["z"] = 14, ["name"] = "wool:white"}, {["x"] = 5, ["y"] = 7, ["param1"] = 140, ["z"] = 11, ["name"] = "wool:white"}, {["x"] = 5, ["y"] = 7, ["param1"] = 140, ["z"] = 13, ["name"] = "wool:white"}, {["x"] = 5, ["y"] = 7, ["param1"] = 140, ["z"] = 14, ["name"] = "wool:white"}, {["x"] = 6, ["y"] = 0, ["param1"] = 140, ["z"] = 11, ["name"] = "wool:white"}, {["x"] = 6, ["y"] = 0, ["param1"] = 140, ["z"] = 12, ["name"] = "wool:white"}, {["x"] = 6, ["y"] = 0, ["param1"] = 140, ["z"] = 13, ["name"] = "wool:white"}, {["x"] = 6, ["y"] = 0, ["param1"] = 140, ["z"] = 14, ["name"] = "wool:white"}, {["x"] = 6, ["y"] = 1, ["param1"] = 140, ["z"] = 10, ["name"] = "wool:white"}, {["x"] = 6, ["y"] = 1, ["param1"] = 140, ["z"] = 11, ["name"] = "wool:white"}, {["x"] = 6, ["y"] = 1, ["param1"] = 140, ["z"] = 15, ["name"] = "wool:white"}, {["x"] = 6, ["y"] = 2, ["param1"] = 140, ["z"] = 10, ["name"] = "wool:white"}, {["x"] = 6, ["y"] = 2, ["param1"] = 140, ["z"] = 11, ["name"] = "wool:white"}, {["x"] = 6, ["y"] = 2, ["param1"] = 140, ["z"] = 15, ["name"] = "wool:white"}, {["x"] = 6, ["y"] = 3, ["param1"] = 140, ["z"] = 11, ["name"] = "wool:white"}, {["x"] = 6, ["y"] = 3, ["param1"] = 140, ["z"] = 15, ["name"] = "wool:white"}, {["x"] = 6, ["y"] = 4, ["param1"] = 140, ["z"] = 11, ["name"] = "wool:white"}, {["x"] = 6, ["y"] = 4, ["param1"] = 140, ["z"] = 15, ["name"] = "wool:white"}, {["x"] = 6, ["y"] = 5, ["param1"] = 140, ["z"] = 8, ["name"] = "wool:white"}, {["x"] = 6, ["y"] = 5, ["param1"] = 140, ["z"] = 9, ["name"] = "wool:white"}, {["x"] = 6, ["y"] = 5, ["param1"] = 140, ["z"] = 10, ["name"] = "wool:white"}, {["x"] = 6, ["y"] = 5, ["param1"] = 140, ["z"] = 11, ["name"] = "wool:white"}, {["x"] = 6, ["y"] = 5, ["param1"] = 140, ["z"] = 12, ["name"] = "wool:white"}, {["x"] = 6, ["y"] = 5, ["param1"] = 140, ["z"] = 13, ["name"] = "wool:white"}, {["x"] = 6, ["y"] = 5, ["param1"] = 140, ["z"] = 14, ["name"] = "wool:white"}, {["x"] = 6, ["y"] = 6, ["param1"] = 140, ["z"] = 8, ["name"] = "wool:white"}, {["x"] = 6, ["y"] = 6, ["param1"] = 140, ["z"] = 10, ["name"] = "wool:white"}, {["x"] = 6, ["y"] = 6, ["param1"] = 140, ["z"] = 11, ["name"] = "wool:white"}, {["x"] = 6, ["y"] = 6, ["param1"] = 140, ["z"] = 13, ["name"] = "wool:white"}, {["x"] = 6, ["y"] = 6, ["param1"] = 140, ["z"] = 14, ["name"] = "wool:white"}, {["x"] = 6, ["y"] = 7, ["param1"] = 140, ["z"] = 8, ["name"] = "wool:white"}, {["x"] = 6, ["y"] = 7, ["param1"] = 140, ["z"] = 10, ["name"] = "wool:white"}, {["x"] = 6, ["y"] = 7, ["param1"] = 140, ["z"] = 11, ["name"] = "wool:white"}, {["x"] = 6, ["y"] = 7, ["param1"] = 140, ["z"] = 13, ["name"] = "wool:white"}, {["x"] = 6, ["y"] = 7, ["param1"] = 140, ["z"] = 14, ["name"] = "wool:white"}, {["x"] = 7, ["y"] = 0, ["param1"] = 140, ["z"] = 11, ["name"] = "wool:white"}, {["x"] = 7, ["y"] = 0, ["param1"] = 140, ["z"] = 12, ["name"] = "wool:white"}, {["x"] = 7, ["y"] = 0, ["param1"] = 140, ["z"] = 13, ["name"] = "wool:white"}, {["x"] = 7, ["y"] = 0, ["param1"] = 140, ["z"] = 14, ["name"] = "wool:white"}, {["x"] = 7, ["y"] = 1, ["param1"] = 140, ["z"] = 10, ["name"] = "wool:white"}, {["x"] = 7, ["y"] = 1, ["param1"] = 140, ["z"] = 15, ["name"] = "wool:white"}, {["x"] = 7, ["y"] = 2, ["param1"] = 140, ["z"] = 7, ["name"] = "wool:white"}, {["x"] = 7, ["y"] = 2, ["param1"] = 140, ["z"] = 9, ["name"] = "wool:white"}, {["x"] = 7, ["y"] = 2, ["param1"] = 140, ["z"] = 10, ["name"] = "wool:white"}, {["x"] = 7, ["y"] = 2, ["param1"] = 140, ["z"] = 15, ["name"] = "wool:white"}, {["x"] = 7, ["y"] = 3, ["param1"] = 140, ["z"] = 7, ["name"] = "wool:white"}, {["x"] = 7, ["y"] = 3, ["param1"] = 140, ["z"] = 9, ["name"] = "wool:white"}, {["x"] = 7, ["y"] = 3, ["param1"] = 140, ["z"] = 10, ["name"] = "wool:white"}, {["x"] = 7, ["y"] = 3, ["param1"] = 140, ["z"] = 15, ["name"] = "wool:white"}, {["x"] = 7, ["y"] = 4, ["param1"] = 140, ["z"] = 10, ["name"] = "wool:white"}, {["x"] = 7, ["y"] = 4, ["param1"] = 140, ["z"] = 15, ["name"] = "wool:white"}, {["x"] = 7, ["y"] = 5, ["param1"] = 140, ["z"] = 10, ["name"] = "wool:white"}, {["x"] = 7, ["y"] = 5, ["param1"] = 140, ["z"] = 15, ["name"] = "wool:white"}, {["x"] = 7, ["y"] = 6, ["param1"] = 140, ["z"] = 10, ["name"] = "wool:white"}, {["x"] = 7, ["y"] = 6, ["param1"] = 140, ["z"] = 15, ["name"] = "wool:white"}, {["x"] = 7, ["y"] = 7, ["param1"] = 140, ["z"] = 8, ["name"] = "wool:white"}, {["x"] = 7, ["y"] = 7, ["param1"] = 140, ["z"] = 10, ["name"] = "wool:white"}, {["x"] = 7, ["y"] = 7, ["param1"] = 140, ["z"] = 12, ["name"] = "wool:white"}, {["x"] = 7, ["y"] = 7, ["param1"] = 140, ["z"] = 13, ["name"] = "wool:white"}, {["x"] = 7, ["y"] = 7, ["param1"] = 140, ["z"] = 14, ["name"] = "wool:white"}, {["x"] = 8, ["y"] = 0, ["param1"] = 140, ["z"] = 11, ["name"] = "wool:white"}, {["x"] = 8, ["y"] = 0, ["param1"] = 140, ["z"] = 12, ["name"] = "wool:white"}, {["x"] = 8, ["y"] = 0, ["param1"] = 140, ["z"] = 13, ["name"] = "wool:white"}, {["x"] = 8, ["y"] = 0, ["param1"] = 140, ["z"] = 14, ["name"] = "wool:white"}, {["x"] = 8, ["y"] = 1, ["param1"] = 140, ["z"] = 10, ["name"] = "wool:white"}, {["x"] = 8, ["y"] = 1, ["param1"] = 140, ["z"] = 15, ["name"] = "wool:white"}, {["x"] = 8, ["y"] = 2, ["param1"] = 140, ["z"] = 7, ["name"] = "wool:white"}, {["x"] = 8, ["y"] = 2, ["param1"] = 140, ["z"] = 9, ["name"] = "wool:white"}, {["x"] = 8, ["y"] = 2, ["param1"] = 140, ["z"] = 10, ["name"] = "wool:white"}, {["x"] = 8, ["y"] = 2, ["param1"] = 140, ["z"] = 15, ["name"] = "wool:white"}, {["x"] = 8, ["y"] = 3, ["param1"] = 140, ["z"] = 7, ["name"] = "wool:white"}, {["x"] = 8, ["y"] = 3, ["param1"] = 140, ["z"] = 9, ["name"] = "wool:white"}, {["x"] = 8, ["y"] = 3, ["param1"] = 140, ["z"] = 10, ["name"] = "wool:white"}, {["x"] = 8, ["y"] = 3, ["param1"] = 140, ["z"] = 15, ["name"] = "wool:white"}, {["x"] = 8, ["y"] = 4, ["param1"] = 140, ["z"] = 10, ["name"] = "wool:white"}, {["x"] = 8, ["y"] = 4, ["param1"] = 140, ["z"] = 15, ["name"] = "wool:white"}, {["x"] = 8, ["y"] = 5, ["param1"] = 140, ["z"] = 10, ["name"] = "wool:white"}, {["x"] = 8, ["y"] = 5, ["param1"] = 140, ["z"] = 15, ["name"] = "wool:white"}, {["x"] = 8, ["y"] = 6, ["param1"] = 140, ["z"] = 10, ["name"] = "wool:white"}, {["x"] = 8, ["y"] = 6, ["param1"] = 140, ["z"] = 15, ["name"] = "wool:white"}, {["x"] = 8, ["y"] = 7, ["param1"] = 140, ["z"] = 8, ["name"] = "wool:white"}, {["x"] = 8, ["y"] = 7, ["param1"] = 140, ["z"] = 10, ["name"] = "wool:white"}, {["x"] = 8, ["y"] = 7, ["param1"] = 140, ["z"] = 12, ["name"] = "wool:white"}, {["x"] = 8, ["y"] = 7, ["param1"] = 140, ["z"] = 13, ["name"] = "wool:white"}, {["x"] = 8, ["y"] = 7, ["param1"] = 140, ["z"] = 14, ["name"] = "wool:white"}, {["x"] = 9, ["y"] = 0, ["param1"] = 140, ["z"] = 11, ["name"] = "wool:white"}, {["x"] = 9, ["y"] = 0, ["param1"] = 140, ["z"] = 12, ["name"] = "wool:white"}, {["x"] = 9, ["y"] = 0, ["param1"] = 140, ["z"] = 13, ["name"] = "wool:white"}, {["x"] = 9, ["y"] = 0, ["param1"] = 140, ["z"] = 14, ["name"] = "wool:white"}, {["x"] = 9, ["y"] = 1, ["param1"] = 140, ["z"] = 10, ["name"] = "wool:white"}, {["x"] = 9, ["y"] = 1, ["param1"] = 140, ["z"] = 11, ["name"] = "wool:white"}, {["x"] = 9, ["y"] = 1, ["param1"] = 140, ["z"] = 15, ["name"] = "wool:white"}, {["x"] = 9, ["y"] = 2, ["param1"] = 140, ["z"] = 10, ["name"] = "wool:white"}, {["x"] = 9, ["y"] = 2, ["param1"] = 140, ["z"] = 11, ["name"] = "wool:white"}, {["x"] = 9, ["y"] = 2, ["param1"] = 140, ["z"] = 15, ["name"] = "wool:white"}, {["x"] = 9, ["y"] = 3, ["param1"] = 140, ["z"] = 11, ["name"] = "wool:white"}, {["x"] = 9, ["y"] = 3, ["param1"] = 140, ["z"] = 15, ["name"] = "wool:white"}, {["x"] = 9, ["y"] = 4, ["param1"] = 140, ["z"] = 11, ["name"] = "wool:white"}, {["x"] = 9, ["y"] = 4, ["param1"] = 140, ["z"] = 15, ["name"] = "wool:white"}, {["x"] = 9, ["y"] = 5, ["param1"] = 140, ["z"] = 8, ["name"] = "wool:white"}, {["x"] = 9, ["y"] = 5, ["param1"] = 140, ["z"] = 9, ["name"] = "wool:white"}, {["x"] = 9, ["y"] = 5, ["param1"] = 140, ["z"] = 10, ["name"] = "wool:white"}, {["x"] = 9, ["y"] = 5, ["param1"] = 140, ["z"] = 11, ["name"] = "wool:white"}, {["x"] = 9, ["y"] = 5, ["param1"] = 140, ["z"] = 12, ["name"] = "wool:white"}, {["x"] = 9, ["y"] = 5, ["param1"] = 140, ["z"] = 13, ["name"] = "wool:white"}, {["x"] = 9, ["y"] = 5, ["param1"] = 140, ["z"] = 14, ["name"] = "wool:white"}, {["x"] = 9, ["y"] = 6, ["param1"] = 140, ["z"] = 8, ["name"] = "wool:white"}, {["x"] = 9, ["y"] = 6, ["param1"] = 140, ["z"] = 10, ["name"] = "wool:white"}, {["x"] = 9, ["y"] = 6, ["param1"] = 140, ["z"] = 11, ["name"] = "wool:white"}, {["x"] = 9, ["y"] = 6, ["param1"] = 140, ["z"] = 13, ["name"] = "wool:white"}, {["x"] = 9, ["y"] = 6, ["param1"] = 140, ["z"] = 14, ["name"] = "wool:white"}, {["x"] = 9, ["y"] = 7, ["param1"] = 140, ["z"] = 8, ["name"] = "wool:white"}, {["x"] = 9, ["y"] = 7, ["param1"] = 140, ["z"] = 10, ["name"] = "wool:white"}, {["x"] = 9, ["y"] = 7, ["param1"] = 140, ["z"] = 11, ["name"] = "wool:white"}, {["x"] = 9, ["y"] = 7, ["param1"] = 140, ["z"] = 13, ["name"] = "wool:white"}, {["x"] = 9, ["y"] = 7, ["param1"] = 140, ["z"] = 14, ["name"] = "wool:white"}, {["x"] = 10, ["y"] = 0, ["param1"] = 140, ["z"] = 11, ["name"] = "wool:white"}, {["x"] = 10, ["y"] = 0, ["param1"] = 140, ["z"] = 12, ["name"] = "wool:white"}, {["x"] = 10, ["y"] = 0, ["param1"] = 140, ["z"] = 13, ["name"] = "wool:white"}, {["x"] = 10, ["y"] = 1, ["param1"] = 140, ["z"] = 14, ["name"] = "wool:white"}, {["x"] = 10, ["y"] = 2, ["param1"] = 140, ["z"] = 15, ["name"] = "wool:white"}, {["x"] = 10, ["y"] = 3, ["param1"] = 140, ["z"] = 15, ["name"] = "wool:white"}, {["x"] = 10, ["y"] = 4, ["param1"] = 140, ["z"] = 11, ["name"] = "wool:white"}, {["x"] = 10, ["y"] = 4, ["param1"] = 140, ["z"] = 12, ["name"] = "wool:white"}, {["x"] = 10, ["y"] = 4, ["param1"] = 140, ["z"] = 13, ["name"] = "wool:white"}, {["x"] = 10, ["y"] = 4, ["param1"] = 140, ["z"] = 14, ["name"] = "wool:white"}, {["x"] = 10, ["y"] = 5, ["param1"] = 140, ["z"] = 8, ["name"] = "wool:white"}, {["x"] = 10, ["y"] = 5, ["param1"] = 140, ["z"] = 9, ["name"] = "wool:white"}, {["x"] = 10, ["y"] = 6, ["param1"] = 140, ["z"] = 8, ["name"] = "wool:white"}, {["x"] = 10, ["y"] = 6, ["param1"] = 140, ["z"] = 9, ["name"] = "wool:white"}, {["x"] = 10, ["y"] = 6, ["param1"] = 140, ["z"] = 11, ["name"] = "wool:white"}, {["x"] = 10, ["y"] = 6, ["param1"] = 140, ["z"] = 13, ["name"] = "wool:white"}, {["x"] = 10, ["y"] = 6, ["param1"] = 140, ["z"] = 14, ["name"] = "wool:white"}, {["x"] = 10, ["y"] = 7, ["param1"] = 140, ["z"] = 11, ["name"] = "wool:white"}, {["x"] = 10, ["y"] = 7, ["param1"] = 140, ["z"] = 13, ["name"] = "wool:white"}, {["x"] = 10, ["y"] = 7, ["param1"] = 140, ["z"] = 14, ["name"] = "wool:white"}, {["x"] = 11, ["y"] = 0, ["param1"] = 140, ["z"] = 12, ["name"] = "wool:white"}, {["x"] = 11, ["y"] = 1, ["param1"] = 140, ["z"] = 11, ["name"] = "wool:white"}, {["x"] = 11, ["y"] = 1, ["param1"] = 140, ["z"] = 12, ["name"] = "wool:white"}, {["x"] = 11, ["y"] = 1, ["param1"] = 140, ["z"] = 13, ["name"] = "wool:white"}, {["x"] = 11, ["y"] = 2, ["param1"] = 140, ["z"] = 10, ["name"] = "wool:white"}, {["x"] = 11, ["y"] = 2, ["param1"] = 140, ["z"] = 11, ["name"] = "wool:white"}, {["x"] = 11, ["y"] = 2, ["param1"] = 140, ["z"] = 12, ["name"] = "wool:white"}, {["x"] = 11, ["y"] = 2, ["param1"] = 140, ["z"] = 13, ["name"] = "wool:white"}, {["x"] = 11, ["y"] = 2, ["param1"] = 140, ["z"] = 14, ["name"] = "wool:white"}, {["x"] = 11, ["y"] = 3, ["param1"] = 140, ["z"] = 10, ["name"] = "wool:white"}, {["x"] = 11, ["y"] = 3, ["param1"] = 140, ["z"] = 11, ["name"] = "wool:white"}, {["x"] = 11, ["y"] = 3, ["param1"] = 140, ["z"] = 12, ["name"] = "wool:white"}, {["x"] = 11, ["y"] = 3, ["param1"] = 140, ["z"] = 13, ["name"] = "wool:white"}, {["x"] = 11, ["y"] = 3, ["param1"] = 140, ["z"] = 14, ["name"] = "wool:white"}, {["x"] = 11, ["y"] = 4, ["param1"] = 140, ["z"] = 10, ["name"] = "wool:white"}, {["x"] = 11, ["y"] = 4, ["param1"] = 140, ["z"] = 11, ["name"] = "wool:white"}, {["x"] = 11, ["y"] = 4, ["param1"] = 140, ["z"] = 12, ["name"] = "wool:white"}, {["x"] = 11, ["y"] = 4, ["param1"] = 140, ["z"] = 13, ["name"] = "wool:white"}, {["x"] = 11, ["y"] = 5, ["param1"] = 140, ["z"] = 11, ["name"] = "wool:white"}, {["x"] = 11, ["y"] = 6, ["param1"] = 140, ["z"] = 11, ["name"] = "wool:white"}, {["x"] = 11, ["y"] = 6, ["param1"] = 140, ["z"] = 12, ["name"] = "wool:white"}, {["x"] = 11, ["y"] = 7, ["param1"] = 140, ["z"] = 12, ["name"] = "wool:white"}}