5:return {{["x"] = 1, ["y"] = 7, ["z"] = 8, ["name"] = "wool:white"}, {["x"] = 1, ["y"] = 8, ["z"] = 7, ["name"] = "wool:white"}, {["x"] = 1, ["y"] = 8, ["z"] = 8, ["name"] = "wool:white"}, {["x"] = 1, ["y"] = 8, ["z"] = 9, ["name"] = "wool:white"}, {["x"] = 1, ["y"] = 9, ["z"] = 6, ["name"] = "wool:white"}, {["x"] = 1, ["y"] = 9, ["z"] = 7, ["name"] = "wool:white"}, {["x"] = 1, ["y"] = 9, ["z"] = 8, ["name"] = "wool:white"}, {["x"] = 1, ["y"] = 9, ["z"] = 9, ["name"] = "wool:white"}, {["x"] = 1, ["y"] = 10, ["z"] = 6, ["name"] = "wool:white"}, {["x"] = 1, ["y"] = 10, ["z"] = 7, ["name"] = "wool:white"}, {["x"] = 1, ["y"] = 10, ["z"] = 8, ["name"] = "wool:white"}, {["x"] = 1, ["y"] = 10, ["z"] = 9, ["name"] = "wool:white"}, {["x"] = 1, ["y"] = 11, ["z"] = 6, ["name"] = "wool:white"}, {["x"] = 1, ["y"] = 11, ["z"] = 7, ["name"] = "wool:white"}, {["x"] = 1, ["y"] = 11, ["z"] = 8, ["name"] = "wool:white"}, {["x"] = 1, ["y"] = 11, ["z"] = 9, ["name"] = "wool:white"}, {["x"] = 1, ["y"] = 12, ["z"] = 7, ["name"] = "wool:white"}, {["x"] = 1, ["y"] = 12, ["z"] = 8, ["name"] = "wool:white"}, {["x"] = 1, ["y"] = 13, ["z"] = 7, ["name"] = "wool:white"}, {["x"] = 1, ["y"] = 13, ["z"] = 8, ["name"] = "wool:white"}, {["x"] = 1, ["y"] = 14, ["z"] = 7, ["name"] = "wool:white"}, {["x"] = 1, ["y"] = 14, ["z"] = 8, ["name"] = "wool:white"}, {["x"] = 1, ["y"] = 15, ["z"] = 7, ["name"] = "wool:white"}, {["x"] = 1, ["y"] = 15, ["z"] = 8, ["name"] = "wool:white"}, {["x"] = 1, ["y"] = 16, ["z"] = 7, ["name"] = "wool:white"}, {["x"] = 1, ["y"] = 16, ["z"] = 8, ["name"] = "wool:white"}, {["x"] = 1, ["y"] = 17, ["z"] = 8, ["name"] = "wool:white"}, {["x"] = 1, ["y"] = 17, ["z"] = 9, ["name"] = "wool:white"}, {["x"] = 1, ["y"] = 18, ["z"] = 7, ["name"] = "wool:white"}, {["x"] = 1, ["y"] = 18, ["z"] = 8, ["name"] = "wool:white"}, {["x"] = 1, ["y"] = 19, ["z"] = 7, ["name"] = "wool:white"}, {["x"] = 1, ["y"] = 19, ["z"] = 8, ["name"] = "wool:white"}, {["x"] = 1, ["y"] = 20, ["z"] = 7, ["name"] = "wool:white"}, {["x"] = 1, ["y"] = 20, ["z"] = 8, ["name"] = "wool:white"}, {["x"] = 1, ["y"] = 21, ["z"] = 7, ["name"] = "wool:white"}, {["x"] = 1, ["y"] = 21, ["z"] = 8, ["name"] = "wool:white"}, {["x"] = 2, ["y"] = 22, ["z"] = 7, ["name"] = "wool:white"}, {["x"] = 2, ["y"] = 22, ["z"] = 8, ["name"] = "wool:white"}, {["x"] = 3, ["y"] = 7, ["z"] = 7, ["name"] = "wool:white"}, {["x"] = 3, ["y"] = 15, ["z"] = 8, ["name"] = "wool:white"}, {["x"] = 3, ["y"] = 22, ["z"] = 7, ["name"] = "wool:white"}, {["x"] = 3, ["y"] = 22, ["z"] = 8, ["name"] = "wool:white"}, {["x"] = 4, ["y"] = 0, ["z"] = 5, ["name"] = "wool:white"}, {["x"] = 4, ["y"] = 0, ["z"] = 6, ["name"] = "wool:white"}, {["x"] = 4, ["y"] = 0, ["z"] = 7, ["name"] = "wool:white"}, {["x"] = 4, ["y"] = 0, ["z"] = 8, ["name"] = "wool:white"}, {["x"] = 4, ["y"] = 1, ["z"] = 7, ["name"] = "wool:white"}, {["x"] = 4, ["y"] = 1, ["z"] = 8, ["name"] = "wool:white"}, {["x"] = 4, ["y"] = 2, ["z"] = 7, ["name"] = "wool:white"}, {["x"] = 4, ["y"] = 2, ["z"] = 8, ["name"] = "wool:white"}, {["x"] = 4, ["y"] = 3, ["z"] = 7, ["name"] = "wool:white"}, {["x"] = 4, ["y"] = 3, ["z"] = 8, ["name"] = "wool:white"}, {["x"] = 4, ["y"] = 4, ["z"] = 7, ["name"] = "wool:white"}, {["x"] = 4, ["y"] = 4, ["z"] = 8, ["name"] = "wool:white"}, {["x"] = 4, ["y"] = 5, ["z"] = 7, ["name"] = "wool:white"}, {["x"] = 4, ["y"] = 5, ["z"] = 8, ["name"] = "wool:white"}, {["x"] = 4, ["y"] = 6, ["z"] = 7, ["name"] = "wool:white"}, {["x"] = 4, ["y"] = 6, ["z"] = 8, ["name"] = "wool:white"}, {["x"] = 4, ["y"] = 7, ["z"] = 8, ["name"] = "wool:white"}, {["x"] = 4, ["y"] = 8, ["z"] = 7, ["name"] = "wool:white"}, {["x"] = 4, ["y"] = 8, ["z"] = 8, ["name"] = "wool:white"}, {["x"] = 4, ["y"] = 9, ["z"] = 7, ["name"] = "wool:white"}, {["x"] = 4, ["y"] = 9, ["z"] = 8, ["name"] = "wool:white"}, {["x"] = 4, ["y"] = 10, ["z"] = 7, ["name"] = "wool:white"}, {["x"] = 4, ["y"] = 10, ["z"] = 8, ["name"] = "wool:white"}, {["x"] = 4, ["y"] = 11, ["z"] = 7, ["name"] = "wool:white"}, {["x"] = 4, ["y"] = 11, ["z"] = 8, ["name"] = "wool:white"}, {["x"] = 4, ["y"] = 14, ["z"] = 8, ["name"] = "wool:white"}, {["x"] = 4, ["y"] = 15, ["z"] = 8, ["name"] = "wool:white"}, {["x"] = 4, ["y"] = 16, ["z"] = 8, ["name"] = "wool:white"}, {["x"] = 4, ["y"] = 19, ["z"] = 5, ["name"] = "wool:white"}, {["x"] = 4, ["y"] = 19, ["z"] = 6, ["name"] = "wool:white"}, {["x"] = 4, ["y"] = 19, ["z"] = 7, ["name"] = "wool:white"}, {["x"] = 4, ["y"] = 19, ["z"] = 8, ["name"] = "wool:white"}, {["x"] = 4, ["y"] = 19, ["z"] = 9, ["name"] = "wool:white"}, {["x"] = 4, ["y"] = 21, ["z"] = 5, ["name"] = "wool:white"}, {["x"] = 4, ["y"] = 21, ["z"] = 6, ["name"] = "wool:white"}, {["x"] = 4, ["y"] = 21, ["z"] = 7, ["name"] = "wool:white"}, {["x"] = 4, ["y"] = 22, ["z"] = 8, ["name"] = "wool:white"}, {["x"] = 4, ["y"] = 22, ["z"] = 9, ["name"] = "wool:white"}, {["x"] = 5, ["y"] = 0, ["z"] = 4, ["name"] = "wool:white"}, {["x"] = 5, ["y"] = 0, ["z"] = 5, ["name"] = "wool:white"}, {["x"] = 5, ["y"] = 0, ["z"] = 6, ["name"] = "wool:white"}, {["x"] = 5, ["y"] = 0, ["z"] = 7, ["name"] = "wool:white"}, {["x"] = 5, ["y"] = 0, ["z"] = 8, ["name"] = "wool:white"}, {["x"] = 5, ["y"] = 1, ["z"] = 7, ["name"] = "wool:white"}, {["x"] = 5, ["y"] = 1, ["z"] = 8, ["name"] = "wool:white"}, {["x"] = 5, ["y"] = 2, ["z"] = 7, ["name"] = "wool:white"}, {["x"] = 5, ["y"] = 2, ["z"] = 8, ["name"] = "wool:white"}, {["x"] = 5, ["y"] = 3, ["z"] = 7, ["name"] = "wool:white"}, {["x"] = 5, ["y"] = 3, ["z"] = 8, ["name"] = "wool:white"}, {["x"] = 5, ["y"] = 4, ["z"] = 7, ["name"] = "wool:white"}, {["x"] = 5, ["y"] = 4, ["z"] = 8, ["name"] = "wool:white"}, {["x"] = 5, ["y"] = 5, ["z"] = 7, ["name"] = "wool:white"}, {["x"] = 5, ["y"] = 5, ["z"] = 8, ["name"] = "wool:white"}, {["x"] = 5, ["y"] = 6, ["z"] = 7, ["name"] = "wool:white"}, {["x"] = 5, ["y"] = 6, ["z"] = 8, ["name"] = "wool:white"}, {["x"] = 5, ["y"] = 7, ["z"] = 8, ["name"] = "wool:white"}, {["x"] = 5, ["y"] = 8, ["z"] = 7, ["name"] = "wool:white"}, {["x"] = 5, ["y"] = 8, ["z"] = 8, ["name"] = "wool:white"}, {["x"] = 5, ["y"] = 9, ["z"] = 7, ["name"] = "wool:white"}, {["x"] = 5, ["y"] = 9, ["z"] = 8, ["name"] = "wool:white"}, {["x"] = 5, ["y"] = 10, ["z"] = 7, ["name"] = "wool:white"}, {["x"] = 5, ["y"] = 10, ["z"] = 8, ["name"] = "wool:white"}, {["x"] = 5, ["y"] = 12, ["z"] = 7, ["name"] = "wool:white"}, {["x"] = 5, ["y"] = 12, ["z"] = 8, ["name"] = "wool:white"}, {["x"] = 5, ["y"] = 13, ["z"] = 8, ["name"] = "wool:white"}, {["x"] = 5, ["y"] = 14, ["z"] = 8, ["name"] = "wool:white"}, {["x"] = 5, ["y"] = 15, ["z"] = 8, ["name"] = "wool:white"}, {["x"] = 5, ["y"] = 17, ["z"] = 8, ["name"] = "wool:white"}, {["x"] = 5, ["y"] = 17, ["z"] = 9, ["name"] = "wool:white"}, {["x"] = 5, ["y"] = 18, ["z"] = 6, ["name"] = "wool:white"}, {["x"] = 5, ["y"] = 18, ["z"] = 7, ["name"] = "wool:white"}, {["x"] = 5, ["y"] = 19, ["z"] = 5, ["name"] = "wool:white"}, {["x"] = 5, ["y"] = 19, ["z"] = 9, ["name"] = "wool:white"}, {["x"] = 5, ["y"] = 21, ["z"] = 5, ["name"] = "wool:white"}, {["x"] = 5, ["y"] = 22, ["z"] = 8, ["name"] = "wool:white"}, {["x"] = 5, ["y"] = 22, ["z"] = 9, ["name"] = "wool:white"}, {["x"] = 6, ["y"] = 7, ["z"] = 7, ["name"] = "wool:white"}, {["x"] = 6, ["y"] = 13, ["z"] = 8, ["name"] = "wool:white"}, {["x"] = 6, ["y"] = 14, ["z"] = 8, ["name"] = "wool:white"}, {["x"] = 6, ["y"] = 17, ["z"] = 9, ["name"] = "wool:white"}, {["x"] = 6, ["y"] = 18, ["z"] = 5, ["name"] = "wool:white"}, {["x"] = 6, ["y"] = 19, ["z"] = 5, ["name"] = "wool:white"}, {["x"] = 6, ["y"] = 19, ["z"] = 9, ["name"] = "wool:white"}, {["x"] = 6, ["y"] = 21, ["z"] = 5, ["name"] = "wool:white"}, {["x"] = 6, ["y"] = 22, ["z"] = 8, ["name"] = "wool:white"}, {["x"] = 6, ["y"] = 22, ["z"] = 9, ["name"] = "wool:white"}, {["x"] = 7, ["y"] = 12, ["z"] = 8, ["name"] = "wool:white"}, {["x"] = 7, ["y"] = 15, ["z"] = 8, ["name"] = "wool:white"}, {["x"] = 7, ["y"] = 15, ["z"] = 9, ["name"] = "wool:white"}, {["x"] = 7, ["y"] = 17, ["z"] = 5, ["name"] = "wool:white"}, {["x"] = 7, ["y"] = 17, ["z"] = 8, ["name"] = "wool:white"}, {["x"] = 7, ["y"] = 17, ["z"] = 9, ["name"] = "wool:white"}, {["x"] = 7, ["y"] = 18, ["z"] = 5, ["name"] = "wool:white"}, {["x"] = 7, ["y"] = 19, ["z"] = 5, ["name"] = "wool:white"}, {["x"] = 7, ["y"] = 19, ["z"] = 8, ["name"] = "wool:white"}, {["x"] = 7, ["y"] = 19, ["z"] = 9, ["name"] = "wool:white"}, {["x"] = 7, ["y"] = 20, ["z"] = 5, ["name"] = "wool:white"}, {["x"] = 7, ["y"] = 21, ["z"] = 5, ["name"] = "wool:white"}, {["x"] = 7, ["y"] = 21, ["z"] = 8, ["name"] = "wool:white"}, {["x"] = 7, ["y"] = 21, ["z"] = 9, ["name"] = "wool:white"}, {["x"] = 8, ["y"] = 12, ["z"] = 8, ["name"] = "wool:white"}, {["x"] = 8, ["y"] = 15, ["z"] = 8, ["name"] = "wool:white"}, {["x"] = 8, ["y"] = 15, ["z"] = 9, ["name"] = "wool:white"}, {["x"] = 8, ["y"] = 17, ["z"] = 5, ["name"] = "wool:white"}, {["x"] = 8, ["y"] = 17, ["z"] = 8, ["name"] = "wool:white"}, {["x"] = 8, ["y"] = 17, ["z"] = 9, ["name"] = "wool:white"}, {["x"] = 8, ["y"] = 18, ["z"] = 5, ["name"] = "wool:white"}, {["x"] = 8, ["y"] = 19, ["z"] = 5, ["name"] = "wool:white"}, {["x"] = 8, ["y"] = 19, ["z"] = 8, ["name"] = "wool:white"}, {["x"] = 8, ["y"] = 19, ["z"] = 9, ["name"] = "wool:white"}, {["x"] = 8, ["y"] = 20, ["z"] = 5, ["name"] = "wool:white"}, {["x"] = 8, ["y"] = 21, ["z"] = 5, ["name"] = "wool:white"}, {["x"] = 8, ["y"] = 21, ["z"] = 8, ["name"] = "wool:white"}, {["x"] = 8, ["y"] = 21, ["z"] = 9, ["name"] = "wool:white"}, {["x"] = 9, ["y"] = 7, ["z"] = 7, ["name"] = "wool:white"}, {["x"] = 9, ["y"] = 13, ["z"] = 8, ["name"] = "wool:white"}, {["x"] = 9, ["y"] = 14, ["z"] = 8, ["name"] = "wool:white"}, {["x"] = 9, ["y"] = 17, ["z"] = 9, ["name"] = "wool:white"}, {["x"] = 9, ["y"] = 18, ["z"] = 5, ["name"] = "wool:white"}, {["x"] = 9, ["y"] = 19, ["z"] = 5, ["name"] = "wool:white"}, {["x"] = 9, ["y"] = 19, ["z"] = 9, ["name"] = "wool:white"}, {["x"] = 9, ["y"] = 21, ["z"] = 5, ["name"] = "wool:white"}, {["x"] = 9, ["y"] = 22, ["z"] = 8, ["name"] = "wool:white"}, {["x"] = 9, ["y"] = 22, ["z"] = 9, ["name"] = "wool:white"}, {["x"] = 10, ["y"] = 0, ["z"] = 4, ["name"] = "wool:white"}, {["x"] = 10, ["y"] = 0, ["z"] = 5, ["name"] = "wool:white"}, {["x"] = 10, ["y"] = 0, ["z"] = 6, ["name"] = "wool:white"}, {["x"] = 10, ["y"] = 0, ["z"] = 7, ["name"] = "wool:white"}, {["x"] = 10, ["y"] = 0, ["z"] = 8, ["name"] = "wool:white"}, {["x"] = 10, ["y"] = 1, ["z"] = 7, ["name"] = "wool:white"}, {["x"] = 10, ["y"] = 1, ["z"] = 8, ["name"] = "wool:white"}, {["x"] = 10, ["y"] = 2, ["z"] = 7, ["name"] = "wool:white"}, {["x"] = 10, ["y"] = 2, ["z"] = 8, ["name"] = "wool:white"}, {["x"] = 10, ["y"] = 3, ["z"] = 7, ["name"] = "wool:white"}, {["x"] = 10, ["y"] = 3, ["z"] = 8, ["name"] = "wool:white"}, {["x"] = 10, ["y"] = 4, ["z"] = 7, ["name"] = "wool:white"}, {["x"] = 10, ["y"] = 4, ["z"] = 8, ["name"] = "wool:white"}, {["x"] = 10, ["y"] = 5, ["z"] = 7, ["name"] = "wool:white"}, {["x"] = 10, ["y"] = 5, ["z"] = 8, ["name"] = "wool:white"}, {["x"] = 10, ["y"] = 6, ["z"] = 7, ["name"] = "wool:white"}, {["x"] = 10, ["y"] = 6, ["z"] = 8, ["name"] = "wool:white"}, {["x"] = 10, ["y"] = 7, ["z"] = 8, ["name"] = "wool:white"}, {["x"] = 10, ["y"] = 8, ["z"] = 7, ["name"] = "wool:white"}, {["x"] = 10, ["y"] = 8, ["z"] = 8, ["name"] = "wool:white"}, {["x"] = 10, ["y"] = 9, ["z"] = 7, ["name"] = "wool:white"}, {["x"] = 10, ["y"] = 9, ["z"] = 8, ["name"] = "wool:white"}, {["x"] = 10, ["y"] = 10, ["z"] = 7, ["name"] = "wool:white"}, {["x"] = 10, ["y"] = 10, ["z"] = 8, ["name"] = "wool:white"}, {["x"] = 10, ["y"] = 12, ["z"] = 7, ["name"] = "wool:white"}, {["x"] = 10, ["y"] = 12, ["z"] = 8, ["name"] = "wool:white"}, {["x"] = 10, ["y"] = 13, ["z"] = 8, ["name"] = "wool:white"}, {["x"] = 10, ["y"] = 14, ["z"] = 8, ["name"] = "wool:white"}, {["x"] = 10, ["y"] = 15, ["z"] = 8, ["name"] = "wool:white"}, {["x"] = 10, ["y"] = 17, ["z"] = 8, ["name"] = "wool:white"}, {["x"] = 10, ["y"] = 17, ["z"] = 9, ["name"] = "wool:white"}, {["x"] = 10, ["y"] = 18, ["z"] = 5, ["name"] = "wool:white"}, {["x"] = 10, ["y"] = 18, ["z"] = 6, ["name"] = "wool:white"}, {["x"] = 10, ["y"] = 18, ["z"] = 7, ["name"] = "wool:white"}, {["x"] = 10, ["y"] = 19, ["z"] = 5, ["name"] = "wool:white"}, {["x"] = 10, ["y"] = 19, ["z"] = 9, ["name"] = "wool:white"}, {["x"] = 10, ["y"] = 21, ["z"] = 5, ["name"] = "wool:white"}, {["x"] = 10, ["y"] = 22, ["z"] = 8, ["name"] = "wool:white"}, {["x"] = 10, ["y"] = 22, ["z"] = 9, ["name"] = "wool:white"}, {["x"] = 11, ["y"] = 0, ["z"] = 5, ["name"] = "wool:white"}, {["x"] = 11, ["y"] = 0, ["z"] = 6, ["name"] = "wool:white"}, {["x"] = 11, ["y"] = 0, ["z"] = 7, ["name"] = "wool:white"}, {["x"] = 11, ["y"] = 0, ["z"] = 8, ["name"] = "wool:white"}, {["x"] = 11, ["y"] = 1, ["z"] = 7, ["name"] = "wool:white"}, {["x"] = 11, ["y"] = 1, ["z"] = 8, ["name"] = "wool:white"}, {["x"] = 11, ["y"] = 2, ["z"] = 7, ["name"] = "wool:white"}, {["x"] = 11, ["y"] = 2, ["z"] = 8, ["name"] = "wool:white"}, {["x"] = 11, ["y"] = 3, ["z"] = 7, ["name"] = "wool:white"}, {["x"] = 11, ["y"] = 3, ["z"] = 8, ["name"] = "wool:white"}, {["x"] = 11, ["y"] = 4, ["z"] = 7, ["name"] = "wool:white"}, {["x"] = 11, ["y"] = 4, ["z"] = 8, ["name"] = "wool:white"}, {["x"] = 11, ["y"] = 5, ["z"] = 7, ["name"] = "wool:white"}, {["x"] = 11, ["y"] = 5, ["z"] = 8, ["name"] = "wool:white"}, {["x"] = 11, ["y"] = 6, ["z"] = 7, ["name"] = "wool:white"}, {["x"] = 11, ["y"] = 6, ["z"] = 8, ["name"] = "wool:white"}, {["x"] = 11, ["y"] = 7, ["z"] = 8, ["name"] = "wool:white"}, {["x"] = 11, ["y"] = 8, ["z"] = 7, ["name"] = "wool:white"}, {["x"] = 11, ["y"] = 8, ["z"] = 8, ["name"] = "wool:white"}, {["x"] = 11, ["y"] = 9, ["z"] = 7, ["name"] = "wool:white"}, {["x"] = 11, ["y"] = 9, ["z"] = 8, ["name"] = "wool:white"}, {["x"] = 11, ["y"] = 10, ["z"] = 7, ["name"] = "wool:white"}, {["x"] = 11, ["y"] = 10, ["z"] = 8, ["name"] = "wool:white"}, {["x"] = 11, ["y"] = 11, ["z"] = 7, ["name"] = "wool:white"}, {["x"] = 11, ["y"] = 11, ["z"] = 8, ["name"] = "wool:white"}, {["x"] = 11, ["y"] = 14, ["z"] = 8, ["name"] = "wool:white"}, {["x"] = 11, ["y"] = 15, ["z"] = 8, ["name"] = "wool:white"}, {["x"] = 11, ["y"] = 16, ["z"] = 8, ["name"] = "wool:white"}, {["x"] = 11, ["y"] = 19, ["z"] = 5, ["name"] = "wool:white"}, {["x"] = 11, ["y"] = 19, ["z"] = 6, ["name"] = "wool:white"}, {["x"] = 11, ["y"] = 19, ["z"] = 7, ["name"] = "wool:white"}, {["x"] = 11, ["y"] = 19, ["z"] = 8, ["name"] = "wool:white"}, {["x"] = 11, ["y"] = 19, ["z"] = 9, ["name"] = "wool:white"}, {["x"] = 11, ["y"] = 21, ["z"] = 5, ["name"] = "wool:white"}, {["x"] = 11, ["y"] = 21, ["z"] = 6, ["name"] = "wool:white"}, {["x"] = 11, ["y"] = 21, ["z"] = 7, ["name"] = "wool:white"}, {["x"] = 11, ["y"] = 22, ["z"] = 8, ["name"] = "wool:white"}, {["x"] = 11, ["y"] = 22, ["z"] = 9, ["name"] = "wool:white"}, {["x"] = 12, ["y"] = 7, ["z"] = 7, ["name"] = "wool:white"}, {["x"] = 12, ["y"] = 15, ["z"] = 8, ["name"] = "wool:white"}, {["x"] = 12, ["y"] = 22, ["z"] = 7, ["name"] = "wool:white"}, {["x"] = 12, ["y"] = 22, ["z"] = 8, ["name"] = "wool:white"}, {["x"] = 13, ["y"] = 22, ["z"] = 7, ["name"] = "wool:white"}, {["x"] = 13, ["y"] = 22, ["z"] = 8, ["name"] = "wool:white"}, {["x"] = 14, ["y"] = 7, ["z"] = 8, ["name"] = "wool:white"}, {["x"] = 14, ["y"] = 8, ["z"] = 7, ["name"] = "wool:white"}, {["x"] = 14, ["y"] = 8, ["z"] = 8, ["name"] = "wool:white"}, {["x"] = 14, ["y"] = 8, ["z"] = 9, ["name"] = "wool:white"}, {["x"] = 14, ["y"] = 9, ["z"] = 6, ["name"] = "wool:white"}, {["x"] = 14, ["y"] = 9, ["z"] = 7, ["name"] = "wool:white"}, {["x"] = 14, ["y"] = 9, ["z"] = 8, ["name"] = "wool:white"}, {["x"] = 14, ["y"] = 9, ["z"] = 9, ["name"] = "wool:white"}, {["x"] = 14, ["y"] = 10, ["z"] = 6, ["name"] = "wool:white"}, {["x"] = 14, ["y"] = 10, ["z"] = 7, ["name"] = "wool:white"}, {["x"] = 14, ["y"] = 10, ["z"] = 8, ["name"] = "wool:white"}, {["x"] = 14, ["y"] = 10, ["z"] = 9, ["name"] = "wool:white"}, {["x"] = 14, ["y"] = 11, ["z"] = 6, ["name"] = "wool:white"}, {["x"] = 14, ["y"] = 11, ["z"] = 7, ["name"] = "wool:white"}, {["x"] = 14, ["y"] = 11, ["z"] = 8, ["name"] = "wool:white"}, {["x"] = 14, ["y"] = 11, ["z"] = 9, ["name"] = "wool:white"}, {["x"] = 14, ["y"] = 12, ["z"] = 7, ["name"] = "wool:white"}, {["x"] = 14, ["y"] = 12, ["z"] = 8, ["name"] = "wool:white"}, {["x"] = 14, ["y"] = 13, ["z"] = 7, ["name"] = "wool:white"}, {["x"] = 14, ["y"] = 13, ["z"] = 8, ["name"] = "wool:white"}, {["x"] = 14, ["y"] = 14, ["z"] = 7, ["name"] = "wool:white"}, {["x"] = 14, ["y"] = 14, ["z"] = 8, ["name"] = "wool:white"}, {["x"] = 14, ["y"] = 15, ["z"] = 7, ["name"] = "wool:white"}, {["x"] = 14, ["y"] = 15, ["z"] = 8, ["name"] = "wool:white"}, {["x"] = 14, ["y"] = 16, ["z"] = 7, ["name"] = "wool:white"}, {["x"] = 14, ["y"] = 16, ["z"] = 8, ["name"] = "wool:white"}, {["x"] = 14, ["y"] = 17, ["z"] = 8, ["name"] = "wool:white"}, {["x"] = 14, ["y"] = 17, ["z"] = 9, ["name"] = "wool:white"}, {["x"] = 14, ["y"] = 18, ["z"] = 7, ["name"] = "wool:white"}, {["x"] = 14, ["y"] = 18, ["z"] = 8, ["name"] = "wool:white"}, {["x"] = 14, ["y"] = 19, ["z"] = 7, ["name"] = "wool:white"}, {["x"] = 14, ["y"] = 19, ["z"] = 8, ["name"] = "wool:white"}, {["x"] = 14, ["y"] = 20, ["z"] = 7, ["name"] = "wool:white"}, {["x"] = 14, ["y"] = 20, ["z"] = 8, ["name"] = "wool:white"}, {["x"] = 14, ["y"] = 21, ["z"] = 7, ["name"] = "wool:white"}, {["x"] = 14, ["y"] = 21, ["z"] = 8, ["name"] = "wool:white"}}