5:return {{["x"] = 4, ["y"] = 0, ["z"] = 4, ["name"] = "wool:white"}, {["x"] = 4, ["y"] = 1, ["z"] = 4, ["name"] = "wool:white"}, {["x"] = 4, ["y"] = 2, ["z"] = 5, ["name"] = "wool:white"}, {["x"] = 4, ["y"] = 3, ["z"] = 5, ["name"] = "wool:white"}, {["x"] = 4, ["y"] = 4, ["z"] = 6, ["name"] = "wool:white"}, {["x"] = 4, ["y"] = 5, ["z"] = 6, ["name"] = "wool:white"}, {["x"] = 5, ["y"] = 0, ["z"] = 9, ["name"] = "wool:white"}, {["x"] = 5, ["y"] = 1, ["z"] = 9, ["name"] = "wool:white"}, {["x"] = 5, ["y"] = 2, ["z"] = 10, ["name"] = "wool:white"}, {["x"] = 5, ["y"] = 3, ["z"] = 10, ["name"] = "wool:white"}, {["x"] = 5, ["y"] = 4, ["z"] = 8, ["name"] = "wool:white"}, {["x"] = 5, ["y"] = 4, ["z"] = 11, ["name"] = "wool:white"}, {["x"] = 5, ["y"] = 6, ["z"] = 6, ["name"] = "wool:white"}, {["x"] = 6, ["y"] = 3, ["z"] = 8, ["name"] = "wool:white"}, {["x"] = 6, ["y"] = 4, ["z"] = 6, ["name"] = "wool:white"}, {["x"] = 6, ["y"] = 4, ["z"] = 11, ["name"] = "wool:white"}, {["x"] = 6, ["y"] = 5, ["z"] = 0, ["name"] = "wool:white"}, {["x"] = 6, ["y"] = 5, ["z"] = 1, ["name"] = "wool:white"}, {["x"] = 6, ["y"] = 5, ["z"] = 6, ["name"] = "wool:white"}, {["x"] = 6, ["y"] = 5, ["z"] = 8, ["name"] = "wool:white"}, {["x"] = 6, ["y"] = 5, ["z"] = 10, ["name"] = "wool:white"}, {["x"] = 6, ["y"] = 5, ["z"] = 11, ["name"] = "wool:white"}, {["x"] = 6, ["y"] = 6, ["z"] = 1, ["name"] = "wool:white"}, {["x"] = 6, ["y"] = 6, ["z"] = 2, ["name"] = "wool:white"}, {["x"] = 6, ["y"] = 6, ["z"] = 6, ["name"] = "wool:white"}, {["x"] = 6, ["y"] = 7, ["z"] = 3, ["name"] = "wool:white"}, {["x"] = 7, ["y"] = 2, ["z"] = 8, ["name"] = "wool:white"}, {["x"] = 7, ["y"] = 2, ["z"] = 15, ["name"] = "wool:white"}, {["x"] = 7, ["y"] = 3, ["z"] = 6, ["name"] = "wool:white"}, {["x"] = 7, ["y"] = 4, ["z"] = 0, ["name"] = "wool:white"}, {["x"] = 7, ["y"] = 4, ["z"] = 1, ["name"] = "wool:white"}, {["x"] = 7, ["y"] = 4, ["z"] = 14, ["name"] = "wool:white"}, {["x"] = 7, ["y"] = 5, ["z"] = 2, ["name"] = "wool:white"}, {["x"] = 7, ["y"] = 5, ["z"] = 12, ["name"] = "wool:white"}, {["x"] = 7, ["y"] = 6, ["z"] = 0, ["name"] = "wool:white"}, {["x"] = 7, ["y"] = 6, ["z"] = 3, ["name"] = "wool:white"}, {["x"] = 7, ["y"] = 6, ["z"] = 6, ["name"] = "wool:white"}, {["x"] = 7, ["y"] = 6, ["z"] = 8, ["name"] = "wool:white"}, {["x"] = 7, ["y"] = 6, ["z"] = 10, ["name"] = "wool:white"}, {["x"] = 7, ["y"] = 7, ["z"] = 1, ["name"] = "wool:white"}, {["x"] = 7, ["y"] = 7, ["z"] = 4, ["name"] = "wool:white"}, {["x"] = 7, ["y"] = 8, ["z"] = 2, ["name"] = "wool:white"}, {["x"] = 7, ["y"] = 8, ["z"] = 3, ["name"] = "wool:white"}, {["x"] = 8, ["y"] = 2, ["z"] = 8, ["name"] = "wool:white"}, {["x"] = 8, ["y"] = 2, ["z"] = 15, ["name"] = "wool:white"}, {["x"] = 8, ["y"] = 3, ["z"] = 6, ["name"] = "wool:white"}, {["x"] = 8, ["y"] = 4, ["z"] = 0, ["name"] = "wool:white"}, {["x"] = 8, ["y"] = 4, ["z"] = 1, ["name"] = "wool:white"}, {["x"] = 8, ["y"] = 4, ["z"] = 14, ["name"] = "wool:white"}, {["x"] = 8, ["y"] = 5, ["z"] = 2, ["name"] = "wool:white"}, {["x"] = 8, ["y"] = 5, ["z"] = 12, ["name"] = "wool:white"}, {["x"] = 8, ["y"] = 6, ["z"] = 0, ["name"] = "wool:white"}, {["x"] = 8, ["y"] = 6, ["z"] = 3, ["name"] = "wool:white"}, {["x"] = 8, ["y"] = 6, ["z"] = 6, ["name"] = "wool:white"}, {["x"] = 8, ["y"] = 6, ["z"] = 8, ["name"] = "wool:white"}, {["x"] = 8, ["y"] = 6, ["z"] = 10, ["name"] = "wool:white"}, {["x"] = 8, ["y"] = 7, ["z"] = 1, ["name"] = "wool:white"}, {["x"] = 8, ["y"] = 7, ["z"] = 4, ["name"] = "wool:white"}, {["x"] = 8, ["y"] = 8, ["z"] = 2, ["name"] = "wool:white"}, {["x"] = 8, ["y"] = 8, ["z"] = 3, ["name"] = "wool:white"}, {["x"] = 9, ["y"] = 3, ["z"] = 8, ["name"] = "wool:white"}, {["x"] = 9, ["y"] = 4, ["z"] = 6, ["name"] = "wool:white"}, {["x"] = 9, ["y"] = 4, ["z"] = 11, ["name"] = "wool:white"}, {["x"] = 9, ["y"] = 5, ["z"] = 0, ["name"] = "wool:white"}, {["x"] = 9, ["y"] = 5, ["z"] = 1, ["name"] = "wool:white"}, {["x"] = 9, ["y"] = 5, ["z"] = 6, ["name"] = "wool:white"}, {["x"] = 9, ["y"] = 5, ["z"] = 8, ["name"] = "wool:white"}, {["x"] = 9, ["y"] = 5, ["z"] = 10, ["name"] = "wool:white"}, {["x"] = 9, ["y"] = 5, ["z"] = 11, ["name"] = "wool:white"}, {["x"] = 9, ["y"] = 6, ["z"] = 1, ["name"] = "wool:white"}, {["x"] = 9, ["y"] = 6, ["z"] = 2, ["name"] = "wool:white"}, {["x"] = 9, ["y"] = 6, ["z"] = 6, ["name"] = "wool:white"}, {["x"] = 9, ["y"] = 7, ["z"] = 3, ["name"] = "wool:white"}, {["x"] = 10, ["y"] = 0, ["z"] = 9, ["name"] = "wool:white"}, {["x"] = 10, ["y"] = 1, ["z"] = 9, ["name"] = "wool:white"}, {["x"] = 10, ["y"] = 2, ["z"] = 10, ["name"] = "wool:white"}, {["x"] = 10, ["y"] = 3, ["z"] = 10, ["name"] = "wool:white"}, {["x"] = 10, ["y"] = 4, ["z"] = 8, ["name"] = "wool:white"}, {["x"] = 10, ["y"] = 4, ["z"] = 11, ["name"] = "wool:white"}, {["x"] = 10, ["y"] = 6, ["z"] = 6, ["name"] = "wool:white"}, {["x"] = 11, ["y"] = 0, ["z"] = 4, ["name"] = "wool:white"}, {["x"] = 11, ["y"] = 1, ["z"] = 4, ["name"] = "wool:white"}, {["x"] = 11, ["y"] = 2, ["z"] = 5, ["name"] = "wool:white"}, {["x"] = 11, ["y"] = 3, ["z"] = 5, ["name"] = "wool:white"}, {["x"] = 11, ["y"] = 4, ["z"] = 6, ["name"] = "wool:white"}, {["x"] = 11, ["y"] = 5, ["z"] = 6, ["name"] = "wool:white"}}