5:return {{["x"] = 1, ["y"] = 0, ["z"] = 1, ["name"] = "wool:white"}, {["x"] = 1, ["y"] = 1, ["z"] = 0, ["name"] = "wool:white"}, {["x"] = 1, ["y"] = 1, ["z"] = 1, ["name"] = "wool:white"}, {["x"] = 1, ["y"] = 1, ["z"] = 2, ["name"] = "wool:white"}, {["x"] = 1, ["y"] = 1, ["z"] = 3, ["name"] = "wool:white"}, {["x"] = 1, ["y"] = 2, ["z"] = 0, ["name"] = "wool:white"}, {["x"] = 1, ["y"] = 2, ["z"] = 2, ["name"] = "wool:white"}, {["x"] = 1, ["y"] = 2, ["z"] = 3, ["name"] = "wool:white"}, {["x"] = 1, ["y"] = 2, ["z"] = 4, ["name"] = "wool:white"}, {["x"] = 1, ["y"] = 2, ["z"] = 5, ["name"] = "wool:white"}, {["x"] = 1, ["y"] = 3, ["param1"] = 164, ["z"] = 4, ["name"] = "wool:white"}, {["x"] = 1, ["y"] = 3, ["param1"] = 164, ["z"] = 5, ["name"] = "wool:white"}, {["x"] = 2, ["y"] = 2, ["z"] = 6, ["name"] = "wool:white"}, {["x"] = 2, ["y"] = 3, ["param1"] = 164, ["z"] = 6, ["name"] = "wool:white"}, {["x"] = 3, ["y"] = 2, ["z"] = 6, ["name"] = "wool:white"}, {["x"] = 3, ["y"] = 3, ["param1"] = 164, ["z"] = 6, ["name"] = "wool:white"}, {["x"] = 4, ["y"] = 0, ["z"] = 3, ["name"] = "wool:white"}, {["x"] = 4, ["y"] = 1, ["z"] = 0, ["name"] = "wool:white"}, {["x"] = 4, ["y"] = 1, ["z"] = 3, ["name"] = "wool:white"}, {["x"] = 4, ["y"] = 1, ["z"] = 6, ["name"] = "wool:white"}, {["x"] = 4, ["y"] = 2, ["param1"] = 164, ["z"] = 3, ["name"] = "wool:white"}, {["x"] = 4, ["y"] = 2, ["param1"] = 164, ["z"] = 6, ["name"] = "wool:white"}, {["x"] = 4, ["y"] = 3, ["param1"] = 164, ["z"] = 3, ["name"] = "wool:white"}, {["x"] = 4, ["y"] = 3, ["z"] = 5, ["name"] = "wool:white"}, {["x"] = 4, ["y"] = 4, ["z"] = 3, ["name"] = "wool:white"}, {["x"] = 4, ["y"] = 4, ["param1"] = 164, ["z"] = 5, ["name"] = "wool:white"}, {["x"] = 4, ["y"] = 5, ["param1"] = 164, ["z"] = 5, ["name"] = "wool:white"}, {["x"] = 5, ["y"] = 0, ["z"] = 1, ["name"] = "wool:white"}, {["x"] = 5, ["y"] = 0, ["z"] = 3, ["name"] = "wool:white"}, {["x"] = 5, ["y"] = 1, ["z"] = 1, ["name"] = "wool:white"}, {["x"] = 5, ["y"] = 1, ["z"] = 6, ["name"] = "wool:white"}, {["x"] = 5, ["y"] = 2, ["z"] = 2, ["name"] = "wool:white"}, {["x"] = 5, ["y"] = 2, ["param1"] = 164, ["z"] = 6, ["name"] = "wool:white"}, {["x"] = 5, ["y"] = 3, ["z"] = 2, ["name"] = "wool:white"}, {["x"] = 5, ["y"] = 4, ["z"] = 3, ["name"] = "wool:white"}, {["x"] = 5, ["y"] = 5, ["z"] = 5, ["name"] = "wool:white"}, {["x"] = 6, ["y"] = 0, ["z"] = 1, ["name"] = "wool:white"}, {["x"] = 6, ["y"] = 0, ["z"] = 3, ["name"] = "wool:white"}, {["x"] = 6, ["y"] = 1, ["z"] = 6, ["name"] = "wool:white"}, {["x"] = 6, ["y"] = 2, ["param1"] = 164, ["z"] = 6, ["name"] = "wool:white"}, {["x"] = 6, ["y"] = 4, ["z"] = 2, ["name"] = "wool:white"}, {["x"] = 6, ["y"] = 4, ["z"] = 3, ["name"] = "wool:white"}, {["x"] = 6, ["y"] = 5, ["z"] = 5, ["name"] = "wool:white"}, {["x"] = 7, ["y"] = 0, ["z"] = 1, ["name"] = "wool:white"}, {["x"] = 7, ["y"] = 0, ["z"] = 3, ["name"] = "wool:white"}, {["x"] = 7, ["y"] = 1, ["z"] = 1, ["name"] = "wool:white"}, {["x"] = 7, ["y"] = 1, ["z"] = 3, ["name"] = "wool:white"}, {["x"] = 7, ["y"] = 1, ["z"] = 5, ["name"] = "wool:white"}, {["x"] = 7, ["y"] = 2, ["param1"] = 164, ["z"] = 5, ["name"] = "wool:white"}, {["x"] = 7, ["y"] = 4, ["z"] = 1, ["name"] = "wool:white"}, {["x"] = 7, ["y"] = 4, ["z"] = 2, ["name"] = "wool:white"}, {["x"] = 7, ["y"] = 4, ["z"] = 3, ["name"] = "wool:white"}, {["x"] = 7, ["y"] = 4, ["z"] = 4, ["name"] = "wool:white"}, {["x"] = 7, ["y"] = 5, ["z"] = 5, ["name"] = "wool:white"}, {["x"] = 8, ["y"] = 0, ["z"] = 1, ["name"] = "wool:white"}, {["x"] = 8, ["y"] = 0, ["z"] = 3, ["name"] = "wool:white"}, {["x"] = 8, ["y"] = 1, ["z"] = 1, ["name"] = "wool:white"}, {["x"] = 8, ["y"] = 1, ["z"] = 3, ["name"] = "wool:white"}, {["x"] = 8, ["y"] = 1, ["z"] = 5, ["name"] = "wool:white"}, {["x"] = 8, ["y"] = 2, ["param1"] = 164, ["z"] = 5, ["name"] = "wool:white"}, {["x"] = 8, ["y"] = 4, ["z"] = 1, ["name"] = "wool:white"}, {["x"] = 8, ["y"] = 4, ["z"] = 2, ["name"] = "wool:white"}, {["x"] = 8, ["y"] = 4, ["z"] = 3, ["name"] = "wool:white"}, {["x"] = 8, ["y"] = 4, ["z"] = 4, ["name"] = "wool:white"}, {["x"] = 8, ["y"] = 5, ["z"] = 5, ["name"] = "wool:white"}, {["x"] = 9, ["y"] = 0, ["z"] = 1, ["name"] = "wool:white"}, {["x"] = 9, ["y"] = 0, ["z"] = 3, ["name"] = "wool:white"}, {["x"] = 9, ["y"] = 1, ["z"] = 6, ["name"] = "wool:white"}, {["x"] = 9, ["y"] = 2, ["param1"] = 164, ["z"] = 6, ["name"] = "wool:white"}, {["x"] = 9, ["y"] = 4, ["z"] = 2, ["name"] = "wool:white"}, {["x"] = 9, ["y"] = 4, ["z"] = 3, ["name"] = "wool:white"}, {["x"] = 9, ["y"] = 5, ["z"] = 5, ["name"] = "wool:white"}, {["x"] = 10, ["y"] = 0, ["z"] = 1, ["name"] = "wool:white"}, {["x"] = 10, ["y"] = 0, ["z"] = 3, ["name"] = "wool:white"}, {["x"] = 10, ["y"] = 1, ["z"] = 1, ["name"] = "wool:white"}, {["x"] = 10, ["y"] = 1, ["z"] = 6, ["name"] = "wool:white"}, {["x"] = 10, ["y"] = 2, ["z"] = 2, ["name"] = "wool:white"}, {["x"] = 10, ["y"] = 2, ["param1"] = 164, ["z"] = 6, ["name"] = "wool:white"}, {["x"] = 10, ["y"] = 3, ["z"] = 2, ["name"] = "wool:white"}, {["x"] = 10, ["y"] = 4, ["z"] = 3, ["name"] = "wool:white"}, {["x"] = 10, ["y"] = 5, ["z"] = 5, ["name"] = "wool:white"}, {["x"] = 11, ["y"] = 0, ["z"] = 3, ["name"] = "wool:white"}, {["x"] = 11, ["y"] = 1, ["z"] = 0, ["name"] = "wool:white"}, {["x"] = 11, ["y"] = 1, ["z"] = 3, ["name"] = "wool:white"}, {["x"] = 11, ["y"] = 1, ["z"] = 6, ["name"] = "wool:white"}, {["x"] = 11, ["y"] = 2, ["param1"] = 164, ["z"] = 3, ["name"] = "wool:white"}, {["x"] = 11, ["y"] = 2, ["param1"] = 164, ["z"] = 6, ["name"] = "wool:white"}, {["x"] = 11, ["y"] = 3, ["param1"] = 164, ["z"] = 3, ["name"] = "wool:white"}, {["x"] = 11, ["y"] = 3, ["z"] = 5, ["name"] = "wool:white"}, {["x"] = 11, ["y"] = 4, ["param1"] = 164, ["z"] = 3, ["name"] = "wool:white"}, {["x"] = 11, ["y"] = 4, ["param1"] = 164, ["z"] = 5, ["name"] = "wool:white"}, {["x"] = 11, ["y"] = 5, ["param1"] = 164, ["z"] = 5, ["name"] = "wool:white"}, {["x"] = 12, ["y"] = 2, ["z"] = 6, ["name"] = "wool:white"}, {["x"] = 12, ["y"] = 3, ["param1"] = 164, ["z"] = 6, ["name"] = "wool:white"}, {["x"] = 13, ["y"] = 2, ["z"] = 6, ["name"] = "wool:white"}, {["x"] = 13, ["y"] = 3, ["param1"] = 164, ["z"] = 6, ["name"] = "wool:white"}, {["x"] = 14, ["y"] = 0, ["z"] = 1, ["name"] = "wool:white"}, {["x"] = 14, ["y"] = 1, ["z"] = 0, ["name"] = "wool:white"}, {["x"] = 14, ["y"] = 1, ["z"] = 1, ["name"] = "wool:white"}, {["x"] = 14, ["y"] = 1, ["z"] = 2, ["name"] = "wool:white"}, {["x"] = 14, ["y"] = 1, ["z"] = 3, ["name"] = "wool:white"}, {["x"] = 14, ["y"] = 2, ["z"] = 0, ["name"] = "wool:white"}, {["x"] = 14, ["y"] = 2, ["z"] = 2, ["name"] = "wool:white"}, {["x"] = 14, ["y"] = 2, ["z"] = 3, ["name"] = "wool:white"}, {["x"] = 14, ["y"] = 2, ["z"] = 4, ["name"] = "wool:white"}, {["x"] = 14, ["y"] = 2, ["z"] = 5, ["name"] = "wool:white"}, {["x"] = 14, ["y"] = 3, ["param1"] = 164, ["z"] = 4, ["name"] = "wool:white"}, {["x"] = 14, ["y"] = 3, ["param1"] = 164, ["z"] = 5, ["name"] = "wool:white"}}