5:return {{["x"] = 4, ["meta"] = {["fields"] = {}, ["inventory"] = {}}, ["y"] = 8, ["z"] = 4, ["name"] = "wool:white"}, {["x"] = 4, ["meta"] = {["fields"] = {}, ["inventory"] = {}}, ["y"] = 8, ["z"] = 5, ["name"] = "wool:white"}, {["x"] = 4, ["meta"] = {["fields"] = {}, ["inventory"] = {}}, ["y"] = 8, ["z"] = 6, ["name"] = "wool:white"}, {["x"] = 4, ["meta"] = {["fields"] = {}, ["inventory"] = {}}, ["y"] = 8, ["z"] = 7, ["name"] = "wool:white"}, {["x"] = 4, ["meta"] = {["fields"] = {}, ["inventory"] = {}}, ["y"] = 8, ["z"] = 9, ["name"] = "wool:white"}, {["x"] = 4, ["meta"] = {["fields"] = {}, ["inventory"] = {}}, ["y"] = 8, ["z"] = 10, ["name"] = "wool:white"}, {["x"] = 4, ["meta"] = {["fields"] = {}, ["inventory"] = {}}, ["y"] = 8, ["z"] = 11, ["name"] = "wool:white"}, {["x"] = 4, ["meta"] = {["fields"] = {}, ["inventory"] = {}}, ["y"] = 9, ["z"] = 4, ["name"] = "wool:white"}, {["x"] = 4, ["meta"] = {["fields"] = {}, ["inventory"] = {}}, ["y"] = 9, ["z"] = 5, ["name"] = "wool:white"}, {["x"] = 4, ["meta"] = {["fields"] = {}, ["inventory"] = {}}, ["y"] = 9, ["z"] = 6, ["name"] = "wool:white"}, {["x"] = 4, ["meta"] = {["fields"] = {}, ["inventory"] = {}}, ["y"] = 9, ["z"] = 7, ["name"] = "wool:white"}, {["x"] = 4, ["meta"] = {["fields"] = {}, ["inventory"] = {}}, ["y"] = 9, ["z"] = 9, ["name"] = "wool:white"}, {["x"] = 4, ["meta"] = {["fields"] = {}, ["inventory"] = {}}, ["y"] = 9, ["z"] = 10, ["name"] = "wool:white"}, {["x"] = 4, ["meta"] = {["fields"] = {}, ["inventory"] = {}}, ["y"] = 9, ["z"] = 11, ["name"] = "wool:white"}, {["x"] = 4, ["meta"] = {["fields"] = {}, ["inventory"] = {}}, ["y"] = 10, ["z"] = 4, ["name"] = "wool:white"}, {["x"] = 4, ["meta"] = {["fields"] = {}, ["inventory"] = {}}, ["y"] = 10, ["z"] = 5, ["name"] = "wool:white"}, {["x"] = 4, ["meta"] = {["fields"] = {}, ["inventory"] = {}}, ["y"] = 10, ["z"] = 6, ["name"] = "wool:white"}, {["x"] = 4, ["meta"] = {["fields"] = {}, ["inventory"] = {}}, ["y"] = 10, ["z"] = 7, ["name"] = "wool:white"}, {["x"] = 4, ["meta"] = {["fields"] = {}, ["inventory"] = {}}, ["y"] = 10, ["z"] = 8, ["name"] = "wool:white"}, {["x"] = 4, ["meta"] = {["fields"] = {}, ["inventory"] = {}}, ["y"] = 10, ["z"] = 9, ["name"] = "wool:white"}, {["x"] = 4, ["meta"] = {["fields"] = {}, ["inventory"] = {}}, ["y"] = 10, ["z"] = 10, ["name"] = "wool:white"}, {["x"] = 4, ["meta"] = {["fields"] = {}, ["inventory"] = {}}, ["y"] = 10, ["z"] = 11, ["name"] = "wool:white"}, {["x"] = 4, ["meta"] = {["fields"] = {}, ["inventory"] = {}}, ["y"] = 11, ["z"] = 4, ["name"] = "wool:white"}, {["x"] = 4, ["meta"] = {["fields"] = {}, ["inventory"] = {}}, ["y"] = 11, ["z"] = 5, ["name"] = "wool:white"}, {["x"] = 4, ["meta"] = {["fields"] = {}, ["inventory"] = {}}, ["y"] = 11, ["z"] = 6, ["name"] = "wool:white"}, {["x"] = 4, ["meta"] = {["fields"] = {}, ["inventory"] = {}}, ["y"] = 11, ["z"] = 7, ["name"] = "wool:white"}, {["x"] = 4, ["meta"] = {["fields"] = {}, ["inventory"] = {}}, ["y"] = 11, ["z"] = 8, ["name"] = "wool:white"}, {["x"] = 4, ["meta"] = {["fields"] = {}, ["inventory"] = {}}, ["y"] = 11, ["z"] = 9, ["name"] = "wool:white"}, {["x"] = 4, ["meta"] = {["fields"] = {}, ["inventory"] = {}}, ["y"] = 11, ["z"] = 10, ["name"] = "wool:white"}, {["x"] = 4, ["meta"] = {["fields"] = {}, ["inventory"] = {}}, ["y"] = 11, ["z"] = 11, ["name"] = "wool:white"}, {["x"] = 4, ["meta"] = {["fields"] = {}, ["inventory"] = {}}, ["y"] = 12, ["z"] = 4, ["name"] = "wool:white"}, {["x"] = 4, ["meta"] = {["fields"] = {}, ["inventory"] = {}}, ["y"] = 12, ["z"] = 5, ["name"] = "wool:white"}, {["x"] = 4, ["meta"] = {["fields"] = {}, ["inventory"] = {}}, ["y"] = 12, ["z"] = 6, ["name"] = "wool:white"}, {["x"] = 4, ["meta"] = {["fields"] = {}, ["inventory"] = {}}, ["y"] = 12, ["z"] = 7, ["name"] = "wool:white"}, {["x"] = 4, ["meta"] = {["fields"] = {}, ["inventory"] = {}}, ["y"] = 12, ["z"] = 8, ["name"] = "wool:white"}, {["x"] = 4, ["meta"] = {["fields"] = {}, ["inventory"] = {}}, ["y"] = 12, ["z"] = 9, ["name"] = "wool:white"}, {["x"] = 4, ["meta"] = {["fields"] = {}, ["inventory"] = {}}, ["y"] = 12, ["z"] = 10, ["name"] = "wool:white"}, {["x"] = 4, ["meta"] = {["fields"] = {}, ["inventory"] = {}}, ["y"] = 12, ["z"] = 11, ["name"] = "wool:white"}, {["x"] = 4, ["meta"] = {["fields"] = {}, ["inventory"] = {}}, ["y"] = 13, ["z"] = 4, ["name"] = "wool:white"}, {["x"] = 4, ["meta"] = {["fields"] = {}, ["inventory"] = {}}, ["y"] = 13, ["z"] = 5, ["name"] = "wool:white"}, {["x"] = 4, ["meta"] = {["fields"] = {}, ["inventory"] = {}}, ["y"] = 13, ["z"] = 6, ["name"] = "wool:white"}, {["x"] = 4, ["meta"] = {["fields"] = {}, ["inventory"] = {}}, ["y"] = 13, ["z"] = 7, ["name"] = "wool:white"}, {["x"] = 4, ["meta"] = {["fields"] = {}, ["inventory"] = {}}, ["y"] = 13, ["z"] = 8, ["name"] = "wool:white"}, {["x"] = 4, ["meta"] = {["fields"] = {}, ["inventory"] = {}}, ["y"] = 13, ["z"] = 9, ["name"] = "wool:white"}, {["x"] = 4, ["meta"] = {["fields"] = {}, ["inventory"] = {}}, ["y"] = 13, ["z"] = 10, ["name"] = "wool:white"}, {["x"] = 4, ["meta"] = {["fields"] = {}, ["inventory"] = {}}, ["y"] = 13, ["z"] = 11, ["name"] = "wool:white"}, {["x"] = 4, ["meta"] = {["fields"] = {}, ["inventory"] = {}}, ["y"] = 14, ["z"] = 4, ["name"] = "wool:white"}, {["x"] = 4, ["meta"] = {["fields"] = {}, ["inventory"] = {}}, ["y"] = 14, ["z"] = 5, ["name"] = "wool:white"}, {["x"] = 4, ["meta"] = {["fields"] = {}, ["inventory"] = {}}, ["y"] = 14, ["z"] = 6, ["name"] = "wool:white"}, {["x"] = 4, ["meta"] = {["fields"] = {}, ["inventory"] = {}}, ["y"] = 14, ["z"] = 7, ["name"] = "wool:white"}, {["x"] = 4, ["meta"] = {["fields"] = {}, ["inventory"] = {}}, ["y"] = 14, ["z"] = 8, ["name"] = "wool:white"}, {["x"] = 4, ["meta"] = {["fields"] = {}, ["inventory"] = {}}, ["y"] = 14, ["z"] = 9, ["name"] = "wool:white"}, {["x"] = 4, ["meta"] = {["fields"] = {}, ["inventory"] = {}}, ["y"] = 14, ["z"] = 10, ["name"] = "wool:white"}, {["x"] = 4, ["meta"] = {["fields"] = {}, ["inventory"] = {}}, ["y"] = 14, ["z"] = 11, ["name"] = "wool:white"}, {["x"] = 4, ["meta"] = {["fields"] = {}, ["inventory"] = {}}, ["y"] = 15, ["z"] = 4, ["name"] = "wool:white"}, {["x"] = 4, ["meta"] = {["fields"] = {}, ["inventory"] = {}}, ["y"] = 15, ["z"] = 5, ["name"] = "wool:white"}, {["x"] = 4, ["meta"] = {["fields"] = {}, ["inventory"] = {}}, ["y"] = 15, ["z"] = 6, ["name"] = "wool:white"}, {["x"] = 4, ["meta"] = {["fields"] = {}, ["inventory"] = {}}, ["y"] = 15, ["z"] = 7, ["name"] = "wool:white"}, {["x"] = 4, ["meta"] = {["fields"] = {}, ["inventory"] = {}}, ["y"] = 15, ["z"] = 8, ["name"] = "wool:white"}, {["x"] = 4, ["meta"] = {["fields"] = {}, ["inventory"] = {}}, ["y"] = 15, ["z"] = 9, ["name"] = "wool:white"}, {["x"] = 4, ["meta"] = {["fields"] = {}, ["inventory"] = {}}, ["y"] = 15, ["z"] = 10, ["name"] = "wool:white"}, {["x"] = 4, ["meta"] = {["fields"] = {}, ["inventory"] = {}}, ["y"] = 15, ["z"] = 11, ["name"] = "wool:white"}, {["x"] = 5, ["meta"] = {["fields"] = {}, ["inventory"] = {}}, ["y"] = 8, ["z"] = 4, ["name"] = "wool:white"}, {["x"] = 5, ["meta"] = {["fields"] = {}, ["inventory"] = {}}, ["y"] = 8, ["z"] = 5, ["name"] = "wool:white"}, {["x"] = 5, ["meta"] = {["fields"] = {}, ["inventory"] = {}}, ["y"] = 8, ["z"] = 6, ["name"] = "wool:white"}, {["x"] = 5, ["meta"] = {["fields"] = {}, ["inventory"] = {}}, ["y"] = 8, ["z"] = 7, ["name"] = "wool:white"}, {["x"] = 5, ["meta"] = {["fields"] = {}, ["inventory"] = {}}, ["y"] = 8, ["z"] = 9, ["name"] = "wool:white"}, {["x"] = 5, ["meta"] = {["fields"] = {}, ["inventory"] = {}}, ["y"] = 8, ["z"] = 10, ["name"] = "wool:white"}, {["x"] = 5, ["meta"] = {["fields"] = {}, ["inventory"] = {}}, ["y"] = 8, ["z"] = 11, ["name"] = "wool:white"}, {["x"] = 5, ["meta"] = {["fields"] = {}, ["inventory"] = {}}, ["y"] = 9, ["z"] = 4, ["name"] = "wool:white"}, {["x"] = 5, ["meta"] = {["fields"] = {}, ["inventory"] = {}}, ["y"] = 9, ["z"] = 11, ["name"] = "wool:white"}, {["x"] = 5, ["meta"] = {["fields"] = {}, ["inventory"] = {}}, ["y"] = 10, ["z"] = 4, ["name"] = "wool:white"}, {["x"] = 5, ["meta"] = {["fields"] = {}, ["inventory"] = {}}, ["y"] = 10, ["z"] = 11, ["name"] = "wool:white"}, {["x"] = 5, ["meta"] = {["fields"] = {}, ["inventory"] = {}}, ["y"] = 11, ["z"] = 4, ["name"] = "wool:white"}, {["x"] = 5, ["meta"] = {["fields"] = {}, ["inventory"] = {}}, ["y"] = 11, ["z"] = 11, ["name"] = "wool:white"}, {["x"] = 5, ["meta"] = {["fields"] = {}, ["inventory"] = {}}, ["y"] = 12, ["z"] = 11, ["name"] = "wool:white"}, {["x"] = 5, ["meta"] = {["fields"] = {}, ["inventory"] = {}}, ["y"] = 13, ["z"] = 4, ["name"] = "wool:white"}, {["x"] = 5, ["meta"] = {["fields"] = {}, ["inventory"] = {}}, ["y"] = 13, ["z"] = 11, ["name"] = "wool:white"}, {["x"] = 5, ["meta"] = {["fields"] = {}, ["inventory"] = {}}, ["y"] = 14, ["z"] = 4, ["name"] = "wool:white"}, {["x"] = 5, ["meta"] = {["fields"] = {}, ["inventory"] = {}}, ["y"] = 14, ["z"] = 11, ["name"] = "wool:white"}, {["x"] = 5, ["meta"] = {["fields"] = {}, ["inventory"] = {}}, ["y"] = 15, ["z"] = 4, ["name"] = "wool:white"}, {["x"] = 5, ["meta"] = {["fields"] = {}, ["inventory"] = {}}, ["y"] = 15, ["z"] = 5, ["name"] = "wool:white"}, {["x"] = 5, ["meta"] = {["fields"] = {}, ["inventory"] = {}}, ["y"] = 15, ["z"] = 6, ["name"] = "wool:white"}, {["x"] = 5, ["meta"] = {["fields"] = {}, ["inventory"] = {}}, ["y"] = 15, ["z"] = 7, ["name"] = "wool:white"}, {["x"] = 5, ["meta"] = {["fields"] = {}, ["inventory"] = {}}, ["y"] = 15, ["z"] = 8, ["name"] = "wool:white"}, {["x"] = 5, ["meta"] = {["fields"] = {}, ["inventory"] = {}}, ["y"] = 15, ["z"] = 9, ["name"] = "wool:white"}, {["x"] = 5, ["meta"] = {["fields"] = {}, ["inventory"] = {}}, ["y"] = 15, ["z"] = 10, ["name"] = "wool:white"}, {["x"] = 5, ["meta"] = {["fields"] = {}, ["inventory"] = {}}, ["y"] = 15, ["z"] = 11, ["name"] = "wool:white"}, {["x"] = 6, ["meta"] = {["fields"] = {}, ["inventory"] = {}}, ["y"] = 8, ["z"] = 4, ["name"] = "wool:white"}, {["x"] = 6, ["meta"] = {["fields"] = {}, ["inventory"] = {}}, ["y"] = 8, ["z"] = 5, ["name"] = "wool:white"}, {["x"] = 6, ["meta"] = {["fields"] = {}, ["inventory"] = {}}, ["y"] = 8, ["z"] = 6, ["name"] = "wool:white"}, {["x"] = 6, ["meta"] = {["fields"] = {}, ["inventory"] = {}}, ["y"] = 8, ["z"] = 7, ["name"] = "wool:white"}, {["x"] = 6, ["meta"] = {["fields"] = {}, ["inventory"] = {}}, ["y"] = 8, ["z"] = 8, ["name"] = "wool:white"}, {["x"] = 6, ["meta"] = {["fields"] = {}, ["inventory"] = {}}, ["y"] = 8, ["z"] = 9, ["name"] = "wool:white"}, {["x"] = 6, ["meta"] = {["fields"] = {}, ["inventory"] = {}}, ["y"] = 8, ["z"] = 10, ["name"] = "wool:white"}, {["x"] = 6, ["meta"] = {["fields"] = {}, ["inventory"] = {}}, ["y"] = 8, ["z"] = 11, ["name"] = "wool:white"}, {["x"] = 6, ["meta"] = {["fields"] = {}, ["inventory"] = {}}, ["y"] = 9, ["z"] = 4, ["name"] = "wool:white"}, {["x"] = 6, ["meta"] = {["fields"] = {}, ["inventory"] = {}}, ["y"] = 9, ["z"] = 11, ["name"] = "wool:white"}, {["x"] = 6, ["meta"] = {["fields"] = {}, ["inventory"] = {}}, ["y"] = 10, ["z"] = 4, ["name"] = "wool:white"}, {["x"] = 6, ["meta"] = {["fields"] = {}, ["inventory"] = {}}, ["y"] = 10, ["z"] = 11, ["name"] = "wool:white"}, {["x"] = 6, ["meta"] = {["fields"] = {}, ["inventory"] = {}}, ["y"] = 11, ["z"] = 4, ["name"] = "wool:white"}, {["x"] = 6, ["meta"] = {["fields"] = {}, ["inventory"] = {}}, ["y"] = 11, ["z"] = 11, ["name"] = "wool:white"}, {["x"] = 6, ["meta"] = {["fields"] = {}, ["inventory"] = {}}, ["y"] = 12, ["z"] = 11, ["name"] = "wool:white"}, {["x"] = 6, ["meta"] = {["fields"] = {}, ["inventory"] = {}}, ["y"] = 13, ["z"] = 4, ["name"] = "wool:white"}, {["x"] = 6, ["meta"] = {["fields"] = {}, ["inventory"] = {}}, ["y"] = 13, ["z"] = 11, ["name"] = "wool:white"}, {["x"] = 6, ["meta"] = {["fields"] = {}, ["inventory"] = {}}, ["y"] = 14, ["z"] = 4, ["name"] = "wool:white"}, {["x"] = 6, ["meta"] = {["fields"] = {}, ["inventory"] = {}}, ["y"] = 14, ["z"] = 11, ["name"] = "wool:white"}, {["x"] = 6, ["meta"] = {["fields"] = {}, ["inventory"] = {}}, ["y"] = 15, ["z"] = 4, ["name"] = "wool:white"}, {["x"] = 6, ["meta"] = {["fields"] = {}, ["inventory"] = {}}, ["y"] = 15, ["z"] = 5, ["name"] = "wool:white"}, {["x"] = 6, ["meta"] = {["fields"] = {}, ["inventory"] = {}}, ["y"] = 15, ["z"] = 6, ["name"] = "wool:white"}, {["x"] = 6, ["meta"] = {["fields"] = {}, ["inventory"] = {}}, ["y"] = 15, ["z"] = 7, ["name"] = "wool:white"}, {["x"] = 6, ["meta"] = {["fields"] = {}, ["inventory"] = {}}, ["y"] = 15, ["z"] = 8, ["name"] = "wool:white"}, {["x"] = 6, ["meta"] = {["fields"] = {}, ["inventory"] = {}}, ["y"] = 15, ["z"] = 9, ["name"] = "wool:white"}, {["x"] = 6, ["meta"] = {["fields"] = {}, ["inventory"] = {}}, ["y"] = 15, ["z"] = 10, ["name"] = "wool:white"}, {["x"] = 6, ["meta"] = {["fields"] = {}, ["inventory"] = {}}, ["y"] = 15, ["z"] = 11, ["name"] = "wool:white"}, {["x"] = 7, ["meta"] = {["fields"] = {}, ["inventory"] = {}}, ["y"] = 7, ["z"] = 8, ["name"] = "wool:white"}, {["x"] = 7, ["meta"] = {["fields"] = {}, ["inventory"] = {}}, ["y"] = 7, ["z"] = 9, ["name"] = "wool:white"}, {["x"] = 7, ["meta"] = {["fields"] = {}, ["inventory"] = {}}, ["y"] = 8, ["z"] = 4, ["name"] = "wool:white"}, {["x"] = 7, ["meta"] = {["fields"] = {}, ["inventory"] = {}}, ["y"] = 8, ["z"] = 5, ["name"] = "wool:white"}, {["x"] = 7, ["meta"] = {["fields"] = {}, ["inventory"] = {}}, ["y"] = 8, ["z"] = 6, ["name"] = "wool:white"}, {["x"] = 7, ["meta"] = {["fields"] = {}, ["inventory"] = {}}, ["y"] = 8, ["z"] = 7, ["name"] = "wool:white"}, {["x"] = 7, ["meta"] = {["fields"] = {}, ["inventory"] = {}}, ["y"] = 8, ["z"] = 10, ["name"] = "wool:white"}, {["x"] = 7, ["meta"] = {["fields"] = {}, ["inventory"] = {}}, ["y"] = 8, ["z"] = 11, ["name"] = "wool:white"}, {["x"] = 7, ["meta"] = {["fields"] = {}, ["inventory"] = {}}, ["y"] = 9, ["z"] = 8, ["name"] = "wool:white"}, {["x"] = 7, ["meta"] = {["fields"] = {}, ["inventory"] = {}}, ["y"] = 9, ["z"] = 9, ["name"] = "wool:white"}, {["x"] = 7, ["meta"] = {["fields"] = {}, ["inventory"] = {}}, ["y"] = 9, ["z"] = 11, ["name"] = "wool:white"}, {["x"] = 7, ["meta"] = {["fields"] = {}, ["inventory"] = {}}, ["y"] = 10, ["z"] = 4, ["name"] = "wool:white"}, {["x"] = 7, ["meta"] = {["fields"] = {}, ["inventory"] = {}}, ["y"] = 10, ["z"] = 11, ["name"] = "wool:white"}, {["x"] = 7, ["meta"] = {["fields"] = {}, ["inventory"] = {}}, ["y"] = 11, ["z"] = 11, ["name"] = "wool:white"}, {["x"] = 7, ["meta"] = {["fields"] = {}, ["inventory"] = {}}, ["y"] = 12, ["z"] = 4, ["name"] = "wool:white"}, {["x"] = 7, ["meta"] = {["fields"] = {}, ["inventory"] = {}}, ["y"] = 12, ["z"] = 11, ["name"] = "wool:white"}, {["x"] = 7, ["meta"] = {["fields"] = {}, ["inventory"] = {}}, ["y"] = 13, ["z"] = 4, ["name"] = "wool:white"}, {["x"] = 7, ["meta"] = {["fields"] = {}, ["inventory"] = {}}, ["y"] = 13, ["z"] = 11, ["name"] = "wool:white"}, {["x"] = 7, ["meta"] = {["fields"] = {}, ["inventory"] = {}}, ["y"] = 14, ["z"] = 4, ["name"] = "wool:white"}, {["x"] = 7, ["meta"] = {["fields"] = {}, ["inventory"] = {}}, ["y"] = 14, ["z"] = 11, ["name"] = "wool:white"}, {["x"] = 7, ["meta"] = {["fields"] = {}, ["inventory"] = {}}, ["y"] = 15, ["z"] = 4, ["name"] = "wool:white"}, {["x"] = 7, ["meta"] = {["fields"] = {}, ["inventory"] = {}}, ["y"] = 15, ["z"] = 5, ["name"] = "wool:white"}, {["x"] = 7, ["meta"] = {["fields"] = {}, ["inventory"] = {}}, ["y"] = 15, ["z"] = 6, ["name"] = "wool:white"}, {["x"] = 7, ["meta"] = {["fields"] = {}, ["inventory"] = {}}, ["y"] = 15, ["z"] = 7, ["name"] = "wool:white"}, {["x"] = 7, ["meta"] = {["fields"] = {}, ["inventory"] = {}}, ["y"] = 15, ["z"] = 8, ["name"] = "wool:white"}, {["x"] = 7, ["meta"] = {["fields"] = {}, ["inventory"] = {}}, ["y"] = 15, ["z"] = 9, ["name"] = "wool:white"}, {["x"] = 7, ["meta"] = {["fields"] = {}, ["inventory"] = {}}, ["y"] = 15, ["z"] = 10, ["name"] = "wool:white"}, {["x"] = 7, ["meta"] = {["fields"] = {}, ["inventory"] = {}}, ["y"] = 15, ["z"] = 11, ["name"] = "wool:white"}, {["x"] = 8, ["meta"] = {["fields"] = {}, ["inventory"] = {}}, ["y"] = 7, ["z"] = 8, ["name"] = "wool:white"}, {["x"] = 8, ["meta"] = {["fields"] = {}, ["inventory"] = {}}, ["y"] = 7, ["z"] = 9, ["name"] = "wool:white"}, {["x"] = 8, ["meta"] = {["fields"] = {}, ["inventory"] = {}}, ["y"] = 8, ["z"] = 4, ["name"] = "wool:white"}, {["x"] = 8, ["meta"] = {["fields"] = {}, ["inventory"] = {}}, ["y"] = 8, ["z"] = 5, ["name"] = "wool:white"}, {["x"] = 8, ["meta"] = {["fields"] = {}, ["inventory"] = {}}, ["y"] = 8, ["z"] = 6, ["name"] = "wool:white"}, {["x"] = 8, ["meta"] = {["fields"] = {}, ["inventory"] = {}}, ["y"] = 8, ["z"] = 7, ["name"] = "wool:white"}, {["x"] = 8, ["meta"] = {["fields"] = {}, ["inventory"] = {}}, ["y"] = 8, ["z"] = 10, ["name"] = "wool:white"}, {["x"] = 8, ["meta"] = {["fields"] = {}, ["inventory"] = {}}, ["y"] = 8, ["z"] = 11, ["name"] = "wool:white"}, {["x"] = 8, ["meta"] = {["fields"] = {}, ["inventory"] = {}}, ["y"] = 9, ["z"] = 8, ["name"] = "wool:white"}, {["x"] = 8, ["meta"] = {["fields"] = {}, ["inventory"] = {}}, ["y"] = 9, ["z"] = 9, ["name"] = "wool:white"}, {["x"] = 8, ["meta"] = {["fields"] = {}, ["inventory"] = {}}, ["y"] = 9, ["z"] = 11, ["name"] = "wool:white"}, {["x"] = 8, ["meta"] = {["fields"] = {}, ["inventory"] = {}}, ["y"] = 10, ["z"] = 4, ["name"] = "wool:white"}, {["x"] = 8, ["meta"] = {["fields"] = {}, ["inventory"] = {}}, ["y"] = 10, ["z"] = 11, ["name"] = "wool:white"}, {["x"] = 8, ["meta"] = {["fields"] = {}, ["inventory"] = {}}, ["y"] = 11, ["z"] = 11, ["name"] = "wool:white"}, {["x"] = 8, ["meta"] = {["fields"] = {}, ["inventory"] = {}}, ["y"] = 12, ["z"] = 4, ["name"] = "wool:white"}, {["x"] = 8, ["meta"] = {["fields"] = {}, ["inventory"] = {}}, ["y"] = 12, ["z"] = 11, ["name"] = "wool:white"}, {["x"] = 8, ["meta"] = {["fields"] = {}, ["inventory"] = {}}, ["y"] = 13, ["z"] = 4, ["name"] = "wool:white"}, {["x"] = 8, ["meta"] = {["fields"] = {}, ["inventory"] = {}}, ["y"] = 13, ["z"] = 11, ["name"] = "wool:white"}, {["x"] = 8, ["meta"] = {["fields"] = {}, ["inventory"] = {}}, ["y"] = 14, ["z"] = 4, ["name"] = "wool:white"}, {["x"] = 8, ["meta"] = {["fields"] = {}, ["inventory"] = {}}, ["y"] = 14, ["z"] = 11, ["name"] = "wool:white"}, {["x"] = 8, ["meta"] = {["fields"] = {}, ["inventory"] = {}}, ["y"] = 15, ["z"] = 4, ["name"] = "wool:white"}, {["x"] = 8, ["meta"] = {["fields"] = {}, ["inventory"] = {}}, ["y"] = 15, ["z"] = 5, ["name"] = "wool:white"}, {["x"] = 8, ["meta"] = {["fields"] = {}, ["inventory"] = {}}, ["y"] = 15, ["z"] = 6, ["name"] = "wool:white"}, {["x"] = 8, ["meta"] = {["fields"] = {}, ["inventory"] = {}}, ["y"] = 15, ["z"] = 7, ["name"] = "wool:white"}, {["x"] = 8, ["meta"] = {["fields"] = {}, ["inventory"] = {}}, ["y"] = 15, ["z"] = 8, ["name"] = "wool:white"}, {["x"] = 8, ["meta"] = {["fields"] = {}, ["inventory"] = {}}, ["y"] = 15, ["z"] = 9, ["name"] = "wool:white"}, {["x"] = 8, ["meta"] = {["fields"] = {}, ["inventory"] = {}}, ["y"] = 15, ["z"] = 10, ["name"] = "wool:white"}, {["x"] = 8, ["meta"] = {["fields"] = {}, ["inventory"] = {}}, ["y"] = 15, ["z"] = 11, ["name"] = "wool:white"}, {["x"] = 9, ["meta"] = {["fields"] = {}, ["inventory"] = {}}, ["y"] = 8, ["z"] = 4, ["name"] = "wool:white"}, {["x"] = 9, ["meta"] = {["fields"] = {}, ["inventory"] = {}}, ["y"] = 8, ["z"] = 5, ["name"] = "wool:white"}, {["x"] = 9, ["meta"] = {["fields"] = {}, ["inventory"] = {}}, ["y"] = 8, ["z"] = 6, ["name"] = "wool:white"}, {["x"] = 9, ["meta"] = {["fields"] = {}, ["inventory"] = {}}, ["y"] = 8, ["z"] = 7, ["name"] = "wool:white"}, {["x"] = 9, ["meta"] = {["fields"] = {}, ["inventory"] = {}}, ["y"] = 8, ["z"] = 8, ["name"] = "wool:white"}, {["x"] = 9, ["meta"] = {["fields"] = {}, ["inventory"] = {}}, ["y"] = 8, ["z"] = 9, ["name"] = "wool:white"}, {["x"] = 9, ["meta"] = {["fields"] = {}, ["inventory"] = {}}, ["y"] = 8, ["z"] = 10, ["name"] = "wool:white"}, {["x"] = 9, ["meta"] = {["fields"] = {}, ["inventory"] = {}}, ["y"] = 8, ["z"] = 11, ["name"] = "wool:white"}, {["x"] = 9, ["meta"] = {["fields"] = {}, ["inventory"] = {}}, ["y"] = 9, ["z"] = 4, ["name"] = "wool:white"}, {["x"] = 9, ["meta"] = {["fields"] = {}, ["inventory"] = {}}, ["y"] = 9, ["z"] = 11, ["name"] = "wool:white"}, {["x"] = 9, ["meta"] = {["fields"] = {}, ["inventory"] = {}}, ["y"] = 10, ["z"] = 4, ["name"] = "wool:white"}, {["x"] = 9, ["meta"] = {["fields"] = {}, ["inventory"] = {}}, ["y"] = 10, ["z"] = 11, ["name"] = "wool:white"}, {["x"] = 9, ["meta"] = {["fields"] = {}, ["inventory"] = {}}, ["y"] = 11, ["z"] = 4, ["name"] = "wool:white"}, {["x"] = 9, ["meta"] = {["fields"] = {}, ["inventory"] = {}}, ["y"] = 11, ["z"] = 11, ["name"] = "wool:white"}, {["x"] = 9, ["meta"] = {["fields"] = {}, ["inventory"] = {}}, ["y"] = 12, ["z"] = 11, ["name"] = "wool:white"}, {["x"] = 9, ["meta"] = {["fields"] = {}, ["inventory"] = {}}, ["y"] = 13, ["z"] = 4, ["name"] = "wool:white"}, {["x"] = 9, ["meta"] = {["fields"] = {}, ["inventory"] = {}}, ["y"] = 13, ["z"] = 11, ["name"] = "wool:white"}, {["x"] = 9, ["meta"] = {["fields"] = {}, ["inventory"] = {}}, ["y"] = 14, ["z"] = 4, ["name"] = "wool:white"}, {["x"] = 9, ["meta"] = {["fields"] = {}, ["inventory"] = {}}, ["y"] = 14, ["z"] = 11, ["name"] = "wool:white"}, {["x"] = 9, ["meta"] = {["fields"] = {}, ["inventory"] = {}}, ["y"] = 15, ["z"] = 4, ["name"] = "wool:white"}, {["x"] = 9, ["meta"] = {["fields"] = {}, ["inventory"] = {}}, ["y"] = 15, ["z"] = 5, ["name"] = "wool:white"}, {["x"] = 9, ["meta"] = {["fields"] = {}, ["inventory"] = {}}, ["y"] = 15, ["z"] = 6, ["name"] = "wool:white"}, {["x"] = 9, ["meta"] = {["fields"] = {}, ["inventory"] = {}}, ["y"] = 15, ["z"] = 7, ["name"] = "wool:white"}, {["x"] = 9, ["meta"] = {["fields"] = {}, ["inventory"] = {}}, ["y"] = 15, ["z"] = 8, ["name"] = "wool:white"}, {["x"] = 9, ["meta"] = {["fields"] = {}, ["inventory"] = {}}, ["y"] = 15, ["z"] = 9, ["name"] = "wool:white"}, {["x"] = 9, ["meta"] = {["fields"] = {}, ["inventory"] = {}}, ["y"] = 15, ["z"] = 10, ["name"] = "wool:white"}, {["x"] = 9, ["meta"] = {["fields"] = {}, ["inventory"] = {}}, ["y"] = 15, ["z"] = 11, ["name"] = "wool:white"}, {["x"] = 10, ["meta"] = {["fields"] = {}, ["inventory"] = {}}, ["y"] = 8, ["z"] = 4, ["name"] = "wool:white"}, {["x"] = 10, ["meta"] = {["fields"] = {}, ["inventory"] = {}}, ["y"] = 8, ["z"] = 5, ["name"] = "wool:white"}, {["x"] = 10, ["meta"] = {["fields"] = {}, ["inventory"] = {}}, ["y"] = 8, ["z"] = 6, ["name"] = "wool:white"}, {["x"] = 10, ["meta"] = {["fields"] = {}, ["inventory"] = {}}, ["y"] = 8, ["z"] = 7, ["name"] = "wool:white"}, {["x"] = 10, ["meta"] = {["fields"] = {}, ["inventory"] = {}}, ["y"] = 8, ["z"] = 9, ["name"] = "wool:white"}, {["x"] = 10, ["meta"] = {["fields"] = {}, ["inventory"] = {}}, ["y"] = 8, ["z"] = 10, ["name"] = "wool:white"}, {["x"] = 10, ["meta"] = {["fields"] = {}, ["inventory"] = {}}, ["y"] = 8, ["z"] = 11, ["name"] = "wool:white"}, {["x"] = 10, ["meta"] = {["fields"] = {}, ["inventory"] = {}}, ["y"] = 9, ["z"] = 4, ["name"] = "wool:white"}, {["x"] = 10, ["meta"] = {["fields"] = {}, ["inventory"] = {}}, ["y"] = 9, ["z"] = 11, ["name"] = "wool:white"}, {["x"] = 10, ["meta"] = {["fields"] = {}, ["inventory"] = {}}, ["y"] = 10, ["z"] = 4, ["name"] = "wool:white"}, {["x"] = 10, ["meta"] = {["fields"] = {}, ["inventory"] = {}}, ["y"] = 10, ["z"] = 11, ["name"] = "wool:white"}, {["x"] = 10, ["meta"] = {["fields"] = {}, ["inventory"] = {}}, ["y"] = 11, ["z"] = 4, ["name"] = "wool:white"}, {["x"] = 10, ["meta"] = {["fields"] = {}, ["inventory"] = {}}, ["y"] = 11, ["z"] = 11, ["name"] = "wool:white"}, {["x"] = 10, ["meta"] = {["fields"] = {}, ["inventory"] = {}}, ["y"] = 12, ["z"] = 11, ["name"] = "wool:white"}, {["x"] = 10, ["meta"] = {["fields"] = {}, ["inventory"] = {}}, ["y"] = 13, ["z"] = 4, ["name"] = "wool:white"}, {["x"] = 10, ["meta"] = {["fields"] = {}, ["inventory"] = {}}, ["y"] = 13, ["z"] = 11, ["name"] = "wool:white"}, {["x"] = 10, ["meta"] = {["fields"] = {}, ["inventory"] = {}}, ["y"] = 14, ["z"] = 4, ["name"] = "wool:white"}, {["x"] = 10, ["meta"] = {["fields"] = {}, ["inventory"] = {}}, ["y"] = 14, ["z"] = 11, ["name"] = "wool:white"}, {["x"] = 10, ["meta"] = {["fields"] = {}, ["inventory"] = {}}, ["y"] = 15, ["z"] = 4, ["name"] = "wool:white"}, {["x"] = 10, ["meta"] = {["fields"] = {}, ["inventory"] = {}}, ["y"] = 15, ["z"] = 5, ["name"] = "wool:white"}, {["x"] = 10, ["meta"] = {["fields"] = {}, ["inventory"] = {}}, ["y"] = 15, ["z"] = 6, ["name"] = "wool:white"}, {["x"] = 10, ["meta"] = {["fields"] = {}, ["inventory"] = {}}, ["y"] = 15, ["z"] = 7, ["name"] = "wool:white"}, {["x"] = 10, ["meta"] = {["fields"] = {}, ["inventory"] = {}}, ["y"] = 15, ["z"] = 8, ["name"] = "wool:white"}, {["x"] = 10, ["meta"] = {["fields"] = {}, ["inventory"] = {}}, ["y"] = 15, ["z"] = 9, ["name"] = "wool:white"}, {["x"] = 10, ["meta"] = {["fields"] = {}, ["inventory"] = {}}, ["y"] = 15, ["z"] = 10, ["name"] = "wool:white"}, {["x"] = 10, ["meta"] = {["fields"] = {}, ["inventory"] = {}}, ["y"] = 15, ["z"] = 11, ["name"] = "wool:white"}, {["x"] = 11, ["meta"] = {["fields"] = {}, ["inventory"] = {}}, ["y"] = 8, ["z"] = 4, ["name"] = "wool:white"}, {["x"] = 11, ["meta"] = {["fields"] = {}, ["inventory"] = {}}, ["y"] = 8, ["z"] = 5, ["name"] = "wool:white"}, {["x"] = 11, ["meta"] = {["fields"] = {}, ["inventory"] = {}}, ["y"] = 8, ["z"] = 6, ["name"] = "wool:white"}, {["x"] = 11, ["meta"] = {["fields"] = {}, ["inventory"] = {}}, ["y"] = 8, ["z"] = 7, ["name"] = "wool:white"}, {["x"] = 11, ["meta"] = {["fields"] = {}, ["inventory"] = {}}, ["y"] = 8, ["z"] = 9, ["name"] = "wool:white"}, {["x"] = 11, ["meta"] = {["fields"] = {}, ["inventory"] = {}}, ["y"] = 8, ["z"] = 10, ["name"] = "wool:white"}, {["x"] = 11, ["meta"] = {["fields"] = {}, ["inventory"] = {}}, ["y"] = 8, ["z"] = 11, ["name"] = "wool:white"}, {["x"] = 11, ["meta"] = {["fields"] = {}, ["inventory"] = {}}, ["y"] = 9, ["z"] = 4, ["name"] = "wool:white"}, {["x"] = 11, ["meta"] = {["fields"] = {}, ["inventory"] = {}}, ["y"] = 9, ["z"] = 5, ["name"] = "wool:white"}, {["x"] = 11, ["meta"] = {["fields"] = {}, ["inventory"] = {}}, ["y"] = 9, ["z"] = 6, ["name"] = "wool:white"}, {["x"] = 11, ["meta"] = {["fields"] = {}, ["inventory"] = {}}, ["y"] = 9, ["z"] = 7, ["name"] = "wool:white"}, {["x"] = 11, ["meta"] = {["fields"] = {}, ["inventory"] = {}}, ["y"] = 9, ["z"] = 9, ["name"] = "wool:white"}, {["x"] = 11, ["meta"] = {["fields"] = {}, ["inventory"] = {}}, ["y"] = 9, ["z"] = 10, ["name"] = "wool:white"}, {["x"] = 11, ["meta"] = {["fields"] = {}, ["inventory"] = {}}, ["y"] = 9, ["z"] = 11, ["name"] = "wool:white"}, {["x"] = 11, ["meta"] = {["fields"] = {}, ["inventory"] = {}}, ["y"] = 10, ["z"] = 4, ["name"] = "wool:white"}, {["x"] = 11, ["meta"] = {["fields"] = {}, ["inventory"] = {}}, ["y"] = 10, ["z"] = 5, ["name"] = "wool:white"}, {["x"] = 11, ["meta"] = {["fields"] = {}, ["inventory"] = {}}, ["y"] = 10, ["z"] = 6, ["name"] = "wool:white"}, {["x"] = 11, ["meta"] = {["fields"] = {}, ["inventory"] = {}}, ["y"] = 10, ["z"] = 7, ["name"] = "wool:white"}, {["x"] = 11, ["meta"] = {["fields"] = {}, ["inventory"] = {}}, ["y"] = 10, ["z"] = 8, ["name"] = "wool:white"}, {["x"] = 11, ["meta"] = {["fields"] = {}, ["inventory"] = {}}, ["y"] = 10, ["z"] = 9, ["name"] = "wool:white"}, {["x"] = 11, ["meta"] = {["fields"] = {}, ["inventory"] = {}}, ["y"] = 10, ["z"] = 10, ["name"] = "wool:white"}, {["x"] = 11, ["meta"] = {["fields"] = {}, ["inventory"] = {}}, ["y"] = 10, ["z"] = 11, ["name"] = "wool:white"}, {["x"] = 11, ["meta"] = {["fields"] = {}, ["inventory"] = {}}, ["y"] = 11, ["z"] = 4, ["name"] = "wool:white"}, {["x"] = 11, ["meta"] = {["fields"] = {}, ["inventory"] = {}}, ["y"] = 11, ["z"] = 5, ["name"] = "wool:white"}, {["x"] = 11, ["meta"] = {["fields"] = {}, ["inventory"] = {}}, ["y"] = 11, ["z"] = 6, ["name"] = "wool:white"}, {["x"] = 11, ["meta"] = {["fields"] = {}, ["inventory"] = {}}, ["y"] = 11, ["z"] = 7, ["name"] = "wool:white"}, {["x"] = 11, ["meta"] = {["fields"] = {}, ["inventory"] = {}}, ["y"] = 11, ["z"] = 8, ["name"] = "wool:white"}, {["x"] = 11, ["meta"] = {["fields"] = {}, ["inventory"] = {}}, ["y"] = 11, ["z"] = 9, ["name"] = "wool:white"}, {["x"] = 11, ["meta"] = {["fields"] = {}, ["inventory"] = {}}, ["y"] = 11, ["z"] = 10, ["name"] = "wool:white"}, {["x"] = 11, ["meta"] = {["fields"] = {}, ["inventory"] = {}}, ["y"] = 11, ["z"] = 11, ["name"] = "wool:white"}, {["x"] = 11, ["meta"] = {["fields"] = {}, ["inventory"] = {}}, ["y"] = 12, ["z"] = 4, ["name"] = "wool:white"}, {["x"] = 11, ["meta"] = {["fields"] = {}, ["inventory"] = {}}, ["y"] = 12, ["z"] = 5, ["name"] = "wool:white"}, {["x"] = 11, ["meta"] = {["fields"] = {}, ["inventory"] = {}}, ["y"] = 12, ["z"] = 6, ["name"] = "wool:white"}, {["x"] = 11, ["meta"] = {["fields"] = {}, ["inventory"] = {}}, ["y"] = 12, ["z"] = 7, ["name"] = "wool:white"}, {["x"] = 11, ["meta"] = {["fields"] = {}, ["inventory"] = {}}, ["y"] = 12, ["z"] = 8, ["name"] = "wool:white"}, {["x"] = 11, ["meta"] = {["fields"] = {}, ["inventory"] = {}}, ["y"] = 12, ["z"] = 9, ["name"] = "wool:white"}, {["x"] = 11, ["meta"] = {["fields"] = {}, ["inventory"] = {}}, ["y"] = 12, ["z"] = 10, ["name"] = "wool:white"}, {["x"] = 11, ["meta"] = {["fields"] = {}, ["inventory"] = {}}, ["y"] = 12, ["z"] = 11, ["name"] = "wool:white"}, {["x"] = 11, ["meta"] = {["fields"] = {}, ["inventory"] = {}}, ["y"] = 13, ["z"] = 4, ["name"] = "wool:white"}, {["x"] = 11, ["meta"] = {["fields"] = {}, ["inventory"] = {}}, ["y"] = 13, ["z"] = 5, ["name"] = "wool:white"}, {["x"] = 11, ["meta"] = {["fields"] = {}, ["inventory"] = {}}, ["y"] = 13, ["z"] = 6, ["name"] = "wool:white"}, {["x"] = 11, ["meta"] = {["fields"] = {}, ["inventory"] = {}}, ["y"] = 13, ["z"] = 7, ["name"] = "wool:white"}, {["x"] = 11, ["meta"] = {["fields"] = {}, ["inventory"] = {}}, ["y"] = 13, ["z"] = 8, ["name"] = "wool:white"}, {["x"] = 11, ["meta"] = {["fields"] = {}, ["inventory"] = {}}, ["y"] = 13, ["z"] = 9, ["name"] = "wool:white"}, {["x"] = 11, ["meta"] = {["fields"] = {}, ["inventory"] = {}}, ["y"] = 13, ["z"] = 10, ["name"] = "wool:white"}, {["x"] = 11, ["meta"] = {["fields"] = {}, ["inventory"] = {}}, ["y"] = 13, ["z"] = 11, ["name"] = "wool:white"}, {["x"] = 11, ["meta"] = {["fields"] = {}, ["inventory"] = {}}, ["y"] = 14, ["z"] = 4, ["name"] = "wool:white"}, {["x"] = 11, ["meta"] = {["fields"] = {}, ["inventory"] = {}}, ["y"] = 14, ["z"] = 5, ["name"] = "wool:white"}, {["x"] = 11, ["meta"] = {["fields"] = {}, ["inventory"] = {}}, ["y"] = 14, ["z"] = 6, ["name"] = "wool:white"}, {["x"] = 11, ["meta"] = {["fields"] = {}, ["inventory"] = {}}, ["y"] = 14, ["z"] = 7, ["name"] = "wool:white"}, {["x"] = 11, ["meta"] = {["fields"] = {}, ["inventory"] = {}}, ["y"] = 14, ["z"] = 8, ["name"] = "wool:white"}, {["x"] = 11, ["meta"] = {["fields"] = {}, ["inventory"] = {}}, ["y"] = 14, ["z"] = 9, ["name"] = "wool:white"}, {["x"] = 11, ["meta"] = {["fields"] = {}, ["inventory"] = {}}, ["y"] = 14, ["z"] = 10, ["name"] = "wool:white"}, {["x"] = 11, ["meta"] = {["fields"] = {}, ["inventory"] = {}}, ["y"] = 14, ["z"] = 11, ["name"] = "wool:white"}, {["x"] = 11, ["meta"] = {["fields"] = {}, ["inventory"] = {}}, ["y"] = 15, ["z"] = 4, ["name"] = "wool:white"}, {["x"] = 11, ["meta"] = {["fields"] = {}, ["inventory"] = {}}, ["y"] = 15, ["z"] = 5, ["name"] = "wool:white"}, {["x"] = 11, ["meta"] = {["fields"] = {}, ["inventory"] = {}}, ["y"] = 15, ["z"] = 6, ["name"] = "wool:white"}, {["x"] = 11, ["meta"] = {["fields"] = {}, ["inventory"] = {}}, ["y"] = 15, ["z"] = 7, ["name"] = "wool:white"}, {["x"] = 11, ["meta"] = {["fields"] = {}, ["inventory"] = {}}, ["y"] = 15, ["z"] = 8, ["name"] = "wool:white"}, {["x"] = 11, ["meta"] = {["fields"] = {}, ["inventory"] = {}}, ["y"] = 15, ["z"] = 9, ["name"] = "wool:white"}, {["x"] = 11, ["meta"] = {["fields"] = {}, ["inventory"] = {}}, ["y"] = 15, ["z"] = 10, ["name"] = "wool:white"}, {["x"] = 11, ["meta"] = {["fields"] = {}, ["inventory"] = {}}, ["y"] = 15, ["z"] = 11, ["name"] = "wool:white"}}