5:return {{["x"] = 3, ["y"] = 3, ["z"] = 7, ["name"] = "wool:white"}, {["x"] = 3, ["y"] = 4, ["z"] = 7, ["name"] = "wool:white"}, {["x"] = 4, ["y"] = 5, ["z"] = 7, ["name"] = "wool:white"}, {["x"] = 4, ["y"] = 5, ["z"] = 8, ["name"] = "wool:white"}, {["x"] = 4, ["y"] = 6, ["z"] = 7, ["name"] = "wool:white"}, {["x"] = 4, ["y"] = 6, ["z"] = 8, ["name"] = "wool:white"}, {["x"] = 4, ["y"] = 7, ["z"] = 7, ["name"] = "wool:white"}, {["x"] = 4, ["y"] = 8, ["z"] = 7, ["name"] = "wool:white"}, {["x"] = 5, ["y"] = 0, ["z"] = 5, ["name"] = "wool:white"}, {["x"] = 5, ["y"] = 0, ["z"] = 6, ["name"] = "wool:white"}, {["x"] = 5, ["y"] = 1, ["z"] = 7, ["name"] = "wool:white"}, {["x"] = 5, ["y"] = 2, ["z"] = 7, ["name"] = "wool:white"}, {["x"] = 5, ["y"] = 5, ["z"] = 5, ["name"] = "wool:white"}, {["x"] = 5, ["y"] = 6, ["z"] = 5, ["name"] = "wool:white"}, {["x"] = 5, ["y"] = 7, ["z"] = 5, ["name"] = "wool:white"}, {["x"] = 5, ["y"] = 8, ["z"] = 6, ["name"] = "wool:white"}, {["x"] = 5, ["y"] = 8, ["z"] = 8, ["name"] = "wool:white"}, {["x"] = 6, ["y"] = 3, ["z"] = 8, ["name"] = "wool:white"}, {["x"] = 6, ["y"] = 3, ["z"] = 9, ["name"] = "wool:white"}, {["x"] = 6, ["y"] = 4, ["z"] = 5, ["name"] = "wool:white"}, {["x"] = 6, ["y"] = 6, ["z"] = 5, ["name"] = "wool:white"}, {["x"] = 6, ["y"] = 6, ["z"] = 7, ["name"] = "wool:white"}, {["x"] = 6, ["y"] = 6, ["z"] = 8, ["name"] = "wool:white"}, {["x"] = 6, ["y"] = 7, ["z"] = 5, ["name"] = "wool:white"}, {["x"] = 6, ["y"] = 8, ["z"] = 7, ["name"] = "wool:white"}, {["x"] = 6, ["y"] = 8, ["z"] = 8, ["name"] = "wool:white"}, {["x"] = 7, ["y"] = 2, ["z"] = 11, ["name"] = "wool:white"}, {["x"] = 7, ["y"] = 3, ["z"] = 10, ["name"] = "wool:white"}, {["x"] = 7, ["y"] = 4, ["z"] = 9, ["name"] = "wool:white"}, {["x"] = 7, ["y"] = 5, ["z"] = 5, ["name"] = "wool:white"}, {["x"] = 7, ["y"] = 6, ["z"] = 6, ["name"] = "wool:white"}, {["x"] = 7, ["y"] = 6, ["z"] = 9, ["name"] = "wool:white"}, {["x"] = 7, ["y"] = 8, ["z"] = 6, ["name"] = "wool:white"}, {["x"] = 7, ["y"] = 8, ["z"] = 9, ["name"] = "wool:white"}, {["x"] = 7, ["y"] = 9, ["z"] = 3, ["name"] = "wool:white"}, {["x"] = 7, ["y"] = 9, ["z"] = 4, ["name"] = "wool:white"}, {["x"] = 7, ["y"] = 9, ["z"] = 8, ["name"] = "wool:white"}, {["x"] = 7, ["y"] = 10, ["z"] = 0, ["name"] = "wool:white"}, {["x"] = 7, ["y"] = 10, ["z"] = 1, ["name"] = "wool:white"}, {["x"] = 7, ["y"] = 10, ["z"] = 2, ["name"] = "wool:white"}, {["x"] = 7, ["y"] = 10, ["z"] = 3, ["name"] = "wool:white"}, {["x"] = 7, ["y"] = 10, ["z"] = 4, ["name"] = "wool:white"}, {["x"] = 7, ["y"] = 10, ["z"] = 7, ["name"] = "wool:white"}, {["x"] = 7, ["y"] = 11, ["z"] = 2, ["name"] = "wool:white"}, {["x"] = 7, ["y"] = 11, ["z"] = 4, ["name"] = "wool:white"}, {["x"] = 7, ["y"] = 11, ["z"] = 6, ["name"] = "wool:white"}, {["x"] = 7, ["y"] = 12, ["z"] = 3, ["name"] = "wool:white"}, {["x"] = 7, ["y"] = 12, ["z"] = 4, ["name"] = "wool:white"}, {["x"] = 8, ["y"] = 2, ["z"] = 11, ["name"] = "wool:white"}, {["x"] = 8, ["y"] = 3, ["z"] = 10, ["name"] = "wool:white"}, {["x"] = 8, ["y"] = 4, ["z"] = 9, ["name"] = "wool:white"}, {["x"] = 8, ["y"] = 5, ["z"] = 5, ["name"] = "wool:white"}, {["x"] = 8, ["y"] = 6, ["z"] = 6, ["name"] = "wool:white"}, {["x"] = 8, ["y"] = 6, ["z"] = 9, ["name"] = "wool:white"}, {["x"] = 8, ["y"] = 8, ["z"] = 6, ["name"] = "wool:white"}, {["x"] = 8, ["y"] = 8, ["z"] = 9, ["name"] = "wool:white"}, {["x"] = 8, ["y"] = 9, ["z"] = 3, ["name"] = "wool:white"}, {["x"] = 8, ["y"] = 9, ["z"] = 4, ["name"] = "wool:white"}, {["x"] = 8, ["y"] = 9, ["z"] = 8, ["name"] = "wool:white"}, {["x"] = 8, ["y"] = 10, ["z"] = 0, ["name"] = "wool:white"}, {["x"] = 8, ["y"] = 10, ["z"] = 1, ["name"] = "wool:white"}, {["x"] = 8, ["y"] = 10, ["z"] = 2, ["name"] = "wool:white"}, {["x"] = 8, ["y"] = 10, ["z"] = 3, ["name"] = "wool:white"}, {["x"] = 8, ["y"] = 10, ["z"] = 4, ["name"] = "wool:white"}, {["x"] = 8, ["y"] = 10, ["z"] = 7, ["name"] = "wool:white"}, {["x"] = 8, ["y"] = 11, ["z"] = 2, ["name"] = "wool:white"}, {["x"] = 8, ["y"] = 11, ["z"] = 4, ["name"] = "wool:white"}, {["x"] = 8, ["y"] = 11, ["z"] = 6, ["name"] = "wool:white"}, {["x"] = 8, ["y"] = 12, ["z"] = 3, ["name"] = "wool:white"}, {["x"] = 8, ["y"] = 12, ["z"] = 4, ["name"] = "wool:white"}, {["x"] = 9, ["y"] = 3, ["z"] = 8, ["name"] = "wool:white"}, {["x"] = 9, ["y"] = 3, ["z"] = 9, ["name"] = "wool:white"}, {["x"] = 9, ["y"] = 4, ["z"] = 5, ["name"] = "wool:white"}, {["x"] = 9, ["y"] = 6, ["z"] = 5, ["name"] = "wool:white"}, {["x"] = 9, ["y"] = 6, ["z"] = 7, ["name"] = "wool:white"}, {["x"] = 9, ["y"] = 6, ["z"] = 8, ["name"] = "wool:white"}, {["x"] = 9, ["y"] = 7, ["z"] = 5, ["name"] = "wool:white"}, {["x"] = 9, ["y"] = 8, ["z"] = 7, ["name"] = "wool:white"}, {["x"] = 9, ["y"] = 8, ["z"] = 8, ["name"] = "wool:white"}, {["x"] = 10, ["y"] = 0, ["z"] = 5, ["name"] = "wool:white"}, {["x"] = 10, ["y"] = 0, ["z"] = 6, ["name"] = "wool:white"}, {["x"] = 10, ["y"] = 1, ["z"] = 7, ["name"] = "wool:white"}, {["x"] = 10, ["y"] = 2, ["z"] = 7, ["name"] = "wool:white"}, {["x"] = 10, ["y"] = 5, ["z"] = 5, ["name"] = "wool:white"}, {["x"] = 10, ["y"] = 6, ["z"] = 5, ["name"] = "wool:white"}, {["x"] = 10, ["y"] = 7, ["z"] = 5, ["name"] = "wool:white"}, {["x"] = 10, ["y"] = 8, ["z"] = 6, ["name"] = "wool:white"}, {["x"] = 10, ["y"] = 8, ["z"] = 8, ["name"] = "wool:white"}, {["x"] = 11, ["y"] = 5, ["z"] = 7, ["name"] = "wool:white"}, {["x"] = 11, ["y"] = 5, ["z"] = 8, ["name"] = "wool:white"}, {["x"] = 11, ["y"] = 6, ["z"] = 7, ["name"] = "wool:white"}, {["x"] = 11, ["y"] = 6, ["z"] = 8, ["name"] = "wool:white"}, {["x"] = 11, ["y"] = 7, ["z"] = 7, ["name"] = "wool:white"}, {["x"] = 11, ["y"] = 8, ["z"] = 7, ["name"] = "wool:white"}, {["x"] = 12, ["y"] = 3, ["z"] = 7, ["name"] = "wool:white"}, {["x"] = 12, ["y"] = 4, ["z"] = 7, ["name"] = "wool:white"}}