5:return {{["x"] = 5, ["y"] = 0, ["z"] = 8, ["name"] = "wool:white"}, {["x"] = 5, ["y"] = 0, ["z"] = 9, ["name"] = "wool:white"}, {["x"] = 5, ["y"] = 0, ["z"] = 10, ["name"] = "wool:white"}, {["x"] = 5, ["y"] = 1, ["z"] = 10, ["name"] = "wool:white"}, {["x"] = 5, ["y"] = 2, ["z"] = 11, ["name"] = "wool:white"}, {["x"] = 5, ["y"] = 4, ["z"] = 7, ["name"] = "wool:white"}, {["x"] = 5, ["y"] = 4, ["z"] = 9, ["name"] = "wool:white"}, {["x"] = 5, ["y"] = 5, ["z"] = 7, ["name"] = "wool:white"}, {["x"] = 5, ["y"] = 5, ["z"] = 9, ["name"] = "wool:white"}, {["x"] = 5, ["y"] = 6, ["z"] = 7, ["name"] = "wool:white"}, {["x"] = 6, ["y"] = 0, ["z"] = 3, ["name"] = "wool:white"}, {["x"] = 6, ["y"] = 0, ["z"] = 4, ["name"] = "wool:white"}, {["x"] = 6, ["y"] = 1, ["z"] = 4, ["name"] = "wool:white"}, {["x"] = 6, ["y"] = 2, ["z"] = 5, ["name"] = "wool:white"}, {["x"] = 6, ["y"] = 2, ["z"] = 12, ["name"] = "wool:white"}, {["x"] = 6, ["y"] = 3, ["z"] = 5, ["name"] = "wool:white"}, {["x"] = 6, ["y"] = 3, ["z"] = 7, ["name"] = "wool:white"}, {["x"] = 6, ["y"] = 3, ["z"] = 9, ["name"] = "wool:white"}, {["x"] = 6, ["y"] = 3, ["z"] = 12, ["name"] = "wool:white"}, {["x"] = 6, ["y"] = 4, ["z"] = 6, ["name"] = "wool:white"}, {["x"] = 6, ["y"] = 5, ["z"] = 3, ["name"] = "wool:white"}, {["x"] = 6, ["y"] = 5, ["z"] = 6, ["name"] = "wool:white"}, {["x"] = 6, ["y"] = 5, ["z"] = 9, ["name"] = "wool:white"}, {["x"] = 6, ["y"] = 6, ["z"] = 2, ["name"] = "wool:white"}, {["x"] = 6, ["y"] = 6, ["z"] = 4, ["name"] = "wool:white"}, {["x"] = 6, ["y"] = 6, ["z"] = 5, ["name"] = "wool:white"}, {["x"] = 6, ["y"] = 6, ["z"] = 7, ["name"] = "wool:white"}, {["x"] = 6, ["y"] = 7, ["z"] = 2, ["name"] = "wool:white"}, {["x"] = 6, ["y"] = 7, ["z"] = 4, ["name"] = "wool:white"}, {["x"] = 6, ["y"] = 7, ["z"] = 5, ["name"] = "wool:white"}, {["x"] = 7, ["y"] = 1, ["z"] = 12, ["name"] = "wool:white"}, {["x"] = 7, ["y"] = 3, ["z"] = 7, ["name"] = "wool:white"}, {["x"] = 7, ["y"] = 3, ["z"] = 9, ["name"] = "wool:white"}, {["x"] = 7, ["y"] = 3, ["z"] = 13, ["name"] = "wool:white"}, {["x"] = 7, ["y"] = 4, ["z"] = 2, ["name"] = "wool:white"}, {["x"] = 7, ["y"] = 4, ["z"] = 3, ["name"] = "wool:white"}, {["x"] = 7, ["y"] = 4, ["z"] = 4, ["name"] = "wool:white"}, {["x"] = 7, ["y"] = 4, ["z"] = 12, ["name"] = "wool:white"}, {["x"] = 7, ["y"] = 5, ["z"] = 1, ["name"] = "wool:white"}, {["x"] = 7, ["y"] = 5, ["z"] = 4, ["name"] = "wool:white"}, {["x"] = 7, ["y"] = 5, ["z"] = 5, ["name"] = "wool:white"}, {["x"] = 7, ["y"] = 5, ["z"] = 8, ["name"] = "wool:white"}, {["x"] = 7, ["y"] = 5, ["z"] = 10, ["name"] = "wool:white"}, {["x"] = 7, ["y"] = 6, ["z"] = 0, ["name"] = "wool:white"}, {["x"] = 7, ["y"] = 6, ["z"] = 5, ["name"] = "wool:white"}, {["x"] = 7, ["y"] = 6, ["z"] = 6, ["name"] = "wool:white"}, {["x"] = 7, ["y"] = 7, ["z"] = 1, ["name"] = "wool:white"}, {["x"] = 7, ["y"] = 7, ["z"] = 2, ["name"] = "wool:white"}, {["x"] = 7, ["y"] = 7, ["z"] = 3, ["name"] = "wool:white"}, {["x"] = 7, ["y"] = 7, ["z"] = 4, ["name"] = "wool:white"}, {["x"] = 7, ["y"] = 7, ["z"] = 5, ["name"] = "wool:white"}, {["x"] = 8, ["y"] = 0, ["z"] = 3, ["name"] = "wool:white"}, {["x"] = 8, ["y"] = 0, ["z"] = 4, ["name"] = "wool:white"}, {["x"] = 8, ["y"] = 1, ["z"] = 4, ["name"] = "wool:white"}, {["x"] = 8, ["y"] = 2, ["z"] = 5, ["name"] = "wool:white"}, {["x"] = 8, ["y"] = 2, ["z"] = 12, ["name"] = "wool:white"}, {["x"] = 8, ["y"] = 2, ["z"] = 14, ["name"] = "wool:white"}, {["x"] = 8, ["y"] = 3, ["z"] = 5, ["name"] = "wool:white"}, {["x"] = 8, ["y"] = 3, ["z"] = 7, ["name"] = "wool:white"}, {["x"] = 8, ["y"] = 3, ["z"] = 9, ["name"] = "wool:white"}, {["x"] = 8, ["y"] = 3, ["z"] = 12, ["name"] = "wool:white"}, {["x"] = 8, ["y"] = 4, ["z"] = 6, ["name"] = "wool:white"}, {["x"] = 8, ["y"] = 5, ["z"] = 3, ["name"] = "wool:white"}, {["x"] = 8, ["y"] = 5, ["z"] = 6, ["name"] = "wool:white"}, {["x"] = 8, ["y"] = 5, ["z"] = 9, ["name"] = "wool:white"}, {["x"] = 8, ["y"] = 6, ["z"] = 2, ["name"] = "wool:white"}, {["x"] = 8, ["y"] = 6, ["z"] = 4, ["name"] = "wool:white"}, {["x"] = 8, ["y"] = 6, ["z"] = 5, ["name"] = "wool:white"}, {["x"] = 8, ["y"] = 6, ["z"] = 7, ["name"] = "wool:white"}, {["x"] = 8, ["y"] = 7, ["z"] = 2, ["name"] = "wool:white"}, {["x"] = 8, ["y"] = 7, ["z"] = 4, ["name"] = "wool:white"}, {["x"] = 8, ["y"] = 7, ["z"] = 5, ["name"] = "wool:white"}, {["x"] = 9, ["y"] = 0, ["z"] = 8, ["name"] = "wool:white"}, {["x"] = 9, ["y"] = 0, ["z"] = 9, ["name"] = "wool:white"}, {["x"] = 9, ["y"] = 0, ["z"] = 10, ["name"] = "wool:white"}, {["x"] = 9, ["y"] = 1, ["z"] = 10, ["name"] = "wool:white"}, {["x"] = 9, ["y"] = 1, ["z"] = 14, ["name"] = "wool:white"}, {["x"] = 9, ["y"] = 2, ["z"] = 11, ["name"] = "wool:white"}, {["x"] = 9, ["y"] = 4, ["z"] = 7, ["name"] = "wool:white"}, {["x"] = 9, ["y"] = 4, ["z"] = 9, ["name"] = "wool:white"}, {["x"] = 9, ["y"] = 5, ["z"] = 7, ["name"] = "wool:white"}, {["x"] = 9, ["y"] = 5, ["z"] = 9, ["name"] = "wool:white"}, {["x"] = 9, ["y"] = 6, ["z"] = 7, ["name"] = "wool:white"}, {["x"] = 10, ["y"] = 0, ["z"] = 14, ["name"] = "wool:white"}, {["x"] = 11, ["y"] = 0, ["z"] = 14, ["name"] = "wool:white"}, {["x"] = 12, ["y"] = 0, ["z"] = 13, ["name"] = "wool:white"}, {["x"] = 13, ["y"] = 0, ["z"] = 10, ["name"] = "wool:white"}, {["x"] = 13, ["y"] = 0, ["z"] = 11, ["name"] = "wool:white"}, {["x"] = 13, ["y"] = 0, ["z"] = 12, ["name"] = "wool:white"}}