5:return {{["x"] = 1, ["y"] = 0, ["z"] = 15, ["name"] = "wool:white"}, {["x"] = 1, ["y"] = 1, ["z"] = 16, ["name"] = "wool:white"}, {["x"] = 1, ["y"] = 2, ["z"] = 16, ["name"] = "wool:white"}, {["x"] = 1, ["y"] = 3, ["z"] = 16, ["name"] = "wool:white"}, {["x"] = 1, ["y"] = 4, ["z"] = 16, ["name"] = "wool:white"}, {["x"] = 1, ["y"] = 5, ["z"] = 14, ["name"] = "wool:white"}, {["x"] = 1, ["y"] = 5, ["z"] = 15, ["name"] = "wool:white"}, {["x"] = 2, ["y"] = 0, ["z"] = 15, ["name"] = "wool:white"}, {["x"] = 2, ["y"] = 0, ["z"] = 21, ["name"] = "wool:white"}, {["x"] = 2, ["y"] = 1, ["z"] = 16, ["name"] = "wool:white"}, {["x"] = 2, ["y"] = 1, ["z"] = 21, ["name"] = "wool:white"}, {["x"] = 2, ["y"] = 2, ["z"] = 16, ["name"] = "wool:white"}, {["x"] = 2, ["y"] = 2, ["z"] = 22, ["name"] = "wool:white"}, {["x"] = 2, ["y"] = 3, ["z"] = 16, ["name"] = "wool:white"}, {["x"] = 2, ["y"] = 3, ["z"] = 21, ["name"] = "wool:white"}, {["x"] = 2, ["y"] = 3, ["z"] = 23, ["name"] = "wool:white"}, {["x"] = 2, ["y"] = 4, ["z"] = 16, ["name"] = "wool:white"}, {["x"] = 2, ["y"] = 4, ["z"] = 21, ["name"] = "wool:white"}, {["x"] = 2, ["y"] = 5, ["z"] = 14, ["name"] = "wool:white"}, {["x"] = 2, ["y"] = 5, ["z"] = 15, ["name"] = "wool:white"}, {["x"] = 2, ["y"] = 5, ["z"] = 21, ["name"] = "wool:white"}, {["x"] = 2, ["y"] = 5, ["z"] = 22, ["name"] = "wool:white"}, {["x"] = 2, ["y"] = 6, ["z"] = 12, ["name"] = "wool:white"}, {["x"] = 2, ["y"] = 6, ["z"] = 13, ["name"] = "wool:white"}, {["x"] = 2, ["y"] = 6, ["z"] = 22, ["name"] = "wool:white"}, {["x"] = 2, ["y"] = 6, ["z"] = 23, ["name"] = "wool:white"}, {["x"] = 2, ["y"] = 6, ["z"] = 24, ["name"] = "wool:white"}, {["x"] = 2, ["y"] = 7, ["z"] = 24, ["name"] = "wool:white"}, {["x"] = 3, ["y"] = 0, ["z"] = 21, ["name"] = "wool:white"}, {["x"] = 3, ["y"] = 1, ["z"] = 21, ["name"] = "wool:white"}, {["x"] = 3, ["y"] = 2, ["z"] = 22, ["name"] = "wool:white"}, {["x"] = 3, ["y"] = 3, ["z"] = 21, ["name"] = "wool:white"}, {["x"] = 3, ["y"] = 3, ["z"] = 23, ["name"] = "wool:white"}, {["x"] = 3, ["y"] = 4, ["z"] = 21, ["name"] = "wool:white"}, {["x"] = 3, ["y"] = 5, ["z"] = 21, ["name"] = "wool:white"}, {["x"] = 3, ["y"] = 5, ["z"] = 22, ["name"] = "wool:white"}, {["x"] = 3, ["y"] = 6, ["z"] = 22, ["name"] = "wool:white"}, {["x"] = 3, ["y"] = 6, ["z"] = 23, ["name"] = "wool:white"}, {["x"] = 3, ["y"] = 6, ["z"] = 24, ["name"] = "wool:white"}, {["x"] = 3, ["y"] = 7, ["z"] = 12, ["name"] = "wool:white"}, {["x"] = 3, ["y"] = 7, ["z"] = 13, ["name"] = "wool:white"}, {["x"] = 3, ["y"] = 7, ["z"] = 24, ["name"] = "wool:white"}, {["x"] = 4, ["y"] = 5, ["z"] = 12, ["name"] = "wool:white"}, {["x"] = 4, ["y"] = 5, ["z"] = 14, ["name"] = "wool:white"}, {["x"] = 4, ["y"] = 5, ["z"] = 16, ["name"] = "wool:white"}, {["x"] = 4, ["y"] = 6, ["z"] = 12, ["name"] = "wool:white"}, {["x"] = 4, ["y"] = 6, ["z"] = 14, ["name"] = "wool:white"}, {["x"] = 4, ["y"] = 6, ["z"] = 16, ["name"] = "wool:white"}, {["x"] = 4, ["y"] = 6, ["z"] = 18, ["name"] = "wool:white"}, {["x"] = 4, ["y"] = 7, ["z"] = 24, ["name"] = "wool:white"}, {["x"] = 4, ["y"] = 8, ["z"] = 12, ["name"] = "wool:white"}, {["x"] = 4, ["y"] = 8, ["z"] = 13, ["name"] = "wool:white"}, {["x"] = 4, ["y"] = 8, ["z"] = 14, ["name"] = "wool:white"}, {["x"] = 4, ["y"] = 8, ["z"] = 22, ["name"] = "wool:white"}, {["x"] = 4, ["y"] = 8, ["z"] = 23, ["name"] = "wool:white"}, {["x"] = 4, ["y"] = 8, ["z"] = 24, ["name"] = "wool:white"}, {["x"] = 4, ["y"] = 9, ["z"] = 21, ["name"] = "wool:white"}, {["x"] = 4, ["y"] = 9, ["z"] = 22, ["name"] = "wool:white"}, {["x"] = 4, ["y"] = 9, ["z"] = 23, ["name"] = "wool:white"}, {["x"] = 5, ["y"] = 4, ["z"] = 12, ["name"] = "wool:white"}, {["x"] = 5, ["y"] = 4, ["z"] = 14, ["name"] = "wool:white"}, {["x"] = 5, ["y"] = 4, ["z"] = 16, ["name"] = "wool:white"}, {["x"] = 5, ["y"] = 7, ["z"] = 12, ["name"] = "wool:white"}, {["x"] = 5, ["y"] = 7, ["z"] = 14, ["name"] = "wool:white"}, {["x"] = 5, ["y"] = 7, ["z"] = 16, ["name"] = "wool:white"}, {["x"] = 5, ["y"] = 7, ["z"] = 18, ["name"] = "wool:white"}, {["x"] = 5, ["y"] = 8, ["z"] = 6, ["name"] = "wool:white"}, {["x"] = 5, ["y"] = 9, ["z"] = 4, ["name"] = "wool:white"}, {["x"] = 5, ["y"] = 9, ["z"] = 5, ["name"] = "wool:white"}, {["x"] = 5, ["y"] = 9, ["z"] = 6, ["name"] = "wool:white"}, {["x"] = 5, ["y"] = 9, ["z"] = 7, ["name"] = "wool:white"}, {["x"] = 5, ["y"] = 9, ["z"] = 9, ["name"] = "wool:white"}, {["x"] = 5, ["y"] = 9, ["z"] = 12, ["name"] = "wool:white"}, {["x"] = 5, ["y"] = 9, ["z"] = 13, ["name"] = "wool:white"}, {["x"] = 5, ["y"] = 9, ["z"] = 14, ["name"] = "wool:white"}, {["x"] = 5, ["y"] = 9, ["z"] = 22, ["name"] = "wool:white"}, {["x"] = 5, ["y"] = 10, ["z"] = 4, ["name"] = "wool:white"}, {["x"] = 5, ["y"] = 10, ["z"] = 5, ["name"] = "wool:white"}, {["x"] = 5, ["y"] = 10, ["z"] = 6, ["name"] = "wool:white"}, {["x"] = 5, ["y"] = 10, ["z"] = 7, ["name"] = "wool:white"}, {["x"] = 5, ["y"] = 10, ["z"] = 8, ["name"] = "wool:white"}, {["x"] = 5, ["y"] = 10, ["z"] = 9, ["name"] = "wool:white"}, {["x"] = 5, ["y"] = 11, ["z"] = 7, ["name"] = "wool:white"}, {["x"] = 5, ["y"] = 11, ["z"] = 8, ["name"] = "wool:white"}, {["x"] = 5, ["y"] = 12, ["z"] = 6, ["name"] = "wool:white"}, {["x"] = 5, ["y"] = 12, ["z"] = 7, ["name"] = "wool:white"}, {["x"] = 6, ["y"] = 3, ["z"] = 12, ["name"] = "wool:white"}, {["x"] = 6, ["y"] = 3, ["z"] = 14, ["name"] = "wool:white"}, {["x"] = 6, ["y"] = 3, ["z"] = 16, ["name"] = "wool:white"}, {["x"] = 6, ["y"] = 8, ["z"] = 3, ["name"] = "wool:white"}, {["x"] = 6, ["y"] = 8, ["z"] = 4, ["name"] = "wool:white"}, {["x"] = 6, ["y"] = 8, ["z"] = 5, ["name"] = "wool:white"}, {["x"] = 6, ["y"] = 8, ["z"] = 10, ["name"] = "wool:white"}, {["x"] = 6, ["y"] = 8, ["z"] = 12, ["name"] = "wool:white"}, {["x"] = 6, ["y"] = 8, ["z"] = 14, ["name"] = "wool:white"}, {["x"] = 6, ["y"] = 8, ["z"] = 16, ["name"] = "wool:white"}, {["x"] = 6, ["y"] = 8, ["z"] = 18, ["name"] = "wool:white"}, {["x"] = 6, ["y"] = 8, ["z"] = 20, ["name"] = "wool:white"}, {["x"] = 6, ["y"] = 8, ["z"] = 22, ["name"] = "wool:white"}, {["x"] = 6, ["y"] = 8, ["z"] = 24, ["name"] = "wool:white"}, {["x"] = 6, ["y"] = 8, ["z"] = 26, ["name"] = "wool:white"}, {["x"] = 6, ["y"] = 9, ["z"] = 2, ["name"] = "wool:white"}, {["x"] = 6, ["y"] = 9, ["z"] = 10, ["name"] = "wool:white"}, {["x"] = 6, ["y"] = 9, ["z"] = 12, ["name"] = "wool:white"}, {["x"] = 6, ["y"] = 9, ["z"] = 14, ["name"] = "wool:white"}, {["x"] = 6, ["y"] = 9, ["z"] = 16, ["name"] = "wool:white"}, {["x"] = 6, ["y"] = 9, ["z"] = 18, ["name"] = "wool:white"}, {["x"] = 6, ["y"] = 9, ["z"] = 20, ["name"] = "wool:white"}, {["x"] = 6, ["y"] = 9, ["z"] = 22, ["name"] = "wool:white"}, {["x"] = 6, ["y"] = 9, ["z"] = 24, ["name"] = "wool:white"}, {["x"] = 6, ["y"] = 10, ["z"] = 3, ["name"] = "wool:white"}, {["x"] = 6, ["y"] = 11, ["z"] = 4, ["name"] = "wool:white"}, {["x"] = 6, ["y"] = 11, ["z"] = 5, ["name"] = "wool:white"}, {["x"] = 6, ["y"] = 12, ["z"] = 6, ["name"] = "wool:white"}, {["x"] = 6, ["y"] = 12, ["z"] = 7, ["name"] = "wool:white"}, {["x"] = 6, ["y"] = 12, ["z"] = 8, ["name"] = "wool:white"}, {["x"] = 7, ["y"] = 3, ["z"] = 12, ["name"] = "wool:white"}, {["x"] = 7, ["y"] = 3, ["z"] = 14, ["name"] = "wool:white"}, {["x"] = 7, ["y"] = 3, ["z"] = 16, ["name"] = "wool:white"}, {["x"] = 7, ["y"] = 8, ["z"] = 3, ["name"] = "wool:white"}, {["x"] = 7, ["y"] = 8, ["z"] = 4, ["name"] = "wool:white"}, {["x"] = 7, ["y"] = 8, ["z"] = 5, ["name"] = "wool:white"}, {["x"] = 7, ["y"] = 8, ["z"] = 10, ["name"] = "wool:white"}, {["x"] = 7, ["y"] = 8, ["z"] = 12, ["name"] = "wool:white"}, {["x"] = 7, ["y"] = 8, ["z"] = 14, ["name"] = "wool:white"}, {["x"] = 7, ["y"] = 8, ["z"] = 16, ["name"] = "wool:white"}, {["x"] = 7, ["y"] = 8, ["z"] = 18, ["name"] = "wool:white"}, {["x"] = 7, ["y"] = 8, ["z"] = 20, ["name"] = "wool:white"}, {["x"] = 7, ["y"] = 8, ["z"] = 22, ["name"] = "wool:white"}, {["x"] = 7, ["y"] = 8, ["z"] = 24, ["name"] = "wool:white"}, {["x"] = 7, ["y"] = 8, ["z"] = 26, ["name"] = "wool:white"}, {["x"] = 7, ["y"] = 9, ["z"] = 2, ["name"] = "wool:white"}, {["x"] = 7, ["y"] = 9, ["z"] = 10, ["name"] = "wool:white"}, {["x"] = 7, ["y"] = 9, ["z"] = 12, ["name"] = "wool:white"}, {["x"] = 7, ["y"] = 9, ["z"] = 14, ["name"] = "wool:white"}, {["x"] = 7, ["y"] = 9, ["z"] = 16, ["name"] = "wool:white"}, {["x"] = 7, ["y"] = 9, ["z"] = 18, ["name"] = "wool:white"}, {["x"] = 7, ["y"] = 9, ["z"] = 20, ["name"] = "wool:white"}, {["x"] = 7, ["y"] = 9, ["z"] = 22, ["name"] = "wool:white"}, {["x"] = 7, ["y"] = 9, ["z"] = 24, ["name"] = "wool:white"}, {["x"] = 7, ["y"] = 10, ["z"] = 3, ["name"] = "wool:white"}, {["x"] = 7, ["y"] = 11, ["z"] = 4, ["name"] = "wool:white"}, {["x"] = 7, ["y"] = 11, ["z"] = 5, ["name"] = "wool:white"}, {["x"] = 7, ["y"] = 12, ["z"] = 6, ["name"] = "wool:white"}, {["x"] = 7, ["y"] = 12, ["z"] = 7, ["name"] = "wool:white"}, {["x"] = 7, ["y"] = 12, ["z"] = 8, ["name"] = "wool:white"}, {["x"] = 8, ["y"] = 4, ["z"] = 12, ["name"] = "wool:white"}, {["x"] = 8, ["y"] = 4, ["z"] = 14, ["name"] = "wool:white"}, {["x"] = 8, ["y"] = 4, ["z"] = 16, ["name"] = "wool:white"}, {["x"] = 8, ["y"] = 7, ["z"] = 12, ["name"] = "wool:white"}, {["x"] = 8, ["y"] = 7, ["z"] = 14, ["name"] = "wool:white"}, {["x"] = 8, ["y"] = 7, ["z"] = 16, ["name"] = "wool:white"}, {["x"] = 8, ["y"] = 7, ["z"] = 18, ["name"] = "wool:white"}, {["x"] = 8, ["y"] = 8, ["z"] = 6, ["name"] = "wool:white"}, {["x"] = 8, ["y"] = 9, ["z"] = 4, ["name"] = "wool:white"}, {["x"] = 8, ["y"] = 9, ["z"] = 5, ["name"] = "wool:white"}, {["x"] = 8, ["y"] = 9, ["z"] = 6, ["name"] = "wool:white"}, {["x"] = 8, ["y"] = 9, ["z"] = 7, ["name"] = "wool:white"}, {["x"] = 8, ["y"] = 9, ["z"] = 9, ["name"] = "wool:white"}, {["x"] = 8, ["y"] = 9, ["z"] = 12, ["name"] = "wool:white"}, {["x"] = 8, ["y"] = 9, ["z"] = 13, ["name"] = "wool:white"}, {["x"] = 8, ["y"] = 9, ["z"] = 14, ["name"] = "wool:white"}, {["x"] = 8, ["y"] = 9, ["z"] = 22, ["name"] = "wool:white"}, {["x"] = 8, ["y"] = 10, ["z"] = 4, ["name"] = "wool:white"}, {["x"] = 8, ["y"] = 10, ["z"] = 5, ["name"] = "wool:white"}, {["x"] = 8, ["y"] = 10, ["z"] = 6, ["name"] = "wool:white"}, {["x"] = 8, ["y"] = 10, ["z"] = 7, ["name"] = "wool:white"}, {["x"] = 8, ["y"] = 10, ["z"] = 8, ["name"] = "wool:white"}, {["x"] = 8, ["y"] = 10, ["z"] = 9, ["name"] = "wool:white"}, {["x"] = 8, ["y"] = 11, ["z"] = 7, ["name"] = "wool:white"}, {["x"] = 8, ["y"] = 11, ["z"] = 8, ["name"] = "wool:white"}, {["x"] = 8, ["y"] = 12, ["z"] = 6, ["name"] = "wool:white"}, {["x"] = 8, ["y"] = 12, ["z"] = 7, ["name"] = "wool:white"}, {["x"] = 9, ["y"] = 5, ["z"] = 12, ["name"] = "wool:white"}, {["x"] = 9, ["y"] = 5, ["z"] = 14, ["name"] = "wool:white"}, {["x"] = 9, ["y"] = 5, ["z"] = 16, ["name"] = "wool:white"}, {["x"] = 9, ["y"] = 6, ["z"] = 12, ["name"] = "wool:white"}, {["x"] = 9, ["y"] = 6, ["z"] = 14, ["name"] = "wool:white"}, {["x"] = 9, ["y"] = 6, ["z"] = 16, ["name"] = "wool:white"}, {["x"] = 9, ["y"] = 6, ["z"] = 18, ["name"] = "wool:white"}, {["x"] = 9, ["y"] = 7, ["z"] = 24, ["name"] = "wool:white"}, {["x"] = 9, ["y"] = 8, ["z"] = 12, ["name"] = "wool:white"}, {["x"] = 9, ["y"] = 8, ["z"] = 13, ["name"] = "wool:white"}, {["x"] = 9, ["y"] = 8, ["z"] = 14, ["name"] = "wool:white"}, {["x"] = 9, ["y"] = 8, ["z"] = 22, ["name"] = "wool:white"}, {["x"] = 9, ["y"] = 8, ["z"] = 23, ["name"] = "wool:white"}, {["x"] = 9, ["y"] = 8, ["z"] = 24, ["name"] = "wool:white"}, {["x"] = 9, ["y"] = 9, ["z"] = 21, ["name"] = "wool:white"}, {["x"] = 9, ["y"] = 9, ["z"] = 22, ["name"] = "wool:white"}, {["x"] = 9, ["y"] = 9, ["z"] = 23, ["name"] = "wool:white"}, {["x"] = 10, ["y"] = 0, ["z"] = 21, ["name"] = "wool:white"}, {["x"] = 10, ["y"] = 1, ["z"] = 21, ["name"] = "wool:white"}, {["x"] = 10, ["y"] = 2, ["z"] = 22, ["name"] = "wool:white"}, {["x"] = 10, ["y"] = 3, ["z"] = 21, ["name"] = "wool:white"}, {["x"] = 10, ["y"] = 3, ["z"] = 23, ["name"] = "wool:white"}, {["x"] = 10, ["y"] = 4, ["z"] = 21, ["name"] = "wool:white"}, {["x"] = 10, ["y"] = 5, ["z"] = 21, ["name"] = "wool:white"}, {["x"] = 10, ["y"] = 5, ["z"] = 22, ["name"] = "wool:white"}, {["x"] = 10, ["y"] = 6, ["z"] = 22, ["name"] = "wool:white"}, {["x"] = 10, ["y"] = 6, ["z"] = 23, ["name"] = "wool:white"}, {["x"] = 10, ["y"] = 6, ["z"] = 24, ["name"] = "wool:white"}, {["x"] = 10, ["y"] = 7, ["z"] = 12, ["name"] = "wool:white"}, {["x"] = 10, ["y"] = 7, ["z"] = 13, ["name"] = "wool:white"}, {["x"] = 10, ["y"] = 7, ["z"] = 24, ["name"] = "wool:white"}, {["x"] = 11, ["y"] = 0, ["z"] = 15, ["name"] = "wool:white"}, {["x"] = 11, ["y"] = 0, ["z"] = 21, ["name"] = "wool:white"}, {["x"] = 11, ["y"] = 1, ["z"] = 16, ["name"] = "wool:white"}, {["x"] = 11, ["y"] = 1, ["z"] = 21, ["name"] = "wool:white"}, {["x"] = 11, ["y"] = 2, ["z"] = 16, ["name"] = "wool:white"}, {["x"] = 11, ["y"] = 2, ["z"] = 22, ["name"] = "wool:white"}, {["x"] = 11, ["y"] = 3, ["z"] = 16, ["name"] = "wool:white"}, {["x"] = 11, ["y"] = 3, ["z"] = 21, ["name"] = "wool:white"}, {["x"] = 11, ["y"] = 3, ["z"] = 23, ["name"] = "wool:white"}, {["x"] = 11, ["y"] = 4, ["z"] = 16, ["name"] = "wool:white"}, {["x"] = 11, ["y"] = 4, ["z"] = 21, ["name"] = "wool:white"}, {["x"] = 11, ["y"] = 5, ["z"] = 14, ["name"] = "wool:white"}, {["x"] = 11, ["y"] = 5, ["z"] = 15, ["name"] = "wool:white"}, {["x"] = 11, ["y"] = 5, ["z"] = 21, ["name"] = "wool:white"}, {["x"] = 11, ["y"] = 5, ["z"] = 22, ["name"] = "wool:white"}, {["x"] = 11, ["y"] = 6, ["z"] = 12, ["name"] = "wool:white"}, {["x"] = 11, ["y"] = 6, ["z"] = 13, ["name"] = "wool:white"}, {["x"] = 11, ["y"] = 6, ["z"] = 22, ["name"] = "wool:white"}, {["x"] = 11, ["y"] = 6, ["z"] = 23, ["name"] = "wool:white"}, {["x"] = 11, ["y"] = 6, ["z"] = 24, ["name"] = "wool:white"}, {["x"] = 11, ["y"] = 7, ["z"] = 24, ["name"] = "wool:white"}, {["x"] = 12, ["y"] = 0, ["z"] = 15, ["name"] = "wool:white"}, {["x"] = 12, ["y"] = 1, ["z"] = 16, ["name"] = "wool:white"}, {["x"] = 12, ["y"] = 2, ["z"] = 16, ["name"] = "wool:white"}, {["x"] = 12, ["y"] = 3, ["z"] = 16, ["name"] = "wool:white"}, {["x"] = 12, ["y"] = 4, ["z"] = 16, ["name"] = "wool:white"}, {["x"] = 12, ["y"] = 5, ["z"] = 14, ["name"] = "wool:white"}, {["x"] = 12, ["y"] = 5, ["z"] = 15, ["name"] = "wool:white"}}