5:return {{["x"] = 4, ["y"] = 0, ["z"] = 5, ["name"] = "wool:white"}, {["x"] = 4, ["y"] = 0, ["z"] = 8, ["name"] = "wool:white"}, {["x"] = 4, ["y"] = 0, ["z"] = 18, ["name"] = "wool:white"}, {["x"] = 4, ["y"] = 0, ["z"] = 19, ["name"] = "wool:white"}, {["x"] = 4, ["y"] = 1, ["z"] = 6, ["name"] = "wool:white"}, {["x"] = 4, ["y"] = 1, ["z"] = 8, ["name"] = "wool:white"}, {["x"] = 4, ["y"] = 1, ["z"] = 19, ["name"] = "wool:white"}, {["x"] = 4, ["y"] = 2, ["z"] = 7, ["name"] = "wool:white"}, {["x"] = 4, ["y"] = 2, ["z"] = 20, ["name"] = "wool:white"}, {["x"] = 4, ["y"] = 3, ["z"] = 8, ["name"] = "wool:white"}, {["x"] = 4, ["y"] = 3, ["z"] = 21, ["name"] = "wool:white"}, {["x"] = 4, ["y"] = 4, ["z"] = 9, ["name"] = "wool:white"}, {["x"] = 4, ["y"] = 4, ["z"] = 20, ["name"] = "wool:white"}, {["x"] = 4, ["y"] = 4, ["z"] = 22, ["name"] = "wool:white"}, {["x"] = 4, ["y"] = 5, ["z"] = 8, ["name"] = "wool:white"}, {["x"] = 4, ["y"] = 5, ["z"] = 10, ["name"] = "wool:white"}, {["x"] = 4, ["y"] = 5, ["z"] = 19, ["name"] = "wool:white"}, {["x"] = 4, ["y"] = 6, ["z"] = 8, ["name"] = "wool:white"}, {["x"] = 4, ["y"] = 6, ["z"] = 18, ["name"] = "wool:white"}, {["x"] = 4, ["y"] = 7, ["z"] = 1, ["name"] = "wool:white"}, {["x"] = 4, ["y"] = 7, ["z"] = 8, ["name"] = "wool:white"}, {["x"] = 4, ["y"] = 7, ["z"] = 14, ["name"] = "wool:white"}, {["x"] = 4, ["y"] = 7, ["z"] = 17, ["name"] = "wool:white"}, {["x"] = 4, ["y"] = 8, ["z"] = 1, ["name"] = "wool:white"}, {["x"] = 4, ["y"] = 8, ["z"] = 8, ["name"] = "wool:white"}, {["x"] = 4, ["y"] = 8, ["z"] = 15, ["name"] = "wool:white"}, {["x"] = 4, ["y"] = 8, ["z"] = 17, ["name"] = "wool:white"}, {["x"] = 4, ["y"] = 9, ["z"] = 13, ["name"] = "wool:white"}, {["x"] = 4, ["y"] = 9, ["z"] = 15, ["name"] = "wool:white"}, {["x"] = 4, ["y"] = 9, ["z"] = 18, ["name"] = "wool:white"}, {["x"] = 4, ["y"] = 10, ["z"] = 15, ["name"] = "wool:white"}, {["x"] = 4, ["y"] = 10, ["z"] = 18, ["name"] = "wool:white"}, {["x"] = 5, ["y"] = 0, ["z"] = 5, ["name"] = "wool:white"}, {["x"] = 5, ["y"] = 0, ["z"] = 18, ["name"] = "wool:white"}, {["x"] = 5, ["y"] = 1, ["z"] = 6, ["name"] = "wool:white"}, {["x"] = 5, ["y"] = 1, ["z"] = 19, ["name"] = "wool:white"}, {["x"] = 5, ["y"] = 2, ["z"] = 7, ["name"] = "wool:white"}, {["x"] = 5, ["y"] = 2, ["z"] = 20, ["name"] = "wool:white"}, {["x"] = 5, ["y"] = 3, ["z"] = 8, ["name"] = "wool:white"}, {["x"] = 5, ["y"] = 3, ["z"] = 21, ["name"] = "wool:white"}, {["x"] = 5, ["y"] = 4, ["z"] = 9, ["name"] = "wool:white"}, {["x"] = 5, ["y"] = 4, ["z"] = 20, ["name"] = "wool:white"}, {["x"] = 5, ["y"] = 4, ["z"] = 22, ["name"] = "wool:white"}, {["x"] = 5, ["y"] = 5, ["z"] = 8, ["name"] = "wool:white"}, {["x"] = 5, ["y"] = 5, ["z"] = 10, ["name"] = "wool:white"}, {["x"] = 5, ["y"] = 5, ["z"] = 19, ["name"] = "wool:white"}, {["x"] = 5, ["y"] = 6, ["z"] = 8, ["name"] = "wool:white"}, {["x"] = 5, ["y"] = 6, ["z"] = 18, ["name"] = "wool:white"}, {["x"] = 5, ["y"] = 7, ["z"] = 1, ["name"] = "wool:white"}, {["x"] = 5, ["y"] = 7, ["z"] = 8, ["name"] = "wool:white"}, {["x"] = 5, ["y"] = 7, ["z"] = 11, ["name"] = "wool:white"}, {["x"] = 5, ["y"] = 7, ["z"] = 17, ["name"] = "wool:white"}, {["x"] = 5, ["y"] = 8, ["z"] = 8, ["name"] = "wool:white"}, {["x"] = 5, ["y"] = 8, ["z"] = 11, ["name"] = "wool:white"}, {["x"] = 5, ["y"] = 8, ["z"] = 13, ["name"] = "wool:white"}, {["x"] = 5, ["y"] = 8, ["z"] = 17, ["name"] = "wool:white"}, {["x"] = 5, ["y"] = 9, ["z"] = 8, ["name"] = "wool:white"}, {["x"] = 5, ["y"] = 9, ["z"] = 9, ["name"] = "wool:white"}, {["x"] = 5, ["y"] = 9, ["z"] = 18, ["name"] = "wool:white"}, {["x"] = 5, ["y"] = 10, ["z"] = 9, ["name"] = "wool:white"}, {["x"] = 5, ["y"] = 10, ["z"] = 10, ["name"] = "wool:white"}, {["x"] = 5, ["y"] = 10, ["z"] = 13, ["name"] = "wool:white"}, {["x"] = 5, ["y"] = 10, ["z"] = 18, ["name"] = "wool:white"}, {["x"] = 5, ["y"] = 11, ["z"] = 4, ["name"] = "wool:white"}, {["x"] = 5, ["y"] = 11, ["z"] = 10, ["name"] = "wool:white"}, {["x"] = 5, ["y"] = 11, ["z"] = 15, ["name"] = "wool:white"}, {["x"] = 5, ["y"] = 12, ["z"] = 4, ["name"] = "wool:white"}, {["x"] = 6, ["y"] = 6, ["z"] = 11, ["name"] = "wool:white"}, {["x"] = 6, ["y"] = 7, ["z"] = 1, ["name"] = "wool:white"}, {["x"] = 6, ["y"] = 7, ["z"] = 13, ["name"] = "wool:white"}, {["x"] = 6, ["y"] = 8, ["z"] = 0, ["name"] = "wool:white"}, {["x"] = 6, ["y"] = 8, ["z"] = 1, ["name"] = "wool:white"}, {["x"] = 6, ["y"] = 8, ["z"] = 2, ["name"] = "wool:white"}, {["x"] = 6, ["y"] = 8, ["z"] = 3, ["name"] = "wool:white"}, {["x"] = 6, ["y"] = 8, ["z"] = 4, ["name"] = "wool:white"}, {["x"] = 6, ["y"] = 9, ["z"] = 1, ["name"] = "wool:white"}, {["x"] = 6, ["y"] = 9, ["z"] = 2, ["name"] = "wool:white"}, {["x"] = 6, ["y"] = 9, ["z"] = 3, ["name"] = "wool:white"}, {["x"] = 6, ["y"] = 9, ["z"] = 4, ["name"] = "wool:white"}, {["x"] = 6, ["y"] = 9, ["z"] = 11, ["name"] = "wool:white"}, {["x"] = 6, ["y"] = 10, ["z"] = 4, ["name"] = "wool:white"}, {["x"] = 6, ["y"] = 10, ["z"] = 5, ["name"] = "wool:white"}, {["x"] = 6, ["y"] = 10, ["z"] = 9, ["name"] = "wool:white"}, {["x"] = 6, ["y"] = 11, ["z"] = 3, ["name"] = "wool:white"}, {["x"] = 6, ["y"] = 11, ["z"] = 5, ["name"] = "wool:white"}, {["x"] = 6, ["y"] = 11, ["z"] = 13, ["name"] = "wool:white"}, {["x"] = 6, ["y"] = 11, ["z"] = 18, ["name"] = "wool:white"}, {["x"] = 6, ["y"] = 12, ["z"] = 4, ["name"] = "wool:white"}, {["x"] = 6, ["y"] = 12, ["z"] = 15, ["name"] = "wool:white"}, {["x"] = 7, ["y"] = 5, ["z"] = 11, ["name"] = "wool:white"}, {["x"] = 7, ["y"] = 6, ["z"] = 13, ["name"] = "wool:white"}, {["x"] = 7, ["y"] = 7, ["z"] = 0, ["name"] = "wool:white"}, {["x"] = 7, ["y"] = 7, ["z"] = 1, ["name"] = "wool:white"}, {["x"] = 7, ["y"] = 7, ["z"] = 2, ["name"] = "wool:white"}, {["x"] = 7, ["y"] = 7, ["z"] = 3, ["name"] = "wool:white"}, {["x"] = 7, ["y"] = 8, ["z"] = 4, ["name"] = "wool:white"}, {["x"] = 7, ["y"] = 8, ["z"] = 7, ["name"] = "wool:white"}, {["x"] = 7, ["y"] = 8, ["z"] = 9, ["name"] = "wool:white"}, {["x"] = 7, ["y"] = 9, ["z"] = 0, ["name"] = "wool:white"}, {["x"] = 7, ["y"] = 9, ["z"] = 5, ["name"] = "wool:white"}, {["x"] = 7, ["y"] = 9, ["z"] = 7, ["name"] = "wool:white"}, {["x"] = 7, ["y"] = 9, ["z"] = 9, ["name"] = "wool:white"}, {["x"] = 7, ["y"] = 9, ["z"] = 11, ["name"] = "wool:white"}, {["x"] = 7, ["y"] = 9, ["z"] = 24, ["name"] = "wool:white"}, {["x"] = 7, ["y"] = 10, ["z"] = 1, ["name"] = "wool:white"}, {["x"] = 7, ["y"] = 10, ["z"] = 2, ["name"] = "wool:white"}, {["x"] = 7, ["y"] = 10, ["z"] = 9, ["name"] = "wool:white"}, {["x"] = 7, ["y"] = 10, ["z"] = 11, ["name"] = "wool:white"}, {["x"] = 7, ["y"] = 10, ["z"] = 13, ["name"] = "wool:white"}, {["x"] = 7, ["y"] = 10, ["z"] = 23, ["name"] = "wool:white"}, {["x"] = 7, ["y"] = 11, ["z"] = 3, ["name"] = "wool:white"}, {["x"] = 7, ["y"] = 11, ["z"] = 5, ["name"] = "wool:white"}, {["x"] = 7, ["y"] = 11, ["z"] = 10, ["name"] = "wool:white"}, {["x"] = 7, ["y"] = 11, ["z"] = 12, ["name"] = "wool:white"}, {["x"] = 7, ["y"] = 11, ["z"] = 13, ["name"] = "wool:white"}, {["x"] = 7, ["y"] = 11, ["z"] = 15, ["name"] = "wool:white"}, {["x"] = 7, ["y"] = 11, ["z"] = 17, ["name"] = "wool:white"}, {["x"] = 7, ["y"] = 11, ["z"] = 19, ["name"] = "wool:white"}, {["x"] = 7, ["y"] = 11, ["z"] = 22, ["name"] = "wool:white"}, {["x"] = 7, ["y"] = 12, ["z"] = 4, ["name"] = "wool:white"}, {["x"] = 7, ["y"] = 12, ["z"] = 10, ["name"] = "wool:white"}, {["x"] = 7, ["y"] = 12, ["z"] = 12, ["name"] = "wool:white"}, {["x"] = 7, ["y"] = 12, ["z"] = 14, ["name"] = "wool:white"}, {["x"] = 7, ["y"] = 12, ["z"] = 15, ["name"] = "wool:white"}, {["x"] = 7, ["y"] = 12, ["z"] = 17, ["name"] = "wool:white"}, {["x"] = 7, ["y"] = 12, ["z"] = 19, ["name"] = "wool:white"}, {["x"] = 7, ["y"] = 12, ["z"] = 21, ["name"] = "wool:white"}, {["x"] = 8, ["y"] = 5, ["z"] = 11, ["name"] = "wool:white"}, {["x"] = 8, ["y"] = 6, ["z"] = 13, ["name"] = "wool:white"}, {["x"] = 8, ["y"] = 7, ["z"] = 0, ["name"] = "wool:white"}, {["x"] = 8, ["y"] = 7, ["z"] = 1, ["name"] = "wool:white"}, {["x"] = 8, ["y"] = 7, ["z"] = 2, ["name"] = "wool:white"}, {["x"] = 8, ["y"] = 7, ["z"] = 3, ["name"] = "wool:white"}, {["x"] = 8, ["y"] = 8, ["z"] = 4, ["name"] = "wool:white"}, {["x"] = 8, ["y"] = 8, ["z"] = 7, ["name"] = "wool:white"}, {["x"] = 8, ["y"] = 8, ["z"] = 9, ["name"] = "wool:white"}, {["x"] = 8, ["y"] = 9, ["z"] = 0, ["name"] = "wool:white"}, {["x"] = 8, ["y"] = 9, ["z"] = 5, ["name"] = "wool:white"}, {["x"] = 8, ["y"] = 9, ["z"] = 7, ["name"] = "wool:white"}, {["x"] = 8, ["y"] = 9, ["z"] = 9, ["name"] = "wool:white"}, {["x"] = 8, ["y"] = 9, ["z"] = 11, ["name"] = "wool:white"}, {["x"] = 8, ["y"] = 9, ["z"] = 24, ["name"] = "wool:white"}, {["x"] = 8, ["y"] = 10, ["z"] = 1, ["name"] = "wool:white"}, {["x"] = 8, ["y"] = 10, ["z"] = 2, ["name"] = "wool:white"}, {["x"] = 8, ["y"] = 10, ["z"] = 9, ["name"] = "wool:white"}, {["x"] = 8, ["y"] = 10, ["z"] = 11, ["name"] = "wool:white"}, {["x"] = 8, ["y"] = 10, ["z"] = 13, ["name"] = "wool:white"}, {["x"] = 8, ["y"] = 10, ["z"] = 23, ["name"] = "wool:white"}, {["x"] = 8, ["y"] = 11, ["z"] = 3, ["name"] = "wool:white"}, {["x"] = 8, ["y"] = 11, ["z"] = 5, ["name"] = "wool:white"}, {["x"] = 8, ["y"] = 11, ["z"] = 10, ["name"] = "wool:white"}, {["x"] = 8, ["y"] = 11, ["z"] = 12, ["name"] = "wool:white"}, {["x"] = 8, ["y"] = 11, ["z"] = 13, ["name"] = "wool:white"}, {["x"] = 8, ["y"] = 11, ["z"] = 15, ["name"] = "wool:white"}, {["x"] = 8, ["y"] = 11, ["z"] = 17, ["name"] = "wool:white"}, {["x"] = 8, ["y"] = 11, ["z"] = 19, ["name"] = "wool:white"}, {["x"] = 8, ["y"] = 11, ["z"] = 22, ["name"] = "wool:white"}, {["x"] = 8, ["y"] = 12, ["z"] = 4, ["name"] = "wool:white"}, {["x"] = 8, ["y"] = 12, ["z"] = 10, ["name"] = "wool:white"}, {["x"] = 8, ["y"] = 12, ["z"] = 12, ["name"] = "wool:white"}, {["x"] = 8, ["y"] = 12, ["z"] = 14, ["name"] = "wool:white"}, {["x"] = 8, ["y"] = 12, ["z"] = 15, ["name"] = "wool:white"}, {["x"] = 8, ["y"] = 12, ["z"] = 17, ["name"] = "wool:white"}, {["x"] = 8, ["y"] = 12, ["z"] = 19, ["name"] = "wool:white"}, {["x"] = 8, ["y"] = 12, ["z"] = 21, ["name"] = "wool:white"}, {["x"] = 9, ["y"] = 6, ["z"] = 11, ["name"] = "wool:white"}, {["x"] = 9, ["y"] = 7, ["z"] = 1, ["name"] = "wool:white"}, {["x"] = 9, ["y"] = 7, ["z"] = 13, ["name"] = "wool:white"}, {["x"] = 9, ["y"] = 8, ["z"] = 0, ["name"] = "wool:white"}, {["x"] = 9, ["y"] = 8, ["z"] = 1, ["name"] = "wool:white"}, {["x"] = 9, ["y"] = 8, ["z"] = 2, ["name"] = "wool:white"}, {["x"] = 9, ["y"] = 8, ["z"] = 3, ["name"] = "wool:white"}, {["x"] = 9, ["y"] = 8, ["z"] = 4, ["name"] = "wool:white"}, {["x"] = 9, ["y"] = 9, ["z"] = 1, ["name"] = "wool:white"}, {["x"] = 9, ["y"] = 9, ["z"] = 2, ["name"] = "wool:white"}, {["x"] = 9, ["y"] = 9, ["z"] = 3, ["name"] = "wool:white"}, {["x"] = 9, ["y"] = 9, ["z"] = 4, ["name"] = "wool:white"}, {["x"] = 9, ["y"] = 9, ["z"] = 11, ["name"] = "wool:white"}, {["x"] = 9, ["y"] = 10, ["z"] = 4, ["name"] = "wool:white"}, {["x"] = 9, ["y"] = 10, ["z"] = 5, ["name"] = "wool:white"}, {["x"] = 9, ["y"] = 10, ["z"] = 9, ["name"] = "wool:white"}, {["x"] = 9, ["y"] = 11, ["z"] = 3, ["name"] = "wool:white"}, {["x"] = 9, ["y"] = 11, ["z"] = 5, ["name"] = "wool:white"}, {["x"] = 9, ["y"] = 11, ["z"] = 13, ["name"] = "wool:white"}, {["x"] = 9, ["y"] = 11, ["z"] = 18, ["name"] = "wool:white"}, {["x"] = 9, ["y"] = 12, ["z"] = 4, ["name"] = "wool:white"}, {["x"] = 9, ["y"] = 12, ["z"] = 15, ["name"] = "wool:white"}, {["x"] = 10, ["y"] = 0, ["z"] = 5, ["name"] = "wool:white"}, {["x"] = 10, ["y"] = 0, ["z"] = 18, ["name"] = "wool:white"}, {["x"] = 10, ["y"] = 1, ["z"] = 6, ["name"] = "wool:white"}, {["x"] = 10, ["y"] = 1, ["z"] = 19, ["name"] = "wool:white"}, {["x"] = 10, ["y"] = 2, ["z"] = 7, ["name"] = "wool:white"}, {["x"] = 10, ["y"] = 2, ["z"] = 20, ["name"] = "wool:white"}, {["x"] = 10, ["y"] = 3, ["z"] = 8, ["name"] = "wool:white"}, {["x"] = 10, ["y"] = 3, ["z"] = 21, ["name"] = "wool:white"}, {["x"] = 10, ["y"] = 4, ["z"] = 9, ["name"] = "wool:white"}, {["x"] = 10, ["y"] = 4, ["z"] = 20, ["name"] = "wool:white"}, {["x"] = 10, ["y"] = 4, ["z"] = 22, ["name"] = "wool:white"}, {["x"] = 10, ["y"] = 5, ["z"] = 8, ["name"] = "wool:white"}, {["x"] = 10, ["y"] = 5, ["z"] = 10, ["name"] = "wool:white"}, {["x"] = 10, ["y"] = 5, ["z"] = 19, ["name"] = "wool:white"}, {["x"] = 10, ["y"] = 6, ["z"] = 8, ["name"] = "wool:white"}, {["x"] = 10, ["y"] = 6, ["z"] = 18, ["name"] = "wool:white"}, {["x"] = 10, ["y"] = 7, ["z"] = 1, ["name"] = "wool:white"}, {["x"] = 10, ["y"] = 7, ["z"] = 8, ["name"] = "wool:white"}, {["x"] = 10, ["y"] = 7, ["z"] = 11, ["name"] = "wool:white"}, {["x"] = 10, ["y"] = 7, ["z"] = 17, ["name"] = "wool:white"}, {["x"] = 10, ["y"] = 8, ["z"] = 8, ["name"] = "wool:white"}, {["x"] = 10, ["y"] = 8, ["z"] = 11, ["name"] = "wool:white"}, {["x"] = 10, ["y"] = 8, ["z"] = 13, ["name"] = "wool:white"}, {["x"] = 10, ["y"] = 8, ["z"] = 17, ["name"] = "wool:white"}, {["x"] = 10, ["y"] = 9, ["z"] = 8, ["name"] = "wool:white"}, {["x"] = 10, ["y"] = 9, ["z"] = 9, ["name"] = "wool:white"}, {["x"] = 10, ["y"] = 9, ["z"] = 18, ["name"] = "wool:white"}, {["x"] = 10, ["y"] = 10, ["z"] = 9, ["name"] = "wool:white"}, {["x"] = 10, ["y"] = 10, ["z"] = 13, ["name"] = "wool:white"}, {["x"] = 10, ["y"] = 10, ["z"] = 18, ["name"] = "wool:white"}, {["x"] = 10, ["y"] = 11, ["z"] = 4, ["name"] = "wool:white"}, {["x"] = 10, ["y"] = 11, ["z"] = 15, ["name"] = "wool:white"}, {["x"] = 10, ["y"] = 12, ["z"] = 4, ["name"] = "wool:white"}, {["x"] = 11, ["y"] = 0, ["z"] = 5, ["name"] = "wool:white"}, {["x"] = 11, ["y"] = 0, ["z"] = 8, ["name"] = "wool:white"}, {["x"] = 11, ["y"] = 0, ["z"] = 18, ["name"] = "wool:white"}, {["x"] = 11, ["y"] = 0, ["z"] = 19, ["name"] = "wool:white"}, {["x"] = 11, ["y"] = 1, ["z"] = 6, ["name"] = "wool:white"}, {["x"] = 11, ["y"] = 1, ["z"] = 8, ["name"] = "wool:white"}, {["x"] = 11, ["y"] = 1, ["z"] = 19, ["name"] = "wool:white"}, {["x"] = 11, ["y"] = 2, ["z"] = 7, ["name"] = "wool:white"}, {["x"] = 11, ["y"] = 2, ["z"] = 20, ["name"] = "wool:white"}, {["x"] = 11, ["y"] = 3, ["z"] = 8, ["name"] = "wool:white"}, {["x"] = 11, ["y"] = 3, ["z"] = 21, ["name"] = "wool:white"}, {["x"] = 11, ["y"] = 4, ["z"] = 9, ["name"] = "wool:white"}, {["x"] = 11, ["y"] = 4, ["z"] = 20, ["name"] = "wool:white"}, {["x"] = 11, ["y"] = 4, ["z"] = 22, ["name"] = "wool:white"}, {["x"] = 11, ["y"] = 5, ["z"] = 8, ["name"] = "wool:white"}, {["x"] = 11, ["y"] = 5, ["z"] = 10, ["name"] = "wool:white"}, {["x"] = 11, ["y"] = 5, ["z"] = 19, ["name"] = "wool:white"}, {["x"] = 11, ["y"] = 6, ["z"] = 8, ["name"] = "wool:white"}, {["x"] = 11, ["y"] = 6, ["z"] = 18, ["name"] = "wool:white"}, {["x"] = 11, ["y"] = 7, ["z"] = 1, ["name"] = "wool:white"}, {["x"] = 11, ["y"] = 7, ["z"] = 8, ["name"] = "wool:white"}, {["x"] = 11, ["y"] = 7, ["z"] = 14, ["name"] = "wool:white"}, {["x"] = 11, ["y"] = 7, ["z"] = 17, ["name"] = "wool:white"}, {["x"] = 11, ["y"] = 8, ["z"] = 1, ["name"] = "wool:white"}, {["x"] = 11, ["y"] = 8, ["z"] = 8, ["name"] = "wool:white"}, {["x"] = 11, ["y"] = 8, ["z"] = 15, ["name"] = "wool:white"}, {["x"] = 11, ["y"] = 8, ["z"] = 17, ["name"] = "wool:white"}, {["x"] = 11, ["y"] = 9, ["z"] = 13, ["name"] = "wool:white"}, {["x"] = 11, ["y"] = 9, ["z"] = 15, ["name"] = "wool:white"}, {["x"] = 11, ["y"] = 9, ["z"] = 18, ["name"] = "wool:white"}, {["x"] = 11, ["y"] = 10, ["z"] = 15, ["name"] = "wool:white"}, {["x"] = 11, ["y"] = 10, ["z"] = 18, ["name"] = "wool:white"}}